File: Development/Test_Figures_and_Outputs/_Cooling.csv
Temperature (K),AC Moment (emu)
300.000823974609,2.0806573824444e-06
299.98957824707,2.09051930341791e-06
299.612548828125,1.94273015336827e-06
299.063217163086,1.96280282769557e-06
298.52679443359403,1.9724936120371897e-06
297.98211669921903,1.97784028210056e-06
297.43499755859403,2.02516323399663e-06
296.892700195313,2.00697148971777e-06
295.73394775390597,2.00864380734537e-06
294.81217956543,1.9816503099425703e-06
294.272216796875,2.01934493599925e-06
293.730545043945,1.97452783368119e-06
292.560089111328,1.83778049678561e-06
290.91351318359403,2.00862437857828e-06
289.899368286133,2.05212526595079e-06
289.138626098633,2.02457769630566e-06
288.36314392089804,1.97304903633548e-06
286.964309692383,2.16355312124375e-06
286.163528442383,2.00121150416301e-06
285.630416870117,2.06107210505759e-06
284.905685424805,2.04185727783421e-06
284.17498779296903,2.0373280547166e-06
283.63397216796903,2.0325019999411597e-06
283.08465576171903,1.9861289864743696e-06
282.15690612793,2.0534080609426898e-06
281.480499267578,2.06776701555114e-06
280.543441772461,1.99849653542373e-06
279.594879150391,2.05095116234178e-06
279.042007446289,2.00523556939061e-06
278.494583129883,2.05990130039465e-06
277.95001220703097,2.06092403500843e-06
277.414916992187,2.0374019028691503e-06
276.87640380859403,2.04690522390972e-06
276.32818603515597,2.0381086688012e-06
275.785491943359,2.06152566825117e-06
275.240463256836,2.08555593491275e-06
274.70347595214804,2.0693682896227e-06
274.160858154297,2.08940839984062e-06
273.611541748047,2.0702332006726698e-06
273.074005126953,2.1000971392122503e-06
272.533462524414,2.0851933649650602e-06
271.99072265625,2.01935447402377e-06
271.250762939453,2.05671204033601e-06
270.501693725586,2.05958627577213e-06
269.954437255859,2.00928597192464e-06
269.149185180664,2.07616141807798e-06
268.603851318359,2.04600326026575e-06
268.059310913086,2.0833863559116798e-06
267.511978149414,2.0947898553694e-06
266.959884643555,2.05710510653094e-06
266.41656494140597,2.05702967156549e-06
265.43035888671903,2.10732529497578e-06
264.51190185546903,1.908869418561e-06
262.94964599609403,2.0639506954079603e-06
262.148727416992,2.0735381513005e-06
261.604034423828,2.1041461503131403e-06
261.059814453125,1.8567013863828603e-06
259.480453491211,2.11955923796884e-06
258.93812561035196,2.13586614986365e-06
258.39588928222696,2.11995958642475e-06
257.68756103515597,2.1389157684886004e-06
256.97544860839804,2.09735114572605e-06
256.213203430176,2.08058164686196e-06
255.199607849121,2.1126394039574697e-06
254.664268493652,2.03809470416841e-06
253.79431152343798,2.14562534449773e-06
253.039405822754,2.01886580843642e-06
251.717834472656,2.15825701516975e-06
251.185012817383,2.36539725863162e-06
250.643600463867,2.1602903769698397e-06
250.103523254395,2.13007592445344e-06
249.564651489258,2.16938481434863e-06
249.025489807129,2.15327880886238e-06
248.489219665527,2.15701535273757e-06
247.945266723633,2.19918050710191e-06
247.399307250977,2.17421128408042e-06
246.863975524902,2.11669270293103e-06
245.88279724121102,2.18960727164142e-06
245.159339904785,2.17664914464211e-06
244.6181640625,2.1240811604149e-06
244.07476043701197,2.18793110423982e-06
243.53150939941398,2.1692129631621797e-06
242.700775146484,2.18598891377859e-06
242.162635803223,2.20653883665024e-06
241.49543762207,2.21284813587985e-06
240.81701660156202,2.04513066965619e-06
239.783020019531,2.21466316223946e-06
239.24754333496102,2.1977110216829104e-06
238.702781677246,2.15884059906758e-06
238.15217590332,2.2093352797886397e-06
237.60920715332,2.24773463068436e-06
237.06008148193402,2.22117688905545e-06
236.51065826416,2.25703948766949e-06
235.964729309082,2.18543444095053e-06
235.026741027832,2.1704491559158697e-06
234.49462890625,2.23494903057e-06
233.953086853027,2.22908093049355e-06
233.406936645508,2.23999368808732e-06
232.86047363281298,2.1908521183974997e-06
232.053321838379,2.21911159819832e-06
231.511344909668,2.21669015541911e-06
230.96598815918,2.2692268132378e-06
230.41989898681598,2.2113935500019797e-06
229.60717010497999,2.25832544327686e-06
229.069900512695,2.25240181317434e-06
228.52851104736303,2.28343958365354e-06
227.979850769043,2.2787967889517502e-06
227.432411193848,2.26629698022771e-06
226.8916015625,2.26721092350564e-06
226.340927124023,2.26326983621017e-06
225.801574707031,2.20248373648787e-06
224.824996948242,2.2850580518845903e-06
224.28150939941398,2.30028312304595e-06
223.73363494872999,2.286985635554e-06
223.18717956543,2.29172900844615e-06
222.64820861816398,2.27986804735318e-06
222.102470397949,2.28037566828359e-06
221.556228637695,2.32148445385479e-06
221.00710296630902,2.35609660115586e-06
220.461730957031,2.28072195955103e-06
219.92253112793,2.2795717796968997e-06
219.37798309326197,2.37221744402333e-06
218.831573486328,2.30824189140033e-06
218.29469299316398,2.3197855654922297e-06
217.75089263916,2.32962476260075e-06
217.204704284668,2.33379989898946e-06
216.663497924805,2.34593614551873e-06
216.124229431152,2.30167296715564e-06
215.57981872558602,2.32958520762517e-06
215.03392791748,2.32978269898526e-06
214.487869262695,2.50766528770366e-06
213.943840026855,2.39084856580622e-06
213.399772644043,2.3561208894896702e-06
212.859031677246,2.36600376282046e-06
212.310157775879,2.3870436586371e-06
211.756546020508,2.36867474042103e-06
211.205390930176,2.39666568760595e-06
210.656188964844,2.37616691537532e-06
210.10959625244098,2.33105867910964e-06
209.56481933593798,2.38869361638655e-06
209.023147583008,2.39972029956114e-06
208.47762298584,2.35779289987746e-06
207.944305419922,2.36720239763985e-06
207.256011962891,2.38879088197673e-06
206.564651489258,2.24828044416642e-06
205.633407592773,2.4243356096077005e-06
205.09690856933602,2.38260760198279e-06
204.551261901855,2.3932847033319697e-06
204.002349853516,2.4752732620519198e-06
203.458076477051,2.4113263369579497e-06
202.918495178223,2.42133479772987e-06
202.377334594727,2.42189302425426e-06
201.83083343505902,2.4297193747552e-06
201.285003662109,2.4301096831018798e-06
200.743659973145,2.42546763887251e-06
200.201072692871,2.4384482467813203e-06
199.657379150391,2.4434713269569697e-06
199.115135192871,2.43484456330193e-06
198.568534851074,2.39033350943518e-06
198.024772644043,2.46762719797272e-06
197.481452941895,2.4490318828042197e-06
196.94140625,2.41601927595158e-06
196.39960479736303,2.4472898857455896e-06
195.856140136719,2.4410639043689203e-06
195.308258056641,2.4931201358146197e-06
194.765182495117,2.4637847071208696e-06
194.224395751953,2.45614602526906e-06
193.679573059082,2.46920942921966e-06
193.133674621582,2.49725215762689e-06
192.586494445801,2.49674912619076e-06
192.04357910156202,2.48893139440825e-06
191.49733734130902,2.47276482653571e-06
190.952835083008,2.56382103106799e-06
190.410026550293,2.50190140800878e-06
189.872375488281,2.4903115799581902e-06
189.332801818848,2.51122899612632e-06
188.78610992431598,2.53646718795569e-06
188.244934082031,2.52056263112532e-06
187.704902648926,2.52006507062443e-06
187.164482116699,2.53355596998432e-06
186.623329162598,2.53842111921544e-06
186.07999420166,2.5564493323126e-06
185.53783416748,2.54406026609212e-06
184.989784240723,2.52620213094469e-06
184.445243835449,2.52736257214163e-06
183.89803314209,2.63693275541612e-06
183.356109619141,2.5961803648024398e-06
182.805564880371,2.5781011572894902e-06
182.266426086426,2.5880186273159e-06
181.721641540527,2.63022366209219e-06
181.175918579102,2.55497132864863e-06
180.63331604003898,2.5776562573356202e-06
180.088317871094,2.5854534622018298e-06
179.54539489746102,2.5268119425839297e-06
178.99755859375,2.5911911306832804e-06
178.45111846923803,2.6114744090211603e-06
177.913703918457,2.75049708807645e-06
177.369064331055,2.60999776113535e-06
176.826370239258,2.62431243517891e-06
176.285293579102,2.57258382715609e-06
175.74102020263697,2.6310731315955202e-06
175.19627380371102,2.65088596003804e-06
174.650428771973,2.61943297971151e-06
174.10698699951197,2.61101943249641e-06
173.558692932129,2.64009633945469e-06
173.011756896973,2.63481122671818e-06
172.471961975098,2.62514862007348e-06
171.928771972656,2.64470815977568e-06
171.383483886719,2.68738187943377e-06
170.840805053711,2.64467616525805e-06
170.302131652832,2.67097419264473e-06
169.761184692383,2.67059356115844e-06
169.215377807617,2.64908127678443e-06
168.675231933594,2.73564983511559e-06
168.136116027832,2.69274281373825e-06
167.596771240234,2.67137249610372e-06
167.056999206543,2.7045862235303e-06
166.51634979248,2.7559078428730597e-06
165.97516632080098,2.68494559180975e-06
165.434898376465,2.6444686027095503e-06
164.896858215332,2.7076779576460603e-06
164.353675842285,2.70909962005527e-06
163.815711975098,2.7364114527232003e-06
163.270660400391,2.7215772702878e-06
162.7265625,2.7136069874105202e-06
162.180519104004,2.76843818667325e-06
161.638862609863,2.74323389976058e-06
161.098083496094,2.71446927345515e-06
160.554641723633,2.73531549195349e-06
160.017143249512,2.76478778864297e-06
159.467628479004,2.7409062729317402e-06
158.917045593262,2.73502937434232e-06
158.38293457031298,2.77333854629657e-06
157.843284606934,2.74911682558431e-06
157.30270385742202,2.8008719995757002e-06
156.758712768555,2.78222325173482e-06
156.224990844727,2.76106822191728e-06
155.680305480957,2.76997074686324e-06
155.140075683594,2.79914843899227e-06
154.59835815429702,2.78486658694474e-06
154.058364868164,2.78820507987686e-06
153.518783569336,2.81596792601751e-06
152.980659484863,2.79767260886761e-06
152.43962097168,2.8344427134931e-06
151.897346496582,2.8315644691961003e-06
151.353576660156,2.8313229033865397e-06
150.814987182617,2.8137019852535e-06
150.274955749512,2.8407817985007098e-06
149.735237121582,2.83829024888096e-06
149.196060180664,2.84815126797536e-06
148.655197143555,2.79167777802805e-06
148.11149597168,2.84072930085317e-06
147.566497802734,2.86238251539347e-06
147.02462768554702,2.8585969757586203e-06
146.48265838623,2.88561993002552e-06
145.93604278564501,2.8802562053035e-06
145.38973236084,2.85778096345771e-06
144.84952545166,2.863061520962e-06
144.308982849121,2.8584855445587397e-06
143.765975952148,2.8765325991222198e-06
143.222618103027,2.8886978329574e-06
142.681755065918,2.86890083610754e-06
142.14001464843798,2.90314424884134e-06
141.59748840332,3.09825496384019e-06
141.05105590820298,2.90893179186932e-06
140.50879669189501,2.90300650749507e-06
139.96813964843798,2.90541752807637e-06
139.424263000488,2.92296565093803e-06
138.885101318359,2.90384833313685e-06
138.34451293945298,2.91622576705134e-06
137.802429199219,2.89741361113052e-06
137.264930725098,2.90883643539874e-06
136.726211547852,2.89001628659722e-06
136.18303680419902,2.93772936039696e-06
135.643356323242,2.9350153614808e-06
135.097694396973,2.89966401008253e-06
134.560043334961,2.9384200803045398e-06
134.015403747559,3.00732409160171e-06
133.47839355468798,2.9262334635799e-06
132.938179016113,2.9460942218978297e-06
132.39431762695298,2.97233080503317e-06
131.850700378418,2.9732033042073997e-06
131.31335449218798,2.9133764970793497e-06
130.77151489257798,2.90478534625834e-06
130.23420715332,2.9992610169002498e-06
129.692718505859,2.98231537840945e-06
129.151382446289,2.98612474195907e-06
128.610397338867,2.97297021752297e-06
128.067615509033,3.01768294117528e-06
127.528839111328,2.99181989072075e-06
126.983776092529,2.9748682434013303e-06
126.441806793213,3.0132245627559898e-06
125.89907836914101,3.04257111154976e-06
125.355556488037,3.02645814137915e-06
124.816143035889,2.98097384832013e-06
124.278179168701,2.99870991847874e-06
123.740219116211,3.08799290612216e-06
123.194133758545,3.08988128107502e-06
122.64810180664101,3.0602310341407503e-06
122.10931396484399,3.0710890746663e-06
121.568668365479,3.06592809562261e-06
121.024585723877,3.0617295253623e-06
120.486991882324,3.1054810865421e-06
119.948078155518,3.0662027405396703e-06
119.40955352783199,3.16066400259265e-06
118.86417388916,3.09327115737526e-06
118.322132110596,3.03821158585232e-06
117.779460906982,3.1073903716108996e-06
117.24098968505899,3.1252704542542303e-06
116.69504547119101,3.1404914765204897e-06
116.159225463867,3.03691324468559e-06
115.618110656738,3.1499623334232102e-06
115.07566070556601,3.03439941068534e-06
114.164485931396,3.16870074647079e-06
113.62899017334,3.16909783112238e-06
113.088798522949,3.18980911716213e-06
112.55185317993201,3.12294688991883e-06
112.01252746581999,3.22572604571497e-06
111.47052001953101,3.21042404204815e-06
110.931625366211,3.19997895780525e-06
110.38882446289101,3.22443260503492e-06
109.847110748291,3.23990641637669e-06
109.30237197876,3.2849526631164e-06
108.75939178466801,3.2146726680477e-06
108.216426849365,3.27487555968432e-06
107.678085327148,3.27720667952316e-06
107.135566711426,3.2833621099060502e-06
106.59424972534201,3.34832920097126e-06
106.051647186279,3.32604738962586e-06
105.50936889648399,3.33186516129359e-06
104.967182159424,3.5791478199748e-06
104.42819976806601,3.35353423057781e-06
103.88595199585,3.35206154409188e-06
103.34616470336901,3.3771968018904703e-06
102.804718017578,3.39647754486504e-06
102.264240264893,3.37807305553732e-06
101.71940612793001,3.41328645513276e-06
101.17247772216801,3.41884149298151e-06
100.631561279297,3.34068096463447e-06
100.08974838256799,3.44937652848292e-06
99.5477180480957,3.4639792747074095e-06
99.007568359375,3.5035595162352896e-06
98.4659271240234,3.4374336849094497e-06
97.92444229125981,3.51163189466361e-06
97.3816986083984,3.5449598306015502e-06
96.8405532836914,3.55520877549684e-06
96.3035430908203,3.53405029071009e-06
95.75850296020509,3.56422775218986e-06
95.21882247924809,3.5927249940138e-06
94.6818733215332,3.6011834232211197e-06
94.1424217224121,3.67716782682952e-06
93.59764862060551,3.64949559770348e-06
93.05426025390629,3.6711075324823e-06
92.5131568908691,3.63777647342054e-06
91.97182083129879,3.6907204324328598e-06
91.4302635192871,3.69688227895235e-06
90.89192581176759,3.7008797299773804e-06
90.349308013916,3.5618536794411796e-06
89.5560302734375,3.7742678690679297e-06
89.01269149780269,3.76680489271486e-06
88.473445892334,3.797883274418e-06
87.93066787719731,3.80362706500605e-06
87.3906593322754,3.84727364854506e-06
86.85305786132808,3.6516279765576003e-06
86.0571174621582,3.83183460265115e-06
85.5185890197754,3.6966027289623705e-06
84.7251663208008,3.92340593037036e-06
84.1816024780273,3.6751092522576897e-06
83.3833999633789,3.96318431237404e-06
82.84336853027341,3.97001294007451e-06
82.2962303161621,4.01312823203778e-06
81.7573432922363,3.97964450230938e-06
81.2142372131348,3.80136257887305e-06
80.4178504943848,4.01890677585886e-06
79.876091003418,4.07827034728713e-06
79.3346900939941,4.11930853963076e-06
78.7921524047852,4.13093664996696e-06
78.2505264282227,4.1031189574073e-06
77.5800132751465,4.16060699705216e-06
76.9110298156738,4.15637018680894e-06
76.3678207397461,4.2894063694272905e-06
75.82817459106441,4.1605928405171796e-06
75.286319732666,4.26500384018471e-06
74.74827575683591,4.26138598258949e-06
74.2072830200195,4.28062780567512e-06
73.6648712158203,4.2711791303318296e-06
73.1245040893555,4.34205055416993e-06
72.5795249938965,3.98630991957686e-06
71.7871742248535,4.394558084151091e-06
71.2447509765625,4.42206367679922e-06
70.7017250061035,4.4101252783363194e-06
70.1601753234863,4.43739523255099e-06
69.618293762207,4.4417606607423104e-06
69.0740509033203,4.476460854704509e-06
68.532642364502,4.69853445698175e-06
67.99407958984379,4.507400100483901e-06
67.4532089233398,4.50208738638303e-06
66.9146347045898,4.57580338459497e-06
66.3758277893066,4.52537442080679e-06
65.8324165344238,4.56498516282095e-06
65.290885925293,4.60169855157716e-06
64.74948120117189,4.6017738383075e-06
64.2108268737793,4.58480820077131e-06
63.6690616607666,4.64611863523164e-06
63.1301174163818,4.70413329099552e-06
62.58871269226071,4.69936988117343e-06
62.044958114624,4.64811423261878e-06
61.5046577453613,4.6509790280770205e-06
60.963808059692404,4.69858074098213e-06
60.4172210693359,4.66924041257814e-06
59.8782901763916,4.7241317659714106e-06
59.3382091522217,4.73791800087681e-06
58.7964019775391,4.662696691265631e-06
58.255821228027294,4.76118770840636e-06
57.7157459259033,4.76232783749612e-06
57.17757987976071,4.73647345711396e-06
56.6334590911865,4.72752982298684e-06
56.093936920165994,4.6543382923057095e-06
55.551149368286104,4.71174930159479e-06
55.0079555511475,4.7262454677957295e-06
54.4713554382324,3.49463293841219e-06
53.6721343994141,4.68316008737331e-06
53.1348514556885,4.6350551652365e-06
52.5924015045166,4.66759817436279e-06
52.052465438842795,4.6543432378647e-06
51.512569427490206,4.6430405339752405e-06
50.9710903167725,4.63376830116422e-06
50.4318561553955,4.59544754871688e-06
49.8925037384033,4.54527389346088e-06
49.350503921508796,4.54784929598132e-06
48.8079166412354,4.47579600220812e-06
48.2680320739746,4.45990244413917e-06
47.7262954711914,4.4441987542299695e-06
47.1869983673096,4.4193273032502405e-06
46.647544860839794,4.3374604268106e-06
46.1051502227783,4.30707631123479e-06
45.5648021697998,4.26318527673465e-06
45.025749206543,4.20949624685951e-06
44.485071182251,4.233071648395961e-06
43.9441661834717,4.11827563030516e-06
43.4036693572998,4.05415305101076e-06
42.8640365600586,4.025000238451069e-06
42.3237247467041,4.00775878383025e-06
41.783678054809606,3.99105660642433e-06
41.24295234680179,3.87663036812097e-06
40.7008628845215,3.90519905250627e-06
40.1614246368408,3.80642813148517e-06
39.623893737793004,3.7892066006613e-06
39.084581375122106,3.74613334443873e-06
38.540931701660206,3.7326735829876196e-06
38.0038414001465,3.7174942710852006e-06
37.464382171630895,3.6586299231669098e-06
36.924015045166,2.58000314030794e-06
36.132581710815394,3.6145901250341902e-06
35.593225479126,3.68505117976754e-06
35.0508003234863,3.7595516822563103e-06
34.5121822357178,3.7092140402748e-06
33.9711303710937,3.71845076407525e-06
33.431871414184606,3.8003040435773497e-06
32.8938732147217,3.8686948302406895e-06
32.3533267974854,3.76651878979012e-06
31.8129997253418,4.02143081580348e-06
31.273478507995602,4.06396322904591e-06
30.7346086502075,4.1655355538005205e-06
30.196215629577605,4.2912669310308e-06
29.6552820205688,4.45281393118984e-06
28.992769241332997,4.61218799165321e-06
28.3261098861694,4.62417836850325e-06
27.5350360870361,4.9351634462967906e-06
26.9947271347046,5.10554178100261e-06
26.458070755004897,4.701440799176699e-06
25.6655206680298,5.50561403355625e-06
25.128552436828603,5.68153704904666e-06
24.5886764526367,5.74113962643686e-06
24.0507764816284,6.15443566762745e-06
23.5148782730103,6.239851697702089e-06
22.9775466918945,6.43542042913267e-06
22.439414024353,6.6291995805763294e-06
21.9014835357666,6.9126169456901705e-06
21.3655290603638,7.12404658674371e-06
20.8276119232178,7.1960741421007995e-06
20.2916288375854,7.27088841939684e-06
19.7550773620605,7.46660724606044e-06
19.2192630767822,7.80612864406913e-06
18.6848497390747,7.95064081096296e-06
18.1519746780396,8.15183997799834e-06
17.6160202026367,8.38763141055791e-06
17.082799911499,8.41890767759721e-06
16.5497522354126,8.44664326243258e-06
16.0166530609131,8.83142215187778e-06
15.483635902404801,8.834219187351519e-06
14.952362060546902,8.96843759956151e-06
14.418052673339801,9.06611508589342e-06
13.8856048583984,9.36380465595929e-06
13.3516917228699,9.25889174937292e-06
12.821647167205802,9.56140336734322e-06
12.292112827300999,9.41929036298062e-06
11.7639760971069,9.56443192158847e-06
11.2357912063599,9.62643684354108e-06
10.707951068878199,9.78395056686933e-06
9.92781352996826,1.0360998025729199e-05
9.15025997161865,1.01756123711203e-05
8.63557529449463,1.03839923084894e-05
8.12212181091309,1.0253054347977802e-05
7.60975861549377,1.0250613853982599e-05
7.10124969482422,1.0106900290653699e-05
6.59903693199158,1.01596889781002e-05
6.098445653915401,1.0053996465621e-05
5.60226511955261,1.0228487307920098e-05
5.10986971855164,9.96482877942514e-06
4.62034797668457,1.0294219877731e-05
3.91418182849884,9.99352837026989e-06
3.45898449420929,9.97471820928788e-06
2.992396235466,9.972624989632671e-06
2.54399192333221,9.912386242714979e-06
2.08675622940063,9.97512462685023e-06
1.99514067173004,9.92368244532546e-06
2.00012451410294,9.95053343352188e-06