File: Sample_Data/20210615IMH002_UTe2cfi-27_UTe3cf1-42.dat
[Header]
TITLE, default name
FILEOPENTIME,41650449.97,6/15/2021,8:36 PM
BYAPP, Resistivity, 2.1, 1.0
INFO, APPNAME, PPMS MultiVu Application, 1.5.11
INFO, , Sample1 Name
INFO, 1, Sample1 Cross Section
INFO, 1, Sample1 Length
INFO, Ohm, Sample1 Units
INFO, , Sample2 Name
INFO, 1, Sample2 Cross Section
INFO, 1, Sample2 Length
INFO, Ohm, Sample2 Units
INFO, , Sample3 Name
INFO, 1, Sample3 Cross Section
INFO, 1, Sample3 Length
INFO, Ohm, Sample3 Units
INFO, , Sample4 Name
INFO, 1, Sample4 Cross Section
INFO, 1, Sample4 Length
INFO, Ohm-m, Sample4 Units
FIELDGROUP, Resistivity,2,3,4,5,6,7,8,9,10,11,12,13,14,15,16,17,18,19,20,21,22,23,24,25,26,27,28,29,30,31,32,33,34,35,36,37,38,39,40,41
STARTUPGROUP, Resistivity
STARTUPAXIS, X, 2, LINEAR, AUTO
STARTUPAXIS, Y1, 7, LINEAR, AUTO
STARTUPAXIS, Y2, 9, LINEAR, AUTO
STARTUPAXIS, Y3, 11, LINEAR, AUTO
PLOT_APPEARANCE, ALL, HORZ_GRID_ON, VERT_GRID_ON, MARKERS_AND_LINES, ALL_LINES
DATATYPE, TIME, 2
DATATYPE, COMMENT, 1
[Data]
Comment,Time Stamp (sec),Status (code),Temperature (K),Magnetic Field (Oe),Sample Position (deg),Bridge 1 Resistivity (Ohm),Bridge 1 Excitation (uA),Bridge 2 Resistivity (Ohm),Bridge 2 Excitation (uA),Bridge 3 Resistivity (Ohm),Bridge 3 Excitation (uA),Bridge 4 Resistivity (Ohm-m),Bridge 4 Excitation (uA),Bridge 1 Std. Dev. (Ohm),Bridge 2 Std. Dev. (Ohm),Bridge 3 Std. Dev. (Ohm),Bridge 4 Std. Dev. (Ohm-m),Number of Readings,Bridge 1 Resistance (Ohms),Bridge 2 Resistance (Ohms),Bridge 3 Resistance (Ohms),Bridge 4 Resistance (Ohms),Signal 1 Vin (V),Signal 2 Vin (V),Digital Inputs (code),Drive 1 Iout (mA),Drive 1 Ipower (watts),Drive 2 Iout (mA),Drive 2 Ipower (watts),Pressure (),Map 20 (),Map 21 (),Map 22 (),Map 23 (),Map 24 (),Map 25 (),Map 26 (),Map 27 (),Map 28 (),Map 29 ()
,41658529.17,5905,1.90079998970032,24999.69140625,364.809906005859,0.449290760755539,9.89299964904785,0.00364813319407403,99.9020004272461,1547.61385742188,0.00499999988824129,,,0.00243513795630469,0.00032802651074803,7.95527833581408,,25,0.449290760755539,0.00364813319407403,1547.61385742188,
,41658741.94,5985,1.89974999427795,23280.953203125,364.809906005859,0.447395588159561,9.98999977111816,0.00341291757300496,99.9020004272461,1564.95724121094,0.00499999988824129,,,0.00951810253580629,0.000807800423925202,27.5197688062603,,25,0.447395588159561,0.00341291757300496,1564.95724121094,
,41658891.97,5985,1.89965003728867,19531.1615625,364.809906005859,0.444934456348419,9.98999977111816,0.000694191561196931,99.9020004272461,1634.19650390625,0.00499999988824129,,,0.00657358757062747,0.000584280019529602,12.251093080878,,25,0.444934456348419,0.000694191561196931,1634.19650390625,
,41659041.70,5985,1.90009999275208,15790.6310546875,364.809906005859,0.435251710414886,9.98999977111816,0.000157319538921001,99.9020004272461,1715.17105957031,0.00499999988824129,,,0.00363049722078485,0.000290416051637312,5.94906014951459,,25,0.435251710414886,0.000157319538921001,1715.17105957031,
,41659192.67,5985,1.90030002593994,12001.9223828125,364.809906005859,0.402187572717667,9.98999977111816,0.00010309775643691,99.9020004272461,1843.31053710938,0.00499999988824129,,,0.00284051782373885,0.0002054162105603,6.64582619205699,,25,0.402187572717667,0.00010309775643691,1843.31053710938,
,41659342.28,5985,1.90090000629425,8263.5341796875,364.809906005859,0.0816111278533936,9.98999977111816,-8.32418921345379e-005,99.9020004272461,2053.32459472656,0.00499999988824129,,,0.00784972404107193,0.000292297673545245,9.52253747031431,,25,0.0816111278533936,-8.32418921345379e-005,2053.32459472656,
,41659492.47,5985,1.89904999732971,4509.92779296875,364.809906005859,0.161370559334755,9.98999977111816,5.80402147170389e-005,99.9020004272461,2478.19627929688,0.00499999988824129,,,0.00935127024468874,0.000294909804687419,12.8813964293635,,25,0.161370559334755,5.80402147170389e-005,2478.19627929688,
,41659641.70,5969,1.89990001916885,982.035180664063,364.809906005859,0.00590465061191935,9.98999977111816,6.64407770091202e-005,99.9020004272461,3895.91157226563,0.00499999988824129,,,0.0029450408541083,0.000295534070198623,32.3003434023116,,25,0.00590465061191935,6.64407770091202e-005,3895.91157226563,
,41659792.95,5905,1.90049999952316,0.343302994966507,364.809906005859,0.0024826115189353,9.98999977111816,-0.000136699985232553,99.9020004272461,4244.47728515625,0.00499999988824129,,,0.00328734840517301,0.000281461949620749,7.8910432454484,,25,0.0024826115189353,-0.000136699985232553,4244.47728515625,
,41659942.53,5905,1.90030002593994,0.343302994966507,364.809906005859,0.000145171174081042,9.98999977111816,5.04033490869915e-005,99.9020004272461,4101.54483398438,0.00499999988824129,,,0.00307113560214074,0.00022388408352733,7.33711717111965,,25,0.000145171174081042,5.04033490869915e-005,4101.54483398438,
,41660091.80,5905,1.90020000934601,0.343302994966507,364.809906005859,0.00126017929054797,9.98999977111816,-9.92793153272942e-006,99.9020004272461,3935.42979492187,0.00499999988824129,,,0.00424136423924804,0.000283651929847276,6.36901820286529,,25,0.00126017929054797,-9.92793153272942e-006,3935.42979492187,
,41660242.47,5905,1.89955002069473,0.343302994966507,364.809906005859,6.11159228719771e-005,9.98999977111816,0.000142045797110768,99.9020004272461,3790.89705078125,0.00499999988824129,,,0.00228912121338695,0.000279037509789366,5.09671102690687,,25,6.11159228719771e-005,0.000142045797110768,3790.89705078125,
,41660391.66,5905,1.89955002069473,0.343302994966507,364.809906005859,-0.000389565742807463,9.98999977111816,7.94234556087758e-005,99.9020004272461,3641.99111328125,0.00499999988824129,,,0.00245711896317583,0.000288774715443869,7.85751754290974,,25,-0.000389565742807463,7.94234556087758e-005,3641.99111328125,
,41660542.50,5905,1.90109997987747,0.343302994966507,364.809906005859,-0.000244424063130282,9.98999977111816,0.000112262002294301,99.9020004272461,3484.681171875,0.00499999988824129,,,0.00223575174818826,0.000226631141441074,8.61690706482374,,25,-0.000244424063130282,0.000112262002294301,3484.681171875,
,41660691.72,5905,1.90104997158051,0.343302994966507,364.809906005859,0.000145108805736527,9.98999977111816,3.74206667765975e-005,99.9020004272461,3338.02502929687,0.00499999988824129,,,0.00230722449533078,0.000274846727275803,7.07866847875956,,25,0.000145108805736527,3.74206667765975e-005,3338.02502929687,
,41660843.17,5905,1.89804995059967,0.343302994966507,364.809906005859,-0.000145129558513872,9.98999977111816,3.28385442116996e-005,99.9020004272461,3186.3675,0.00499999988824129,,,0.00178914685904981,0.000269275242950187,7.0852230692613,,25,-0.000145129558513872,3.28385442116996e-005,3186.3675,
,41660992.22,5905,1.89965003728867,0.343302994966507,364.809906005859,0.000443099016556516,9.98999977111816,4.12391028658021e-005,99.9020004272461,3061.33319335937,0.00499999988824129,,,0.00272935076416505,0.000215846662724329,5.26086612652434,,25,0.000443099016556516,4.12391028658021e-005,3061.33319335937,
,41661142.80,5905,1.9004499912262,0.343302994966507,364.809906005859,-0.000320763797499239,9.98999977111816,0.00016801116107672,99.9020004272461,2929.52887695312,0.00499999988824129,,,0.00323557342998972,0.000267780975530167,6.94674555609749,,25,-0.000320763797499239,0.00016801116107672,2929.52887695312,
,41661292.53,5905,1.89875000715256,0.343302994966507,364.809906005859,-0.000466013433760963,9.98999977111816,0.000104625129824854,99.9020004272461,2802.09107421875,0.00499999988824129,,,0.00237937806838279,0.000240599004882152,5.42928642568633,,25,-0.000466013433760963,0.000104625129824854,2802.09107421875,
,41661441.91,5905,1.90065002441406,0.343302994966507,364.809906005859,0.00156594641390257,9.98999977111816,0.000144336858793395,99.9020004272461,2692.53119140625,0.00499999988824129,,,0.00288154553205734,0.000200391843620996,6.07724932653206,,25,0.00156594641390257,0.000144336858793395,2692.53119140625,
,41661592.31,5905,1.90009999275208,0.343302994966507,364.809906005859,0.00107697298459243,9.98999977111816,4.96396599919535e-005,99.9020004272461,2579.47122070312,0.00499999988824129,,,0.00269229977990575,0.00017746484026249,4.73510600948288,,25,0.00107697298459243,4.96396599919535e-005,2579.47122070312,
,41661742.66,5905,1.89950001239777,0.343302994966507,364.809906005859,0.00250525087816641,9.98999977111816,0.000159610602058819,99.9020004272461,2464.00165039062,0.00499999988824129,,,0.00304768962905229,0.000198035122639366,5.80874003727659,,25,0.00250525087816641,0.000159610602058819,2464.00165039062,
,41661891.77,5905,1.90069997310638,0.343302994966507,364.809906005859,0.00359008124447428,9.98999977111816,0.000102334067414631,99.9020004272461,2355.96751953125,0.00499999988824129,,,0.00201589070867922,0.000260095719477203,5.28732743815843,,25,0.00359008124447428,0.000102334067414631,2355.96751953125,
,41662042.25,5905,1.90170001983643,0.343302994966507,364.809906005859,0.00781518381554633,9.98999977111816,4.27664762537461e-005,99.9020004272461,2241.83286132813,0.00499999988824129,,,0.00286298605363307,0.000251047534980469,6.69804460506898,,25,0.00781518381554633,4.27664762537461e-005,2241.83286132813,
,41662192.19,5905,1.89974999427795,0.343302994966507,364.809906005859,0.0136306362971663,9.98999977111816,0.000107679878055933,99.9020004272461,2134.88450195313,0.00499999988824129,,,0.0023616762683852,0.000172792536248283,7.0807866789015,,25,0.0136306362971663,0.000107679878055933,2134.88450195313,
,41662342.27,5905,1.8992999792099,0.343302994966507,364.809906005859,0.0236480233818293,9.98999977111816,-8.09508321253816e-005,99.9020004272461,2029.67650390625,0.00499999988824129,,,0.00324030298194393,0.000311397098166002,4.42081391870144,,25,0.0236480233818293,-8.09508321253816e-005,2029.67650390625,
,41662491.83,5905,1.89985001087189,0.343302994966507,364.809906005859,0.0354092444479465,9.98999977111816,0.000133645237583551,99.9020004272461,1936.61353027344,0.00499999988824129,,,0.00217047719787027,0.000237787677263003,6.42668999855847,,25,0.0354092444479465,0.000133645237583551,1936.61353027344,
,41662642.67,5905,1.89904999732971,0.343302994966507,364.809906005859,0.071735738068819,9.98999977111816,-1.90921764442464e-005,99.9020004272461,1852.92067382813,0.00499999988824129,,,0.00366149465215768,0.000295774734728925,4.87000649251636,,25,0.071735738068819,-1.90921764442464e-005,1852.92067382813,
,41662791.52,5905,1.90030002593994,0.343302994966507,364.809906005859,0.151071212887764,9.98999977111816,9.08787599473726e-005,99.9020004272461,1784.33116210938,0.00499999988824129,,,0.00255539489536335,0.000238049969275131,5.92216076136254,,25,0.151071212887764,9.08787599473726e-005,1784.33116210938,
,41662942.66,5905,1.90049999952316,0.343302994966507,364.809906005859,0.222920992970467,9.98999977111816,-9.3169824758661e-005,99.9020004272461,1728.18809570313,0.00499999988824129,,,0.00389423429843327,0.000281650445049628,5.44174672512624,,25,0.222920992970467,-9.3169824758661e-005,1728.18809570313,
,41663091.72,5905,1.90055000782013,0.343302994966507,364.809906005859,0.231825385093689,9.98999977111816,1.29826788179344e-005,99.9020004272461,1681.17434082031,0.00499999988824129,,,0.00314243415839997,0.000260030683923769,3.19107690092843,,25,0.231825385093689,1.29826788179344e-005,1681.17434082031,
,41663241.55,5905,1.89844995737076,0.343302994966507,364.809906005859,0.157778967618942,9.98999977111816,-1.60374290862819e-005,99.9020004272461,1655.78722167969,0.00499999988824129,,,0.00318762920065506,0.000299968662268932,3.98322611740227,,25,0.157778967618942,-1.60374290862819e-005,1655.78722167969,
,41663392.44,5905,1.90064996480942,0.343302994966507,364.809906005859,0.0797090163826942,9.98999977111816,0.000111498312980984,99.9020004272461,1625.63837890625,0.00499999988824129,,,0.00204863616899078,0.000185473790669235,5.06062235650777,,25,0.0797090163826942,0.000111498312980984,1625.63837890625,
,41663542.23,5905,1.8996000289917,0.343302994966507,364.809906005859,0.19855061173439,9.98999977111816,1.52737429743866e-005,99.9020004272461,1609.96027832031,0.00499999988824129,,,0.00381431571811566,0.000216542665398441,4.54347289116954,,25,0.19855061173439,1.52737429743866e-005,1609.96027832031,
,41663721.69,5905,1.89910000562668,0.343302994966507,364.809906005859,0.374768929481506,9.98999977111816,1.5273741009878e-005,99.9020004272461,1595.00616210938,0.00499999988824129,,,0.00273620122781887,0.000230691649406678,4.81056811443787,,25,0.374768929481506,1.5273741009878e-005,1595.00616210938,
,41663871.86,5905,1.90015000104904,0.343302994966507,364.809906005859,0.443272405862808,9.98999977111816,6.41497157630511e-005,99.9020004272461,1580.99799316406,0.00499999988824129,,,0.00223079006278505,0.000223753798482699,5.27228544971753,,25,0.443272405862808,6.41497157630511e-005,1580.99799316406,
,41664021.80,5905,1.90049999952316,0.343302994966507,364.809906005859,0.449635301828384,9.98999977111816,0.000101570380065823,99.9020004272461,1574.60849121094,0.00499999988824129,,,0.00224031325114424,0.000216658440261977,4.08643553848095,,25,0.449635301828384,0.000101570380065823,1574.60849121094,
,41664172.84,5905,1.89994996786118,0.343302994966507,364.809906005859,0.445666338205338,9.98999977111816,4.58212234661914e-005,99.9020004272461,1571.21077148438,0.00499999988824129,,,0.0021982474036452,0.000195226261225271,4.57662277349876,,25,0.445666338205338,4.58212234661914e-005,1571.21077148438,
,41664322.20,5905,1.89965003728867,0.343302994966507,364.809906005859,0.444597181081772,9.98999977111816,1.98558638658142e-005,99.9020004272461,1563.7181640625,0.00499999988824129,,,0.00220789349163297,0.000208269662033955,5.47670896089599,,25,0.444597181081772,1.98558638658142e-005,1563.7181640625,
,41664472.75,5905,1.89899998903275,0.343302994966507,364.809906005859,0.444835668802261,9.98999977111816,9.24061364639783e-005,99.9020004272461,1555.91892578125,0.00499999988824129,,,0.00176756157437694,0.000285984237913037,5.45358330988805,,25,0.444835668802261,9.24061364639783e-005,1555.91892578125,
,41664622.17,5905,1.89879995584488,0.343302994966507,364.809906005859,0.44612352848053,9.98999977111816,8.09508310339879e-005,99.9020004272461,1555.73956054688,0.00499999988824129,,,0.00192102880846727,0.00018338669576652,5.09187891511411,,25,0.44612352848053,8.09508310339879e-005,1555.73956054688,
,41664771.84,5905,1.89925003051758,0.343302994966507,364.809906005859,0.446562772989273,9.98999977111816,0.000256598857813515,99.9020004272461,1549.92235839844,0.00499999988824129,,,0.00233814281535879,0.000238710552873602,5.96039290423824,,25,0.446562772989273,0.000256598857813515,1549.92235839844,
,41664922.47,5905,1.9006000161171,0.343302994966507,364.809906005859,0.446745208501816,9.98999977111816,0.000569710566196591,99.9020004272461,1547.9764453125,0.00499999988824129,,,0.00222494680433763,0.000231554666322493,6.15203891407668,,25,0.446745208501816,0.000569710566196591,1547.9764453125,
,41665072.08,5905,1.90049999952316,0.343302994966507,364.809906005859,0.448330808877945,9.98999977111816,0.000997375348815694,99.9020004272461,1545.33503417969,0.00499999988824129,,,0.00282057169651622,0.000318754981263607,3.9970970726096,,25,0.448330808877945,0.000997375348815694,1545.33503417969,
,41665221.83,5905,1.89965003728867,0.343302994966507,364.809906005859,0.447379413843155,9.98999977111816,0.00134638032177463,99.9020004272461,1545.94491699219,0.00499999988824129,,,0.00234306494299862,0.000214181224286981,5.77590473654455,,25,0.447379413843155,0.00134638032177463,1545.94491699219,
,41665371.98,5905,1.89995002746582,0.343302994966507,364.809906005859,0.450660828351974,9.98999977111816,0.00152890153927729,99.9020004272461,1540.30920410156,0.00499999988824129,,,0.00228043961084636,0.000282972575613634,5.20105428107036,,25,0.450660828351974,0.00152890153927729,1540.30920410156,
,41665522.34,5905,1.90030002593994,0.343302994966507,364.809906005859,0.448110268115997,9.98999977111816,0.0019359467504546,99.9020004272461,1538.501328125,0.00499999988824129,,,0.00223176219595048,0.000183205369287515,5.26630242348045,,25,0.448110268115997,0.0019359467504546,1538.501328125,
,41665672.52,5905,1.89969998598099,0.343302994966507,364.809906005859,0.450417654514313,9.98999977111816,0.00186339647043496,99.9020004272461,1533.64023925781,0.00499999988824129,,,0.00291719899306381,0.000307378133791344,6.87783183095659,,25,0.450417654514313,0.00186339647043496,1533.64023925781,
,41665822.36,5905,1.900750041008,0.343302994966507,364.809906005859,0.448430420160294,9.98999977111816,0.00214366963598877,99.9020004272461,1543.67760742188,0.00499999988824129,,,0.00155038638214633,0.00021858800426981,5.22543595999189,,25,0.448430420160294,0.00214366963598877,1543.67760742188,
,41665972.45,5905,1.9013500213623,0.343302994966507,364.809906005859,0.449930758476257,9.98999977111816,0.00204209927003831,99.9020004272461,1536.46168945313,0.00499999988824129,,,0.00376611460598979,0.000289772722006533,5.26000529754052,,25,0.449930758476257,0.00204209927003831,1536.46168945313,
,41666121.73,5905,1.9006000161171,0.343302994966507,364.809906005859,0.448974931240082,9.98999977111816,0.00209402995184064,99.9020004272461,1535.34307617188,0.00499999988824129,,,0.00225301845425657,0.000262597313618401,3.55347974611712,,25,0.448974931240082,0.00209402995184064,1535.34307617188,
,41666272.63,5905,1.90074998140335,0.343302994966507,364.809906005859,0.449320682287216,9.98999977111816,0.00224371262826025,99.9020004272461,1530.7075,0.00499999988824129,,,0.00296088968381512,0.000334287365270471,4.70085491088353,,25,0.449320682287216,0.00224371262826025,1530.7075,
,41666422.70,5905,1.89839994907379,0.343302994966507,364.809906005859,0.449207040071487,9.98999977111816,0.00229793442413211,99.9020004272461,1535.03066894531,0.00499999988824129,,,0.00228061171072473,0.000220603782478006,4.25957138075809,,25,0.449207040071487,0.00229793442413211,1535.03066894531,
,41666572.27,5905,1.90119999647141,0.343302994966507,364.809906005859,0.449496899843216,9.98999977111816,0.00243692548014224,99.9020004272461,1534.68670410156,0.00499999988824129,,,0.00190875614965784,0.00019053033526545,3.78699283226256,,25,0.449496899843216,0.00243692548014224,1534.68670410156,
,41666722.59,5905,1.89974999427795,0.343302994966507,364.809906005859,0.450158450603485,9.98999977111816,0.00233077296055853,99.9020004272461,1536.10175292969,0.00499999988824129,,,0.0020324249706296,0.000216065399588385,4.60117851804242,,25,0.450158450603485,0.00233077296055853,1536.10175292969,
,41666871.39,5905,1.89784997701645,0.343302994966507,364.809906005859,0.449933111667633,9.98999977111816,0.00238041263073683,99.9020004272461,1537.76166992188,0.00499999988824129,,,0.00253533813915039,0.000207795854778372,4.35101997926879,,25,0.449933111667633,0.00238041263073683,1537.76166992188,
,41667021.89,5905,1.9006000161171,0.343302994966507,364.809906005859,0.449102407693863,9.98999977111816,0.00244227128103375,99.9020004272461,1537.58384277344,0.00499999988824129,,,0.00231113173418821,0.00022244931652791,4.2321696674434,,25,0.449102407693863,0.00244227128103375,1537.58384277344,
,41667171.63,5905,1.89980000257492,0.343302994966507,364.809906005859,0.449097738265991,9.98999977111816,0.00245372658595443,99.9020004272461,1535.38151855469,0.00499999988824129,,,0.00283399326825889,0.000234087206997786,5.43152166560031,,25,0.449097738265991,0.00245372658595443,1535.38151855469,
,41667321.89,5905,1.90170001983643,0.343302994966507,364.809906005859,0.448724383115768,9.98999977111816,0.00252398580312729,99.9020004272461,1533.49214355469,0.00499999988824129,,,0.00264228158253256,0.000261945774604316,6.39696273543795,,25,0.448724383115768,0.00252398580312729,1533.49214355469,
,41667472.17,5905,1.90015000104904,0.343302994966507,364.809906005859,0.448947200775146,9.98999977111816,0.00245907238684595,99.9020004272461,1537.00748535156,0.00499999988824129,,,0.002263552052806,0.000229868496709912,5.01290442654634,,25,0.448947200775146,0.00245907238684595,1537.00748535156,
,41667622.27,5905,1.89994996786118,0.343302994966507,364.809906005859,0.449802327156067,9.98999977111816,0.00250718470662832,99.9020004272461,1530.79420898438,0.00499999988824129,,,0.00273446805292492,0.000254361670724005,6.33488980000911,,25,0.449802327156067,0.00250718470662832,1530.79420898438,
,41667772.66,5905,1.89910000562668,0.343302994966507,364.809906005859,0.449941219091415,9.98999977111816,0.00240255953278393,99.9020004272461,1535.61044921875,0.00499999988824129,,,0.00211185846062655,0.000239418007393209,5.08740608608966,,25,0.449941219091415,0.00240255953278393,1535.61044921875,
,41667921.83,5905,1.8996000289917,0.343302994966507,364.809906005859,0.450352796316147,9.98999977111816,0.0024109600763768,99.9020004272461,1532.45291503906,0.00499999988824129,,,0.00324038787219483,0.000236774968420378,5.3355802812029,,25,0.450352796316147,0.0024109600763768,1532.45291503906,
,41668072.44,5905,1.8986000418663,0.343302994966507,364.809906005859,0.450378988981247,9.98999977111816,0.00240255954675376,99.9020004272461,1532.95301269531,0.00499999988824129,,,0.00339120252454083,0.000274220033035062,5.83557131822832,,25,0.450378988981247,0.00240255954675376,1532.95301269531,
,41668222.03,5905,1.89794999361038,0.343302994966507,364.809906005859,0.450274204015732,9.98999977111816,0.0024002684885636,99.9020004272461,1533.10271484375,0.00499999988824129,,,0.00289720694671414,0.000302815149260211,5.57508431424532,,25,0.450274204015732,0.0024002684885636,1533.10271484375,
,41668371.78,5905,1.89849996566772,0.343302994966507,364.809906005859,0.449194467067718,9.98999977111816,0.00253238636069,99.9020004272461,1534.2065234375,0.00499999988824129,,,0.00213665902422533,0.000239734500409248,6.08300716958507,,25,0.449194467067718,0.00253238636069,1534.2065234375,
,41668521.92,5905,1.89955002069473,0.343302994966507,364.809906005859,0.452128251791,9.98999977111816,0.00239186794031411,99.9020004272461,1531.73401367187,0.00499999988824129,,,0.00328320469428042,0.000242554481670922,4.71842066297654,,25,0.452128251791,0.00239186794031411,1531.73401367187,
,41668671.98,5905,1.89895004034042,0.343302994966507,364.809906005859,0.44919890165329,9.98999977111816,0.00261715559288859,99.9020004272461,1535.98110351562,0.00499999988824129,,,0.00210280522488464,0.000259985819035928,5.01204722721562,,25,0.44919890165329,0.00261715559288859,1535.98110351562,
,41668822.02,5905,1.90074998140335,0.343302994966507,364.809906005859,0.451992229223251,9.98999977111816,0.00241477855481207,99.9020004272461,1532.95791015625,0.00499999988824129,,,0.00265140949697183,0.000260669125174042,5.53372806818663,,25,0.451992229223251,0.00241477855481207,1532.95791015625,
,41668972.02,5905,1.90049999952316,0.343302994966507,364.809906005859,0.449076271057129,9.98999977111816,0.00248045563697815,99.9020004272461,1534.09976074219,0.00499999988824129,,,0.00223614217053942,0.000242398155101332,3.3047752118617,,25,0.449076271057129,0.00248045563697815,1534.09976074219,
,41669122.27,5905,1.90129995346069,0.343302994966507,364.809906005859,0.453291831016541,9.98999977111816,0.00227578749414533,99.9020004272461,1530.21129394531,0.00499999988824129,,,0.00319136334588761,0.000211983346316619,4.27005336714262,,25,0.453291831016541,0.00227578749414533,1530.21129394531,
,41669271.94,5905,1.90020000934601,0.343302994966507,364.809906005859,0.450425771474838,9.98999977111816,0.00252704052254558,99.9020004272461,1536.8520703125,0.00499999988824129,,,0.00220402630173255,0.000163781953937606,4.02707111010913,,25,0.450425771474838,0.00252704052254558,1536.8520703125,
,41669421.70,5905,1.90030002593994,0.343302994966507,364.809906005859,0.453206498622894,9.98999977111816,0.00238423104863614,99.9020004272461,1531.80956542969,0.00499999988824129,,,0.00241806737545192,0.000217437636893908,3.84815545704344,,25,0.453206498622894,0.00238423104863614,1531.80956542969,
,41669571.91,5905,1.90030002593994,0.343302994966507,364.809906005859,0.450155111551285,9.98999977111816,0.00257591651752591,99.9020004272461,1535.4015234375,0.00499999988824129,,,0.00185941674195806,0.000184546991993139,4.58327253574087,,25,0.450155111551285,0.00257591651752591,1535.4015234375,
,41669722.14,5905,1.90005004405975,0.343302994966507,364.809906005859,0.452918794155121,9.98999977111816,0.00230709867086262,99.9020004272461,1531.43771484375,0.00499999988824129,,,0.0018419535975052,0.000236908006972248,3.78961200047803,,25,0.452918794155121,0.00230709867086262,1531.43771484375,
,41669872.42,5905,1.90049999952316,0.343302994966507,364.809906005859,0.449244697093964,9.98999977111816,0.00260188188403845,99.9020004272461,1534.90888183594,0.00499999988824129,,,0.00217062553981663,0.000282745784532062,4.89963504782557,,25,0.449244697093964,0.00260188188403845,1534.90888183594,
,41670022.89,5905,1.90049999952316,0.343302994966507,364.809906005859,0.453257946968079,9.98999977111816,0.0022643322031945,99.9020004272461,1531.03971679687,0.00499999988824129,,,0.0019013588179957,0.000239863358642204,5.6839404838118,,25,0.453257946968079,0.0022643322031945,1531.03971679687,
,41670172.03,5905,1.89885002374649,0.343302994966507,364.809906005859,0.449137780666351,9.98999977111816,0.00255529695190489,99.9020004272461,1535.13997558594,0.00499999988824129,,,0.00201153951724469,0.000233872850464096,3.95697563453333,,25,0.449137780666351,0.00255529695190489,1535.13997558594,
,41670322.89,5905,1.8992999792099,0.343302994966507,364.809906005859,0.452859020233154,9.98999977111816,0.00231626291759312,99.9020004272461,1536.07755859375,0.00499999988824129,,,0.00229396369964076,0.000235242883986644,4.38028411079376,,25,0.452859020233154,0.00231626291759312,1536.07755859375,
,41670471.63,5905,1.900750041008,0.343302994966507,364.809906005859,0.449568380117416,9.98999977111816,0.00250031149946153,99.9020004272461,1537.44807617188,0.00499999988824129,,,0.00257482992006238,0.000208409624868148,5.37667810001362,,25,0.449568380117416,0.00250031149946153,1537.44807617188,
,41670622.64,5905,1.90030002593994,0.343302994966507,364.809906005859,0.452249630689621,9.98999977111816,0.00230328024830669,99.9020004272461,1533.22141601563,0.00499999988824129,,,0.00275987891393859,0.000263880116473013,5.07444020748689,,25,0.452249630689621,0.00230328024830669,1533.22141601563,
,41670772.39,5905,1.90020000934601,0.343302994966507,364.809906005859,0.449458709955215,9.98999977111816,0.00261333719827235,99.9020004272461,1534.71415039063,0.00499999988824129,,,0.00270204463033896,0.000280561202564985,5.3029666207846,,25,0.449458709955215,0.00261333719827235,1534.71415039063,
,41670922.42,5905,1.90035003423691,0.343302994966507,364.809906005859,0.451684713363647,9.98999977111816,0.00248580144252628,99.9020004272461,1535.33104492188,0.00499999988824129,,,0.00340437126778471,0.00028757658576151,5.03103887115183,,25,0.451684713363647,0.00248580144252628,1535.33104492188,
,41671072.19,5905,1.90030002593994,0.343302994966507,364.809906005859,0.4502945291996,9.98999977111816,0.00257744387723506,99.9020004272461,1533.58446777344,0.00499999988824129,,,0.00258517236806497,0.000268053081673472,6.61578889690181,,25,0.4502945291996,0.00257744387723506,1533.58446777344,
,41671222.05,5905,1.9004499912262,0.343302994966507,364.809906005859,0.450728954076767,9.98999977111816,0.0027065070066601,99.9020004272461,1533.33971679688,0.00499999988824129,,,0.00259698967744967,0.000266650395349691,6.26021322942756,,25,0.450728954076767,0.0027065070066601,1533.33971679688,
,41671372.14,5905,1.89985001087189,0.343302994966507,364.809906005859,0.45211895942688,9.98999977111816,0.00260799136012793,99.9020004272461,1530.40265625,0.00499999988824129,,,0.00332199702857954,0.000293299606328599,6.46564871719202,,25,0.45211895942688,0.00260799136012793,1530.40265625,
,41671521.89,5905,1.90034997463226,0.343302994966507,364.809906005859,0.449545030593872,9.98999977111816,0.00265457627363503,99.9020004272461,1532.08224121094,0.00499999988824129,,,0.00248506660829233,0.000235847040078941,4.64451938901145,,25,0.449545030593872,0.00265457627363503,1532.08224121094,
,41671671.91,5905,1.89915001392365,0.343302994966507,364.809906005859,0.450951189994812,9.98999977111816,0.00248580142389983,99.9020004272461,1530.20399414062,0.00499999988824129,,,0.00343556114052922,0.000294836636780084,7.01884738344445,,25,0.450951189994812,0.00248580142389983,1530.20399414062,
,41671822.13,5905,1.89850002527237,0.343302994966507,364.809906005859,0.449563095569611,9.98999977111816,0.00255911538377404,99.9020004272461,1534.44174316406,0.00499999988824129,,,0.00237577766933703,0.000213455686229759,5.10788301401974,,25,0.449563095569611,0.00255911538377404,1534.44174316406,
,41671971.84,5905,1.89924997091293,0.343302994966507,364.809906005859,0.452062791585922,9.98999977111816,0.00242776121944189,99.9020004272461,1532.70713867188,0.00499999988824129,,,0.00242356749397678,0.000259916257389462,5.06422616294298,,25,0.452062791585922,0.00242776121944189,1532.70713867188,
,41672121.91,5905,1.89745002985001,0.343302994966507,364.809906005859,0.450112171173096,9.98999977111816,0.0025713344104588,99.9020004272461,1535.90969238281,0.00499999988824129,,,0.00194495316392385,0.000232499773037122,6.0086328053566,,25,0.450112171173096,0.0025713344104588,1535.90969238281,
,41672272.58,5905,1.90170001983643,0.343302994966507,364.809906005859,0.452884161472321,9.98999977111816,0.00238957686815411,99.9020004272461,1531.41150878906,0.00499999988824129,,,0.00251069275688644,0.000212579504551542,3.55972549783076,,25,0.452884161472321,0.00238957686815411,1531.41150878906,
,41672422.66,5905,1.90065002441406,0.343302994966507,364.809906005859,0.449339820146561,9.98999977111816,0.00254766008816659,99.9020004272461,1535.76145996094,0.00499999988824129,,,0.00218700290827349,0.000235698605049721,4.81412596408279,,25,0.449339820146561,0.00254766008816659,1535.76145996094,
,41672571.94,5905,1.9002999663353,0.343302994966507,364.809906005859,0.452555066347122,9.98999977111816,0.00231015340425074,99.9020004272461,1530.3796875,0.00499999988824129,,,0.00241480760697799,0.000251205427405842,5.87988489578146,,25,0.452555066347122,0.00231015340425074,1530.3796875,
,41672721.92,5905,1.89994996786118,0.343302994966507,364.809906005859,0.451224856376648,9.98999977111816,0.00253391371108592,99.9020004272461,1539.12053710937,0.00499999988824129,,,0.00242724698544417,0.000224900331191629,5.4186345301477,,25,0.451224856376648,0.00253391371108592,1539.12053710937,
,41672872.06,5905,1.90119999647141,0.343302994966507,364.809906005859,0.453749366998672,9.98999977111816,0.00230328019708395,99.9020004272461,1533.36517089844,0.00499999988824129,,,0.00208221907468909,0.000226409657532911,5.42419164452991,,25,0.453749366998672,0.00230328019708395,1533.36517089844,
,41673022.19,5905,1.89875000715256,0.343302994966507,364.809906005859,0.450518958568573,9.98999977111816,0.00260875506326556,99.9020004272461,1534.61881347656,0.00499999988824129,,,0.00204065407944612,0.000243116518594826,5.53071141251675,,25,0.450518958568573,0.00260875506326556,1534.61881347656,
,41673172.75,5905,1.90095001459122,0.343302994966507,364.809906005859,0.453356243371964,9.98999977111816,0.00241248749196529,99.9020004272461,1531.17891601563,0.00499999988824129,,,0.00211335827258108,0.000203768513986939,4.88519803357904,,25,0.453356243371964,0.00241248749196529,1531.17891601563,
,41673322.09,5905,1.90149998664856,0.343302994966507,364.809906005859,0.449334573745728,9.98999977111816,0.00254536905325949,99.9020004272461,1535.99750488281,0.00499999988824129,,,0.00230889707647684,0.000261985845041201,5.48651485971547,,25,0.449334573745728,0.00254536905325949,1535.99750488281,
,41673472.08,5905,1.90015000104904,0.343302994966507,364.809906005859,0.453550490140915,9.98999977111816,0.00238499473780394,99.9020004272461,1530.58712402344,0.00499999988824129,,,0.00223584872072976,0.000232950850481848,3.67157755766828,,25,0.453550490140915,0.00238499473780394,1530.58712402344,
,41673621.38,5905,1.90180003643036,0.343302994966507,364.809906005859,0.450081608295441,9.98999977111816,0.00264235726557672,99.9020004272461,1538.35677246094,0.00499999988824129,,,0.00356191331363733,0.000216475307832578,5.64504462311534,,25,0.450081608295441,0.00264235726557672,1538.35677246094,
,41673772.20,5905,1.90025001764297,0.343302994966507,364.809906005859,0.452370792627335,9.98999977111816,0.00240179582964629,99.9020004272461,1529.27114257812,0.00499999988824129,,,0.00378087226305684,0.000262890304278539,6.34451152291194,,25,0.452370792627335,0.00240179582964629,1529.27114257812,
,41673921.70,5905,1.90175002813339,0.343302994966507,364.809906005859,0.450610903501511,9.98999977111816,0.00267214108258486,99.9020004272461,1535.27763671875,0.00499999988824129,,,0.00287449040886286,0.00017766847204948,5.12552861905276,,25,0.450610903501511,0.00267214108258486,1535.27763671875,
,41674072.66,5905,1.89995002746582,0.343302994966507,364.809906005859,0.45186337351799,9.98999977111816,0.00240408693440259,99.9020004272461,1531.97610839844,0.00499999988824129,,,0.00306441875837225,0.000348960705806827,6.26999780435617,,25,0.45186337351799,0.00240408693440259,1531.97610839844,
,41674222.41,5905,1.90095001459122,0.343302994966507,364.809906005859,0.450481181144714,9.98999977111816,0.00257286177482456,99.9020004272461,1531.14282714844,0.00499999988824129,,,0.00209036986990151,0.00024759717161441,5.82825449428631,,25,0.450481181144714,0.00257286177482456,1531.14282714844,
,41674371.95,5905,1.89999997615814,0.343302994966507,364.809906005859,0.451497088670731,9.98999977111816,0.00256904332898557,99.9020004272461,1535.80201171875,0.00499999988824129,,,0.00329333228041971,0.00024083887519688,5.11610684359025,,25,0.451497088670731,0.00256904332898557,1535.80201171875,
,41674521.72,5905,1.90039998292923,0.343302994966507,364.809906005859,0.451027082204819,9.98999977111816,0.00253315003123134,99.9020004272461,1533.21349121094,0.00499999988824129,,,0.00262994945102576,0.000293335377493868,4.27362851025686,,25,0.451027082204819,0.00253315003123134,1533.21349121094,
,41674672.23,5905,1.90025001764297,0.343302994966507,364.809906005859,0.449914479255676,9.98999977111816,0.00257591649889946,99.9020004272461,1532.52944824219,0.00499999988824129,,,0.00250507726996,0.000197004657119822,4.31423546703777,,25,0.449914479255676,0.00257591649889946,1532.52944824219,
,41674822.17,5905,1.89910000562668,0.343302994966507,364.809906005859,0.451847702264786,9.98999977111816,0.00249725674744695,99.9020004272461,1532.45416503906,0.00499999988824129,,,0.00246597826012641,0.000293249878712979,5.06809875846326,,25,0.451847702264786,0.00249725674744695,1532.45416503906,
,41674971.92,5905,1.90174996852875,0.343302994966507,364.809906005859,0.450203820466995,9.98999977111816,0.00266450420953333,99.9020004272461,1532.19865722656,0.00499999988824129,,,0.00278315112200512,0.000207961411040532,4.79996190662514,,25,0.450203820466995,0.00266450420953333,1532.19865722656,
,41675121.91,5905,1.89904999732971,0.343302994966507,364.809906005859,0.453187855482101,9.98999977111816,0.00243310702499002,99.9020004272461,1526.0094921875,0.00499999988824129,,,0.00283212145685964,0.000272962314166212,4.62951348366881,,25,0.453187855482101,0.00243310702499002,1526.0094921875,
,41675272.33,5905,1.90049999952316,0.343302994966507,364.809906005859,0.449411833286285,9.98999977111816,0.00263624778017402,99.9020004272461,1533.71705078125,0.00499999988824129,,,0.00256030711152681,0.000203198158542865,3.99333722515059,,25,0.449411833286285,0.00263624778017402,1533.71705078125,
,41675422.44,5905,1.8982999920845,0.343302994966507,364.809906005859,0.453343749046326,9.98999977111816,0.00236895730253309,99.9020004272461,1524.90341308594,0.00499999988824129,,,0.0021067149800036,0.000268157465214521,5.05738188374286,,25,0.453343749046326,0.00236895730253309,1524.90341308594,
,41675572.34,5905,1.90015000104904,0.343302994966507,364.809906005859,0.450097364187241,9.98999977111816,0.00262173771858215,99.9020004272461,1534.55798339844,0.00499999988824129,,,0.00222324861584487,0.000220196302880165,3.51515985166788,,25,0.450097364187241,0.00262173771858215,1534.55798339844,
,41675722.39,5905,1.90225005149841,0.343302994966507,364.809906005859,0.453636813163757,9.98999977111816,0.00243387071415782,99.9020004272461,1529.98217773438,0.00499999988824129,,,0.00290364171865782,0.000194336943032508,5.4553918301425,,25,0.453636813163757,0.00243387071415782,1529.98217773438,
,41675871.78,5905,1.8996000289917,0.343302994966507,364.809906005859,0.449373633861542,9.98999977111816,0.00262631987221539,99.9020004272461,1535.762421875,0.00499999988824129,,,0.00206338851084779,0.000159469874612829,4.91907729948183,,25,0.449373633861542,0.00262631987221539,1535.762421875,
,41676022.42,5905,1.90155005455017,0.343302994966507,364.809906005859,0.453720841407776,9.98999977111816,0.00233993722591549,99.9020004272461,1529.18405761719,0.00499999988824129,,,0.00219928544925524,0.000292955343994214,4.98435591461226,,25,0.453720841407776,0.00233993722591549,1529.18405761719,
,41676171.92,5905,1.90005004405975,0.343302994966507,364.809906005859,0.44982670545578,9.98999977111816,0.00263853886164725,99.9020004272461,1535.02337890625,0.00499999988824129,,,0.00220475478596236,0.000217617321418684,6.0288453421149,,25,0.44982670545578,0.00263853886164725,1535.02337890625,
,41676321.98,5905,1.89980000257492,0.343302994966507,364.809906005859,0.452729451656342,9.98999977111816,0.00234833777416497,99.9020004272461,1532.6664453125,0.00499999988824129,,,0.00260401185075675,0.00025466417201118,5.19789545498965,,25,0.452729451656342,0.00234833777416497,1532.6664453125,
,41676472.73,5905,1.90055000782013,0.343302994966507,364.809906005859,0.448672391176224,9.98999977111816,0.00264693940058351,99.9020004272461,1532.29690429688,0.00499999988824129,,,0.00244860583770254,0.000207807126702919,6.25916619224098,,25,0.448672391176224,0.00264693940058351,1532.29690429688,
,41676622.41,5905,1.90020000934601,0.343302994966507,364.809906005859,0.453369700908661,9.98999977111816,0.00253009527921677,99.9020004272461,1533.63479492188,0.00499999988824129,,,0.00182810010833423,0.00025150246997318,4.1530390197844,,25,0.453369700908661,0.00253009527921677,1533.63479492188,
,41676772.48,5905,1.89885002374649,0.343302994966507,364.809906005859,0.449728754758835,9.98999977111816,0.00260875503532588,99.9020004272461,1537.01751464844,0.00499999988824129,,,0.00254597740683189,0.000234072250106858,6.3356231687623,,25,0.449728754758835,0.00260875503532588,1537.01751464844,
,41676922.33,5905,1.8994500041008,0.343302994966507,364.809906005859,0.451520764827728,9.98999977111816,0.00249038357287645,99.9020004272461,1537.59072265625,0.00499999988824129,,,0.00365978246430661,0.000302119072925017,5.88962484132685,,25,0.451520764827728,0.00249038357287645,1537.59072265625,
,41677072.06,5905,1.8994500041008,0.343302994966507,364.809906005859,0.450343337059021,9.98999977111816,0.00271108913235366,99.9020004272461,1533.32430664063,0.00499999988824129,,,0.00295846302781015,0.000260046366391012,5.36980315286737,,25,0.450343337059021,0.00271108913235366,1533.32430664063,
,41677222.23,5905,1.9006000161171,0.343302994966507,364.809906005859,0.450243453979492,9.98999977111816,0.00258584449533373,99.9020004272461,1536.60916503906,0.00499999988824129,,,0.00322041936512188,0.000378856564582151,6.48596805707697,,25,0.450243453979492,0.00258584449533373,1536.60916503906,
,41677372.38,5905,1.90079998970032,0.343302994966507,364.809906005859,0.449851503372192,9.98999977111816,0.00266832262277603,99.9020004272461,1529.76229003906,0.00499999988824129,,,0.0025915816150825,0.000244098097353912,5.04858952369831,,25,0.449851503372192,0.00266832262277603,1529.76229003906,
,41677522.73,5905,1.90090000629425,0.343302994966507,364.809906005859,0.449932640790939,9.98999977111816,0.00263701148331165,99.9020004272461,1532.66697753906,0.00499999988824129,,,0.00312394069039303,0.000264842012783658,4.51138174766633,,25,0.449932640790939,0.00263701148331165,1532.66697753906,
,41677672.19,5905,1.89980000257492,0.343302994966507,364.809906005859,0.451461024284363,9.98999977111816,0.00261486453935504,99.9020004272461,1532.750234375,0.00499999988824129,,,0.00290991250094786,0.000238368235673034,4.79994606768371,,25,0.451461024284363,0.00261486453935504,1532.750234375,
,41677821.61,5905,1.89939999580383,0.343302994966507,364.809906005859,0.450926682949066,9.98999977111816,0.00260111818090081,99.9020004272461,1537.6847265625,0.00499999988824129,,,0.00201993338286004,0.000202000680550236,4.71904307379568,,25,0.450926682949066,0.00260111818090081,1537.6847265625,
,41677972.70,5905,1.89924997091293,0.343302994966507,364.809906005859,0.452269759178162,9.98999977111816,0.00253620480187237,99.9020004272461,1534.90375976563,0.00499999988824129,,,0.00318955821576655,0.000202101675949154,5.28062267755322,,25,0.452269759178162,0.00253620480187237,1534.90375976563,
,41678121.88,5905,1.89940005540848,0.343302994966507,364.809906005859,0.450084005594254,9.98999977111816,0.00267748687416315,99.9020004272461,1533.45268066406,0.00499999988824129,,,0.00240453770802314,0.000176333977435487,4.69403834522583,,25,0.450084005594254,0.00267748687416315,1533.45268066406,
,41678272.67,5905,1.90094995498657,0.343302994966507,364.809906005859,0.451879321336746,9.98999977111816,0.0024201243929565,99.9020004272461,1529.55767578125,0.00499999988824129,,,0.00325394809152448,0.000211037564393381,4.36059121149339,,25,0.451879321336746,0.0024201243929565,1529.55767578125,
,41678421.83,5905,1.89904999732971,0.343302994966507,364.809906005859,0.451304721832275,9.98999977111816,0.00263395672664046,99.9020004272461,1534.75697265625,0.00499999988824129,,,0.00278080131173245,0.000245776770576055,3.67191059977947,,25,0.451304721832275,0.00263395672664046,1534.75697265625,
,41678602.61,5905,1.89964997768402,0.343302994966507,364.809906005859,0.449479207992554,9.98999977111816,0.00259195394814014,99.9020004272461,1537.00570800781,0.00499999988824129,,,0.00263239827192431,0.000222996643246872,4.50724672365149,,25,0.449479207992554,0.00259195394814014,1537.00570800781,
,41678751.78,5905,1.90099996328354,0.343302994966507,364.809906005859,0.453532946109772,9.98999977111816,0.00244456230662763,99.9020004272461,1535.62700195313,0.00499999988824129,,,0.00230265113291871,0.000201942896792443,4.46199944621725,,25,0.453532946109772,0.00244456230662763,1535.62700195313,
,41678901.81,5905,1.89920002222061,0.343302994966507,364.809906005859,0.450775321722031,9.98999977111816,0.00262555614113808,99.9020004272461,1529.49719726562,0.00499999988824129,,,0.00279267282835423,0.000228922775624187,4.47286768287546,,25,0.450775321722031,0.00262555614113808,1529.49719726562,
,41679052.70,5905,1.89989995956421,0.343302994966507,364.809906005859,0.45357469201088,9.98999977111816,0.00245143551379442,99.9020004272461,1531.33161621094,0.00499999988824129,,,0.00248363042965044,0.000227317178955221,5.35533710232891,,25,0.45357469201088,0.00245143551379442,1531.33161621094,
,41679202.94,5905,1.90034997463226,0.343302994966507,364.809906005859,0.450417758226395,9.98999977111816,0.00272025336511433,99.9020004272461,1535.93698730469,0.00499999988824129,,,0.0023082190966265,0.000274349738057049,5.47594243064087,,25,0.450417758226395,0.00272025336511433,1535.93698730469,
,41679351.98,5905,1.89804995059967,0.343302994966507,364.809906005859,0.453253128528595,9.98999977111816,0.00247358243912458,99.9020004272461,1531.37393554687,0.00499999988824129,,,0.00218042640366465,0.000187070592269727,4.82523719181315,,25,0.453253128528595,0.00247358243912458,1531.37393554687,
,41679502.44,5905,1.90005004405975,0.343302994966507,364.809906005859,0.449051095247269,9.98999977111816,0.00265533998608589,99.9020004272461,1535.8508984375,0.00499999988824129,,,0.00181963513069981,0.00021754499667537,6.13165456696813,,25,0.449051095247269,0.00265533998608589,1535.8508984375,
,41679652.34,5905,1.89950001239777,0.343302994966507,364.809906005859,0.453861424922943,9.98999977111816,0.00245678133331239,99.9020004272461,1529.99167480469,0.00499999988824129,,,0.00261903637201239,0.000233750615069578,5.88266608977724,,25,0.453861424922943,0.00245678133331239,1529.99167480469,
,41679802.53,5905,1.90079998970032,0.343302994966507,364.809906005859,0.451439102888107,9.98999977111816,0.00269657908938825,99.9020004272461,1532.81766113281,0.00499999988824129,,,0.00316110599824329,0.000306441305904758,5.80694554473331,,25,0.451439102888107,0.00269657908938825,1532.81766113281,
,41679952.14,5905,1.90110003948212,0.343302994966507,364.809906005859,0.453160667419434,9.98999977111816,0.00252627689857036,99.9020004272461,1528.77427246094,0.00499999988824129,,,0.00328114409649623,0.000357741559643011,4.83842376862771,,25,0.453160667419434,0.00252627689857036,1528.77427246094,
,41680162.20,5905,1.89999997615814,0.343302994966507,364.809906005859,0.452061983346939,9.98999977111816,0.00279814945533872,99.9020004272461,1532.75919921875,0.00499999988824129,,,0.00256383518218565,0.000201552624991517,6.44691495760067,,25,0.452061983346939,0.00279814945533872,1532.75919921875,
,41680252.61,5905,1.89864999055862,0.343302994966507,364.809906005859,0.453262060880661,9.98999977111816,0.00257744391448796,99.9020004272461,1528.003046875,0.00499999988824129,,,0.00298756131373311,0.000405797470882696,5.03856606898225,,25,0.453262060880661,0.00257744391448796,1528.003046875,