File: Sample_Data/ADR__CaSb2-b3-1-resistance3_R(0p1-3K)_500uA_0OePerpXtal_20210415.dat
[Header]
; Copyright 1997-2010, Quantum Design, Inc. All rights reserved.
TITLE, CaSb2-b3-1-resistance3
FILEOPENTIME,3827622213.077,4/15/2021,4:24 AM
BYAPP, LogDynaCoolData, 1.0, 2.2
INFO, APPNAME, DynaCool MultiVu Application, Release 1.2.5.1
FIELDGROUP, Standard,2,3,4,5,6,7,8,9,11,10
FIELDGROUP, Diagnostic,2,12,13,14,15,16,17,18,19,20,21,22,23,24,25,26,27,28,29,30,31,32,33
FIELDGROUP, User,2,50,51,52,53,54,55,56,57,58,59,60,61,62,63,64,65
STARTUPGROUP, All
STARTUPAXIS, X, 2, LINEAR, AUTO
STARTUPAXIS, Y1, 3, LINEAR, AUTO
TIMEMODE, MINUTES, RELATIVE
PLOT_APPEARANCE, ALL, HORZ_GRID_ON, VERT_GRID_ON, MARKERS_AND_LINES, ALL_LINES
RECORDS, ALL_RECORDS
DATATYPE, TIME, 2
DATATYPE, COMMENT, 1
[Data]
Comment,Time Stamp (sec),Temperature (K),Magnetic Field (Oe),System Pres (Torr),Chamber Status (code),Temperature Status (code),Field Status (code),Cryostat Status (code),Control Therm (ID),Sample Therm (ID),Block Temp (K),Neck Temp (K),High Neck Temp (K),Control Temp (K),1st Stage Temp (K),2nd Stage Temp (K),Magnet Temp (K),Impedance Temp (K),Pot Liquid level (%),Block Power (W),Neck Heater Power (W),High Neck Heater Power (W),1st Stage Heater Power (W),2nd Stage Heater Power (W),Magnet Voltage (V),Impedance Heater Power (W),Pot Power (W),CFE Flow (SCCM),Pump Flow (uncal SCCM),Tank Pressure (Torr),Annulus Pressure (Torr),Compressor State (code),Channel 1 Resistance (Ohm),Channel 1 Current (uA),Channel 2 Resistance (Ohm),Channel 2 Current (uA),ADR Temp (K),Resistance of Therm.,Channel 7,Channel 8,Channel 9,Channel 10,Channel 11,Channel 12,Channel 13,Channel 14,Channel 15,Channel 16
,3827622213.09,1.900099,0.5150002,9.9e-006,7,1,4,7,643,643,,,,,,,,,,,,,,,,,,,,,,,-0.000021,499.995148,,99.989029,1.295739,4135.194824,,,,,,,,,,
,3827622232.57,1.90011,0.4794829,9.9e-006,7,1,4,7,643,643,,,,,,,,,,,,,,,,,,,,,,,-0.000013,499.995148,,99.989029,1.295739,4158.698242,,,,,,,,,,
,3827622251.70,1.900085,0.6037933,9.9e-006,7,1,4,7,643,643,,,,,,,,,,,,,,,,,,,,,,,-0.000050,499.995148,,99.989029,1.295739,4142.294434,,,,,,,,,,
,3827622270.52,1.900048,0.6037933,9.9e-006,7,1,4,7,643,643,,,,,,,,,,,,,,,,,,,,,,,-0.000020,499.995148,,99.989029,1.295739,4125.588379,,,,,,,,,,
,3827622289.14,1.900227,0.6570692,9.9e-006,7,1,4,7,643,643,,,,,,,,,,,,,,,,,,,,,,,-0.000033,499.995148,,99.989029,1.295739,4107.221191,,,,,,,,,,
,3827622308.10,1.89995,0.5150002,9.9e-006,7,1,4,7,643,643,,,,,,,,,,,,,,,,,,,,,,,0.000008,499.995148,,99.989029,1.295739,4091.149414,,,,,,,,,,
,3827622326.83,1.900048,0.6393105,9.9e-006,7,1,4,7,643,643,,,,,,,,,,,,,,,,,,,,,,,-0.000019,499.995148,,99.989029,1.295739,4072.751465,,,,,,,,,,
,3827622345.75,1.900027,0.6570692,9.9e-006,7,1,4,7,643,643,,,,,,,,,,,,,,,,,,,,,,,-0.000006,499.995148,,99.989029,1.295739,4059.247803,,,,,,,,,,
,3827622364.53,1.899816,0.2486208,9.9e-006,7,1,4,7,643,643,,,,,,,,,,,,,,,,,,,,,,,0.000035,499.995148,,99.989029,1.295739,4042.602295,,,,,,,,,,
,3827622383.33,1.899631,0.2308621,9.9e-006,7,1,4,7,643,643,,,,,,,,,,,,,,,,,,,,,,,-0.000024,499.995148,,99.989029,1.295739,4032.361328,,,,,,,,,,
,3827622402.16,1.899983,0.2486208,9.9e-006,7,1,4,7,643,643,,,,,,,,,,,,,,,,,,,,,,,-0.000051,499.995148,,99.989029,1.295739,4016.561523,,,,,,,,,,
,3827622421.09,1.900019,0.284138,9.9e-006,7,1,4,7,643,643,,,,,,,,,,,,,,,,,,,,,,,0.000011,499.995148,,99.989029,1.295739,4003.480713,,,,,,,,,,
,3827622440.05,1.900212,0.2486208,9.9e-006,7,1,4,7,643,643,,,,,,,,,,,,,,,,,,,,,,,0.000027,499.995148,,99.989029,1.295739,3986.140137,,,,,,,,,,
,3827622459.06,1.900234,0.2131035,9.9e-006,7,1,4,7,643,643,,,,,,,,,,,,,,,,,,,,,,,-0.000005,499.995148,,99.989029,1.295739,3966.081299,,,,,,,,,,
,3827622477.92,1.899947,0.3018967,9.9e-006,7,1,4,7,643,643,,,,,,,,,,,,,,,,,,,,,,,-0.000004,499.995148,,99.989029,1.295739,3950.523193,,,,,,,,,,
,3827622496.89,1.900333,0.284138,9.9e-006,7,1,4,7,643,643,,,,,,,,,,,,,,,,,,,,,,,0.000022,499.995148,,99.989029,1.295739,3934.481934,,,,,,,,,,
,3827622515.78,1.900073,0.2131035,9.9e-006,7,1,4,7,643,643,,,,,,,,,,,,,,,,,,,,,,,-0.000016,499.995148,,99.989029,1.295739,3918.984131,,,,,,,,,,
,3827622534.60,1.900003,0.284138,9.9e-006,7,1,4,7,643,643,,,,,,,,,,,,,,,,,,,,,,,-0.000040,499.995148,,99.989029,1.295739,3901.009521,,,,,,,,,,
,3827622553.42,1.899798,0.3374139,9.9e-006,7,1,4,7,643,643,,,,,,,,,,,,,,,,,,,,,,,0.000011,499.995148,,99.989029,1.295739,3884.031738,,,,,,,,,,
,3827622572.20,1.899917,0.3729312,9.9e-006,7,1,4,7,643,643,,,,,,,,,,,,,,,,,,,,,,,-0.000018,499.995148,,99.989029,1.295739,3865.845215,,,,,,,,,,
,3827622591.12,1.900038,0.2308621,9.9e-006,7,1,4,7,643,643,,,,,,,,,,,,,,,,,,,,,,,-0.000026,499.995148,,99.989029,1.295739,3849.864502,,,,,,,,,,
,3827622610.18,1.900056,0.426207,9.9e-006,7,1,4,7,643,643,,,,,,,,,,,,,,,,,,,,,,,0.000002,499.995148,,99.989029,1.295739,3831.375977,,,,,,,,,,
,3827622628.86,1.900141,0.3906898,9.9e-006,7,1,4,7,643,643,,,,,,,,,,,,,,,,,,,,,,,0.000011,499.995148,,99.989029,1.295739,3817.479736,,,,,,,,,,
,3827622647.80,1.900249,0.3374139,9.9e-006,7,1,4,7,643,643,,,,,,,,,,,,,,,,,,,,,,,-0.000005,499.995148,,99.989029,1.295739,3794.912842,,,,,,,,,,
,3827622666.59,1.900207,0.3551725,9.9e-006,7,1,4,7,643,643,,,,,,,,,,,,,,,,,,,,,,,0.000007,499.995148,,99.989029,1.295739,3778.871582,,,,,,,,,,
,3827622685.53,1.899988,0.3196553,9.9e-006,7,1,4,7,643,643,,,,,,,,,,,,,,,,,,,,,,,-0.000019,499.995148,,99.989029,1.295739,3764.431152,,,,,,,,,,
,3827622704.40,1.899916,0.4084484,9.9e-006,7,1,4,7,643,643,,,,,,,,,,,,,,,,,,,,,,,0.000032,499.995148,,99.989029,1.295739,3743.314941,,,,,,,,,,
,3827622723.23,1.900273,0.3906898,9.9e-006,7,1,4,7,643,643,,,,,,,,,,,,,,,,,,,,,,,-0.000023,499.995148,,99.989029,1.295739,3723.859619,,,,,,,,,,
,3827622742.13,1.900108,0.3551725,9.9e-006,7,1,4,7,643,643,,,,,,,,,,,,,,,,,,,,,,,-0.000035,499.995148,,99.989029,1.295739,3704.646484,,,,,,,,,,
,3827622761.27,1.899908,0.3374139,9.9e-006,7,1,4,7,643,643,,,,,,,,,,,,,,,,,,,,,,,0.000007,499.995148,,99.989029,1.295739,3686.339111,,,,,,,,,,
,3827622780.45,1.899845,0.426207,9.9e-006,7,1,4,7,643,643,,,,,,,,,,,,,,,,,,,,,,,0.000007,499.995148,,99.989029,1.295739,3669.935547,,,,,,,,,,
,3827622799.21,1.89984,0.5327588,9.9e-006,7,1,4,7,643,643,,,,,,,,,,,,,,,,,,,,,,,0.000023,499.995148,,99.989029,1.295739,3647.972656,,,,,,,,,,
,3827622818.10,1.900028,0.4084484,9.9e-006,7,1,4,7,643,643,,,,,,,,,,,,,,,,,,,,,,,-0.000028,499.995148,,99.989029,1.295739,3632.445313,,,,,,,,,,
,3827622836.79,1.900001,0.426207,9.9e-006,7,1,4,7,643,643,,,,,,,,,,,,,,,,,,,,,,,-0.000007,499.995148,,99.989029,1.295739,3611.842285,,,,,,,,,,
,3827622855.58,1.899721,0.4617243,9.9e-006,7,1,4,7,643,643,,,,,,,,,,,,,,,,,,,,,,,0.000054,499.995148,,99.989029,1.295739,3592.809814,,,,,,,,,,
,3827622874.62,1.900068,0.4439657,9.9e-006,7,1,4,7,643,643,,,,,,,,,,,,,,,,,,,,,,,0.000055,499.995148,,99.989029,1.295739,3576.164551,,,,,,,,,,
,3827622893.33,1.900135,0.5150002,9.9e-006,7,1,4,7,643,643,,,,,,,,,,,,,,,,,,,,,,,-0.000047,499.995148,,99.989029,1.295739,3557.524902,,,,,,,,,,
,3827622912.10,1.900002,0.5327588,9.9e-006,7,1,4,7,643,643,,,,,,,,,,,,,,,,,,,,,,,0.000046,499.995148,,99.989029,1.295739,3536.106445,,,,,,,,,,
,3827622931.23,1.899952,0.4084484,9.9e-006,7,1,4,7,643,643,,,,,,,,,,,,,,,,,,,,,,,0.000051,499.995148,,99.989029,1.295739,3518.796387,,,,,,,,,,
,3827622950.10,1.899866,0.5505174,9.9e-006,7,1,4,7,643,643,,,,,,,,,,,,,,,,,,,,,,,-0.000041,499.995148,,99.989029,1.295739,3501.002686,,,,,,,,,,
,3827622968.94,1.899913,0.4972415,9.9e-006,7,1,4,7,643,643,,,,,,,,,,,,,,,,,,,,,,,0.000013,499.995148,,99.989029,1.295739,3484.206299,,,,,,,,,,
,3827622987.75,1.900175,0.4617243,9.9e-006,7,1,4,7,643,643,,,,,,,,,,,,,,,,,,,,,,,-0.000032,499.995148,,99.989029,1.295739,3461.156250,,,,,,,,,,
,3827623006.79,1.899899,0.568276,9.9e-006,7,1,4,7,643,643,,,,,,,,,,,,,,,,,,,,,,,0.000018,499.995148,,99.989029,1.295739,3442.818848,,,,,,,,,,
,3827623025.65,1.899968,0.5860347,9.9e-006,7,1,4,7,643,643,,,,,,,,,,,,,,,,,,,,,,,-0.000049,499.995148,,99.989029,1.295739,3428.197266,,,,,,,,,,
,3827623044.42,1.899933,0.5327588,9.9e-006,7,1,4,7,643,643,,,,,,,,,,,,,,,,,,,,,,,0.000023,499.995148,,99.989029,1.295739,3406.567139,,,,,,,,,,
,3827623063.30,1.900298,0.568276,9.9e-006,7,1,4,7,643,643,,,,,,,,,,,,,,,,,,,,,,,-0.000011,499.995148,,99.989029,1.295739,3389.226807,,,,,,,,,,
,3827623082.05,1.900224,0.568276,9.9e-006,7,1,4,7,643,643,,,,,,,,,,,,,,,,,,,,,,,-0.000005,499.995148,,99.989029,1.295739,3368.412354,,,,,,,,,,
,3827623100.83,1.899941,0.4972415,9.9e-006,7,1,4,7,643,643,,,,,,,,,,,,,,,,,,,,,,,-0.000032,499.995148,,99.989029,1.295739,3352.099121,,,,,,,,,,
,3827623119.55,1.899996,0.568276,9.9e-006,7,1,4,7,643,643,,,,,,,,,,,,,,,,,,,,,,,0.000001,499.995148,,99.989029,1.295739,3332.100098,,,,,,,,,,
,3827623138.67,1.900066,0.5327588,9.9e-006,7,1,4,7,643,643,,,,,,,,,,,,,,,,,,,,,,,-0.000017,499.995148,,99.989029,1.295739,3311.134766,,,,,,,,,,
,3827623157.41,1.899957,0.5505174,9.9e-006,7,1,4,7,643,643,,,,,,,,,,,,,,,,,,,,,,,-0.000002,499.995148,,99.989029,1.295739,3292.797607,,,,,,,,,,
,3827623176.10,1.900112,0.6393105,9.9e-006,7,1,4,7,643,643,,,,,,,,,,,,,,,,,,,,,,,0.000055,499.995148,,99.989029,1.295739,3274.913330,,,,,,,,,,
,3827623194.86,1.899932,0.5327588,9.9e-006,7,1,4,7,643,643,,,,,,,,,,,,,,,,,,,,,,,-0.000035,499.995148,,99.989029,1.295739,3252.950928,,,,,,,,,,
,3827623213.70,1.899978,0.5327588,9.9e-006,7,1,4,7,643,643,,,,,,,,,,,,,,,,,,,,,,,-0.000037,499.995148,,99.989029,1.295739,3238.238525,,,,,,,,,,
,3827623232.67,1.899978,0.5505174,9.9e-006,7,1,4,7,643,643,,,,,,,,,,,,,,,,,,,,,,,-0.000011,499.995148,,99.989029,1.295739,3215.611816,,,,,,,,,,
,3827623251.50,1.900273,0.5860347,9.9e-006,7,1,4,7,643,643,,,,,,,,,,,,,,,,,,,,,,,-0.000068,499.995148,,99.989029,1.295739,3197.183594,,,,,,,,,,
,3827623270.21,1.899951,0.6215519,9.9e-006,7,1,4,7,643,643,,,,,,,,,,,,,,,,,,,,,,,-0.000012,499.995148,,99.989029,1.295739,3177.094238,,,,,,,,,,
,3827623288.90,1.900104,0.568276,9.9e-006,7,1,4,7,643,643,,,,,,,,,,,,,,,,,,,,,,,-0.000008,499.995148,,99.989029,1.295739,3157.518311,,,,,,,,,,
,3827623307.74,1.899674,0.6570692,9.9e-006,7,1,4,7,643,643,,,,,,,,,,,,,,,,,,,,,,,-0.000018,499.995148,,99.989029,1.295739,3139.724854,,,,,,,,,,
,3827623326.92,1.900028,0.6215519,9.9e-006,7,1,4,7,643,643,,,,,,,,,,,,,,,,,,,,,,,-0.000005,499.995148,,99.989029,1.295739,3121.447998,,,,,,,,,,
,3827623345.82,1.899949,0.6393105,9.9e-006,7,1,4,7,643,643,,,,,,,,,,,,,,,,,,,,,,,-0.000013,499.995148,,99.989029,1.295739,3100.784424,,,,,,,,,,
,3827623364.89,1.899812,0.5505174,9.9e-006,7,1,4,7,643,643,,,,,,,,,,,,,,,,,,,,,,,0.000002,499.995148,,99.989029,1.295739,3087.673340,,,,,,,,,,
,3827623383.87,1.899842,0.5860347,9.9e-006,7,1,4,7,643,643,,,,,,,,,,,,,,,,,,,,,,,0.000013,499.995148,,99.989029,1.295739,3067.070313,,,,,,,,,,
,3827623402.55,1.90014,0.6037933,9.9e-006,7,1,4,7,643,643,,,,,,,,,,,,,,,,,,,,,,,0.000002,499.995148,,99.989029,1.295739,3049.911377,,,,,,,,,,
,3827623421.26,1.899735,0.6393105,9.9e-006,7,1,4,7,643,643,,,,,,,,,,,,,,,,,,,,,,,0.000026,499.995148,,99.989029,1.295739,3031.725098,,,,,,,,,,
,3827623439.93,1.900065,0.5860347,9.9e-006,7,1,4,7,643,643,,,,,,,,,,,,,,,,,,,,,,,-0.000003,499.995148,,99.989029,1.295739,3012.300293,,,,,,,,,,
,3827623458.70,1.899955,0.6570692,9.9e-006,7,1,4,7,643,643,,,,,,,,,,,,,,,,,,,,,,,0.000006,499.995148,,99.989029,1.295739,2994.748535,,,,,,,,,,
,3827623477.50,1.900113,0.5860347,9.9e-006,7,1,4,7,643,643,,,,,,,,,,,,,,,,,,,,,,,0.000008,499.995148,,99.989029,1.295739,2978.918457,,,,,,,,,,
,3827623496.22,1.900094,0.5860347,9.9e-006,7,1,4,7,643,643,,,,,,,,,,,,,,,,,,,,,,,0.000014,499.995148,,99.989029,1.295739,2960.702148,,,,,,,,,,
,3827623514.96,1.900119,0.5505174,9.9e-006,7,1,4,7,643,643,,,,,,,,,,,,,,,,,,,,,,,0.000007,499.995148,,99.989029,1.295739,2943.633545,,,,,,,,,,
,3827623533.67,1.899768,0.6037933,9.9e-006,7,1,4,7,643,643,,,,,,,,,,,,,,,,,,,,,,,0.000016,499.995148,,99.989029,1.295739,2925.628418,,,,,,,,,,
,3827623552.44,1.899942,0.5860347,9.9e-006,7,1,4,7,643,643,,,,,,,,,,,,,,,,,,,,,,,0.000029,499.995148,,99.989029,1.295739,2911.309326,,,,,,,,,,
,3827623571.14,1.900115,0.6393105,9.9e-006,7,1,4,7,643,643,,,,,,,,,,,,,,,,,,,,,,,-0.000045,499.995148,,99.989029,1.295739,2887.775879,,,,,,,,,,
,3827623589.95,1.900102,0.6037933,9.9e-006,7,1,4,7,643,643,,,,,,,,,,,,,,,,,,,,,,,-0.000045,499.995148,,99.989029,1.295739,2875.873291,,,,,,,,,,
,3827623608.70,1.900072,0.6748278,9.9e-006,7,1,4,7,643,643,,,,,,,,,,,,,,,,,,,,,,,-0.000006,499.995148,,99.989029,1.295739,2856.538818,,,,,,,,,,
,3827623627.39,1.900184,0.5505174,9.9e-006,7,1,4,7,643,643,,,,,,,,,,,,,,,,,,,,,,,0.000034,499.995148,,99.989029,1.295739,2841.766357,,,,,,,,,,
,3827623646.25,1.900095,0.6215519,9.9e-006,7,1,4,7,643,643,,,,,,,,,,,,,,,,,,,,,,,0.000010,499.995148,,99.989029,1.295739,2824.486572,,,,,,,,,,
,3827623665.04,1.899806,0.568276,9.9e-006,7,1,4,7,643,643,,,,,,,,,,,,,,,,,,,,,,,-0.000004,499.995148,,99.989029,1.295739,2805.968018,,,,,,,,,,
,3827623683.79,1.899998,0.6393105,9.9e-006,7,1,4,7,643,643,,,,,,,,,,,,,,,,,,,,,,,0.000009,499.995148,,99.989029,1.295739,2789.956787,,,,,,,,,,
,3827623702.65,1.899962,0.6215519,9.9e-006,7,1,4,7,643,643,,,,,,,,,,,,,,,,,,,,,,,0.000023,499.995148,,99.989029,1.295739,2774.398926,,,,,,,,,,
,3827623721.46,1.899864,0.6393105,9.9e-006,7,1,4,7,643,643,,,,,,,,,,,,,,,,,,,,,,,0.000009,499.995148,,99.989029,1.295739,2758.689697,,,,,,,,,,
,3827623740.27,1.899966,0.5860347,9.9e-006,7,1,4,7,643,643,,,,,,,,,,,,,,,,,,,,,,,0.000062,499.995148,,99.989029,1.295739,2739.989990,,,,,,,,,,
,3827623759.06,1.899825,0.6925864,9.9e-006,7,1,4,7,643,643,,,,,,,,,,,,,,,,,,,,,,,-0.000032,499.995148,,99.989029,1.295739,2725.972656,,,,,,,,,,
,3827623777.85,1.899835,0.6037933,9.9e-006,7,1,4,7,643,643,,,,,,,,,,,,,,,,,,,,,,,-0.000051,499.995148,,99.989029,1.295739,2706.245605,,,,,,,,,,
,3827623796.56,1.900095,0.5505174,9.9e-006,7,1,4,7,643,643,,,,,,,,,,,,,,,,,,,,,,,-0.000019,499.995148,,99.989029,1.295739,2691.080566,,,,,,,,,,
,3827623815.47,1.900061,0.568276,9.9e-006,7,1,4,7,643,643,,,,,,,,,,,,,,,,,,,,,,,-0.000036,499.995148,,99.989029,1.295739,2676.882080,,,,,,,,,,
,3827623834.14,1.899804,0.5327588,9.9e-006,7,1,4,7,643,643,,,,,,,,,,,,,,,,,,,,,,,-0.000033,499.995148,,99.989029,1.295739,2659.964600,,,,,,,,,,
,3827623853.12,1.90004,0.6393105,9.9e-006,7,1,4,7,643,643,,,,,,,,,,,,,,,,,,,,,,,0.000035,499.995148,,99.989029,1.295739,2639.995850,,,,,,,,,,
,3827623871.92,1.899951,0.6215519,9.9e-006,7,1,4,7,643,643,,,,,,,,,,,,,,,,,,,,,,,0.000004,499.995148,,99.989029,1.295739,2627.851563,,,,,,,,,,
,3827623890.98,1.899993,0.5505174,9.9e-006,7,1,4,7,643,643,,,,,,,,,,,,,,,,,,,,,,,0.000007,499.995148,,99.989029,1.295739,2609.091309,,,,,,,,,,
,3827623909.96,1.899866,0.6037933,9.9e-006,7,1,4,7,643,643,,,,,,,,,,,,,,,,,,,,,,,0.000030,499.995148,,99.989029,1.295739,2595.708496,,,,,,,,,,
,3827623928.94,1.899674,0.5505174,9.9e-006,7,1,4,7,643,643,,,,,,,,,,,,,,,,,,,,,,,0.000037,499.995148,,99.989029,1.295739,2580.059814,,,,,,,,,,
,3827623947.87,1.899858,0.568276,9.9e-006,7,1,4,7,643,643,,,,,,,,,,,,,,,,,,,,,,,-0.000056,499.995148,,99.989029,1.295739,2561.722656,,,,,,,,,,
,3827623966.76,1.899865,0.6037933,9.9e-006,7,1,4,7,643,643,,,,,,,,,,,,,,,,,,,,,,,0.000024,499.995148,,99.989029,1.295739,2545.016602,,,,,,,,,,
,3827623985.78,1.900005,0.5860347,9.9e-006,7,1,4,7,643,643,,,,,,,,,,,,,,,,,,,,,,,-0.000011,499.995148,,99.989029,1.295739,2530.636719,,,,,,,,,,
,3827624004.75,1.899818,0.6037933,9.9e-006,7,1,4,7,643,643,,,,,,,,,,,,,,,,,,,,,,,-0.000021,499.995148,,99.989029,1.295739,2515.018311,,,,,,,,,,
,3827624023.48,1.899988,0.6393105,9.9e-006,7,1,4,7,643,643,,,,,,,,,,,,,,,,,,,,,,,-0.000010,499.995148,,99.989029,1.295739,2499.641602,,,,,,,,,,
,3827624042.17,1.899926,0.5860347,9.9e-006,7,1,4,7,643,643,,,,,,,,,,,,,,,,,,,,,,,-0.000012,499.995148,,99.989029,1.295739,2483.207520,,,,,,,,,,
,3827624060.91,1.899783,0.6215519,9.9e-006,7,1,4,7,643,643,,,,,,,,,,,,,,,,,,,,,,,0.000029,499.995148,,99.989029,1.295739,2466.018311,,,,,,,,,,
,3827624079.69,1.899976,0.6215519,9.9e-006,7,1,4,7,643,643,,,,,,,,,,,,,,,,,,,,,,,0.000009,499.995148,,99.989029,1.295739,2452.997803,,,,,,,,,,
,3827624098.69,1.899931,0.6393105,9.9e-006,7,1,4,7,643,643,,,,,,,,,,,,,,,,,,,,,,,0.000004,499.995148,,99.989029,1.295739,2435.536621,,,,,,,,,,
,3827624117.38,1.90037,0.6215519,9.9e-006,7,1,4,7,643,643,,,,,,,,,,,,,,,,,,,,,,,0.000009,499.995148,,99.989029,1.295739,2418.860840,,,,,,,,,,
,3827624136.07,1.899959,0.6393105,9.9e-006,7,1,4,7,643,643,,,,,,,,,,,,,,,,,,,,,,,0.000029,499.995148,,99.989029,1.295739,2403.423584,,,,,,,,,,
,3827624154.77,1.899933,0.6215519,9.9e-006,7,1,4,7,643,643,,,,,,,,,,,,,,,,,,,,,,,0.000021,499.995148,,99.989029,1.295739,2389.285400,,,,,,,,,,
,3827624173.59,1.900063,0.6570692,9.9e-006,7,1,4,7,643,643,,,,,,,,,,,,,,,,,,,,,,,-0.000051,499.995148,,99.989029,1.295739,2375.419434,,,,,,,,,,
,3827624192.31,1.90008,0.5860347,9.9e-006,7,1,4,7,643,643,,,,,,,,,,,,,,,,,,,,,,,-0.000013,499.995148,,99.989029,1.295739,2356.417480,,,,,,,,,,
,3827624211.49,1.900034,0.6037933,9.9e-006,7,1,4,7,643,643,,,,,,,,,,,,,,,,,,,,,,,-0.000012,499.995148,,99.989029,1.295739,2341.312500,,,,,,,,,,
,3827624230.23,1.899918,0.6570692,9.9e-006,7,1,4,7,643,643,,,,,,,,,,,,,,,,,,,,,,,0.000030,499.995148,,99.989029,1.295739,2324.848145,,,,,,,,,,
,3827624248.95,1.900065,0.5860347,9.9e-006,7,1,4,7,643,643,,,,,,,,,,,,,,,,,,,,,,,-0.000023,499.995148,,99.989029,1.295739,2307.779541,,,,,,,,,,
,3827624267.72,1.899722,0.568276,9.9e-006,7,1,4,7,643,643,,,,,,,,,,,,,,,,,,,,,,,-0.000049,499.995148,,99.989029,1.295739,2295.000977,,,,,,,,,,
,3827624286.48,1.900177,0.6393105,9.9e-006,7,1,4,7,643,643,,,,,,,,,,,,,,,,,,,,,,,0.000018,499.995148,,99.989029,1.295739,2278.264893,,,,,,,,,,
,3827624305.16,1.900255,0.5860347,9.9e-006,7,1,4,7,643,643,,,,,,,,,,,,,,,,,,,,,,,0.000005,499.995148,,99.989029,1.295739,2263.673340,,,,,,,,,,
,3827624323.91,1.899956,0.5860347,9.9e-006,7,1,4,7,643,643,,,,,,,,,,,,,,,,,,,,,,,-0.000060,499.995148,,99.989029,1.295739,2250.260498,,,,,,,,,,
,3827624342.59,1.899867,0.6215519,9.9e-006,7,1,4,7,643,643,,,,,,,,,,,,,,,,,,,,,,,0.000018,499.995148,,99.989029,1.295739,2232.104492,,,,,,,,,,
,3827624361.57,1.900244,0.5860347,9.9e-006,7,1,4,7,643,643,,,,,,,,,,,,,,,,,,,,,,,-0.000002,499.995148,,99.989029,1.295739,2215.398682,,,,,,,,,,
,3827624380.41,1.899842,0.6215519,9.9e-006,7,1,4,7,643,643,,,,,,,,,,,,,,,,,,,,,,,0.000014,499.995148,,99.989029,1.295739,2201.985352,,,,,,,,,,
,3827624399.19,1.900159,0.6393105,9.9e-006,7,1,4,7,643,643,,,,,,,,,,,,,,,,,,,,,,,0.000015,499.995148,,99.989029,1.295739,2188.602295,,,,,,,,,,
,3827624417.90,1.899974,0.6037933,9.9e-006,7,1,4,7,643,643,,,,,,,,,,,,,,,,,,,,,,,0.000042,499.995148,,99.989029,1.295739,2173.074707,,,,,,,,,,
,3827624437.16,1.900072,0.6393105,9.9e-006,7,1,4,7,643,643,,,,,,,,,,,,,,,,,,,,,,,0.000016,499.995148,,99.989029,1.295739,2155.372070,,,,,,,,,,
,3827624455.78,1.899783,0.6925864,9.9e-006,7,1,4,7,643,643,,,,,,,,,,,,,,,,,,,,,,,-0.000027,499.995148,,99.989029,1.295739,2143.499268,,,,,,,,,,
,3827624474.77,1.900074,0.6215519,9.9e-006,7,1,4,7,643,643,,,,,,,,,,,,,,,,,,,,,,,-0.000009,499.995148,,99.989029,1.295739,2126.914307,,,,,,,,,,
,3827624493.55,1.90019,0.6215519,9.9e-006,7,1,4,7,643,643,,,,,,,,,,,,,,,,,,,,,,,-0.000011,499.995148,,99.989029,1.295739,2114.860596,,,,,,,,,,
,3827624512.38,1.900023,0.6037933,9.9e-006,7,1,4,7,643,643,,,,,,,,,,,,,,,,,,,,,,,0.000033,499.995148,,99.989029,1.295739,2098.245117,,,,,,,,,,
,3827624531.21,1.899926,0.6570692,9.9e-006,7,1,4,7,643,643,,,,,,,,,,,,,,,,,,,,,,,-0.000013,499.995148,,99.989029,1.295739,2083.261230,,,,,,,,,,
,3827624550.09,1.899871,0.6570692,9.9e-006,7,1,4,7,643,643,,,,,,,,,,,,,,,,,,,,,,,-0.000002,499.995148,,99.989029,1.295739,2071.086914,,,,,,,,,,
,3827624568.77,1.89999,0.6570692,9.9e-006,7,1,4,7,643,643,,,,,,,,,,,,,,,,,,,,,,,-0.000023,499.995148,,99.989029,1.295739,2055.558838,,,,,,,,,,
,3827624587.58,1.899796,0.6037933,9.9e-006,7,1,4,7,643,643,,,,,,,,,,,,,,,,,,,,,,,0.000002,499.995148,,99.989029,1.295739,2040.665527,,,,,,,,,,
,3827624606.27,1.900196,0.6215519,9.9e-006,7,1,4,7,643,643,,,,,,,,,,,,,,,,,,,,,,,0.000010,499.995148,,99.989029,1.295739,2028.068237,,,,,,,,,,
,3827624625.17,1.899983,0.6570692,9.9e-006,7,1,4,7,643,643,,,,,,,,,,,,,,,,,,,,,,,-0.000035,499.995148,,99.989029,1.295739,2011.150757,,,,,,,,,,
,3827624644.00,1.900071,0.6037933,9.9e-006,7,1,4,7,643,643,,,,,,,,,,,,,,,,,,,,,,,-0.000011,499.995148,,99.989029,1.295739,1998.583618,,,,,,,,,,
,3827624662.89,1.899783,0.6393105,9.9e-006,7,1,4,7,643,643,,,,,,,,,,,,,,,,,,,,,,,-0.000038,499.995148,,99.989029,1.295739,1985.985962,,,,,,,,,,
,3827624681.91,1.899964,0.6570692,9.9e-006,7,1,4,7,643,643,,,,,,,,,,,,,,,,,,,,,,,-0.000014,499.995148,,99.989029,1.295739,1973.418701,,,,,,,,,,
,3827624700.75,1.899682,0.3906898,9.9e-006,7,1,4,7,643,643,,,,,,,,,,,,,,,,,,,,,,,0.000010,499.995148,,99.989029,1.295739,1958.344116,,,,,,,,,,
,3827624719.58,1.900122,0.4084484,9.9e-006,7,1,4,7,643,643,,,,,,,,,,,,,,,,,,,,,,,0.000026,499.995148,,99.989029,1.295739,1946.985474,,,,,,,,,,
,3827624738.53,1.900003,0.426207,9.9e-006,7,1,4,7,643,643,,,,,,,,,,,,,,,,,,,,,,,-0.000013,499.995148,,99.989029,1.295739,1934.961670,,,,,,,,,,
,3827624757.45,1.900153,0.4617243,9.9e-006,7,1,4,7,643,643,,,,,,,,,,,,,,,,,,,,,,,0.000020,499.995148,,99.989029,1.295739,1920.944458,,,,,,,,,,
,3827624776.28,1.900072,0.426207,9.9e-006,7,1,4,7,643,643,,,,,,,,,,,,,,,,,,,,,,,0.000043,499.995148,,99.989029,1.295739,1908.588745,,,,,,,,,,
,3827624795.19,1.900075,0.426207,9.9e-006,7,1,4,7,643,643,,,,,,,,,,,,,,,,,,,,,,,-0.000019,499.995148,,99.989029,1.295739,1901.277832,,,,,,,,,,
,3827624814.09,1.900079,0.3906898,9.9e-006,7,1,4,7,643,643,,,,,,,,,,,,,,,,,,,,,,,0.000022,499.995148,,99.989029,1.295739,1884.934570,,,,,,,,,,
,3827624832.96,1.899984,0.3551725,9.9e-006,7,1,4,7,643,643,,,,,,,,,,,,,,,,,,,,,,,-0.000013,499.995148,,99.989029,1.295739,1873.666504,,,,,,,,,,
,3827624851.80,1.899598,0.426207,9.9e-006,7,1,4,7,643,643,,,,,,,,,,,,,,,,,,,,,,,-0.000005,499.995148,,99.989029,1.295739,1864.905396,,,,,,,,,,
,3827624870.43,1.900315,0.4617243,9.9e-006,7,1,4,7,643,643,,,,,,,,,,,,,,,,,,,,,,,0.000008,499.995148,,99.989029,1.295739,1853.365356,,,,,,,,,,
,3827624889.22,1.899992,0.4439657,9.9e-006,7,1,4,7,643,643,,,,,,,,,,,,,,,,,,,,,,,-0.000046,499.995148,,99.989029,1.295739,1843.758789,,,,,,,,,,
,3827624908.03,1.899965,0.4439657,9.9e-006,7,1,4,7,643,643,,,,,,,,,,,,,,,,,,,,,,,-0.000007,499.995148,,99.989029,1.295739,1832.913330,,,,,,,,,,
,3827624927.00,1.9003,0.4439657,9.9e-006,7,1,4,7,643,643,,,,,,,,,,,,,,,,,,,,,,,0.000005,499.995148,,99.989029,1.295739,1821.373169,,,,,,,,,,
,3827624945.70,1.899793,0.4439657,9.9e-006,7,1,4,7,643,643,,,,,,,,,,,,,,,,,,,,,,,0.000024,499.995148,,99.989029,1.295739,1811.766602,,,,,,,,,,
,3827624964.49,1.900056,0.3729312,9.9e-006,7,1,4,7,643,643,,,,,,,,,,,,,,,,,,,,,,,-0.000017,499.995148,,99.989029,1.295739,1800.377686,,,,,,,,,,
,3827624983.22,1.900166,0.3906898,9.9e-006,7,1,4,7,643,643,,,,,,,,,,,,,,,,,,,,,,,-0.000013,499.995148,,99.989029,1.295739,1791.375000,,,,,,,,,,
,3827625002.26,1.899926,0.3729312,9.9e-006,7,1,4,7,643,643,,,,,,,,,,,,,,,,,,,,,,,0.000001,499.995148,,99.989029,1.295739,1783.580933,,,,,,,,,,
,3827625021.17,1.900181,0.3906898,9.9e-006,7,1,4,7,643,643,,,,,,,,,,,,,,,,,,,,,,,0.000026,499.995148,,99.989029,1.295739,1771.164795,,,,,,,,,,
,3827625040.05,1.900164,0.4084484,9.9e-006,7,1,4,7,643,643,,,,,,,,,,,,,,,,,,,,,,,0.000064,499.995148,,99.989029,1.295739,1761.406982,,,,,,,,,,
,3827625058.76,1.900037,0.4084484,9.9e-006,7,1,4,7,643,643,,,,,,,,,,,,,,,,,,,,,,,0.000042,499.995148,,99.989029,1.295739,1758.506958,,,,,,,,,,
,3827625077.55,1.899959,0.3729312,9.9e-006,7,1,4,7,643,643,,,,,,,,,,,,,,,,,,,,,,,0.000017,499.995148,,99.989029,1.295739,1747.782471,,,,,,,,,,
,3827625096.48,1.900154,0.3729312,9.9e-006,7,1,4,7,643,643,,,,,,,,,,,,,,,,,,,,,,,-0.000024,499.995148,,99.989029,1.295739,1741.680176,,,,,,,,,,
,3827625115.29,1.89984,0.3551725,9.9e-006,7,1,4,7,643,643,,,,,,,,,,,,,,,,,,,,,,,0.000009,499.995148,,99.989029,1.295739,1732.466187,,,,,,,,,,
,3827625134.10,1.899924,0.3906898,9.9e-006,7,1,4,7,643,643,,,,,,,,,,,,,,,,,,,,,,,-0.000025,499.995148,,99.989029,1.295739,1727.692993,,,,,,,,,,
,3827625152.75,1.900236,0.3906898,9.9e-006,7,1,4,7,643,643,,,,,,,,,,,,,,,,,,,,,,,-0.000012,499.995148,,99.989029,1.295739,1720.050049,,,,,,,,,,
,3827625171.48,1.900132,0.426207,9.9e-006,7,1,4,7,643,643,,,,,,,,,,,,,,,,,,,,,,,0.000011,499.995148,,99.989029,1.295739,1712.286133,,,,,,,,,,
,3827625190.24,1.900223,0.4617243,9.9e-006,7,1,4,7,643,643,,,,,,,,,,,,,,,,,,,,,,,0.000038,499.995148,,99.989029,1.295739,1705.942139,,,,,,,,,,
,3827625209.25,1.899872,0.3906898,9.9e-006,7,1,4,7,643,643,,,,,,,,,,,,,,,,,,,,,,,-0.000051,499.995148,,99.989029,1.295739,1699.990601,,,,,,,,,,
,3827625227.96,1.899775,0.426207,9.9e-006,7,1,4,7,643,643,,,,,,,,,,,,,,,,,,,,,,,0.000049,499.995148,,99.989029,1.295739,1694.130249,,,,,,,,,,
,3827625246.92,1.900087,0.426207,9.9e-006,7,1,4,7,643,643,,,,,,,,,,,,,,,,,,,,,,,0.000026,499.995148,,99.989029,1.295739,1690.232910,,,,,,,,,,
,3827625265.80,1.900378,0.3906898,9.9e-006,7,1,4,7,643,643,,,,,,,,,,,,,,,,,,,,,,,-0.000022,499.995148,,99.989029,1.295739,1684.765015,,,,,,,,,,
,3827625284.51,1.89985,0.4084484,9.9e-006,7,1,4,7,643,643,,,,,,,,,,,,,,,,,,,,,,,-0.000006,499.995148,,99.989029,1.295739,1676.940796,,,,,,,,,,
,3827625303.35,1.900157,0.426207,9.9e-006,7,1,4,7,643,643,,,,,,,,,,,,,,,,,,,,,,,-0.000039,499.995148,,99.989029,1.295739,1672.016602,,,,,,,,,,
,3827625322.20,1.900092,0.4617243,9.9e-006,7,1,4,7,643,643,,,,,,,,,,,,,,,,,,,,,,,0.000020,499.995148,,99.989029,1.295739,1667.333984,,,,,,,,,,
,3827625340.84,1.899971,0.3551725,9.9e-006,7,1,4,7,643,643,,,,,,,,,,,,,,,,,,,,,,,-0.000018,499.995148,,99.989029,1.295739,1662.409912,,,,,,,,,,
,3827625359.83,1.900195,0.426207,9.9e-006,7,1,4,7,643,643,,,,,,,,,,,,,,,,,,,,,,,0.000003,499.995148,,99.989029,1.295739,1657.666870,,,,,,,,,,
,3827625378.90,1.899886,0.4617243,9.9e-006,7,1,4,7,643,643,,,,,,,,,,,,,,,,,,,,,,,-0.000056,499.995148,,99.989029,1.295739,1654.404297,,,,,,,,,,
,3827625397.98,1.900059,0.4617243,9.9e-006,7,1,4,7,643,643,,,,,,,,,,,,,,,,,,,,,,,0.000031,499.995148,,99.989029,1.295739,1647.909180,,,,,,,,,,
,3827625416.93,1.89988,0.4617243,9.9e-006,7,1,4,7,643,643,,,,,,,,,,,,,,,,,,,,,,,-0.000007,499.995148,,99.989029,1.295739,1641.202637,,,,,,,,,,
,3827625435.86,1.899927,0.3906898,9.9e-006,7,1,4,7,643,643,,,,,,,,,,,,,,,,,,,,,,,-0.000016,499.995148,,99.989029,1.295739,1642.320435,,,,,,,,,,
,3827625454.77,1.90022,0.3729312,9.9e-006,7,1,4,7,643,643,,,,,,,,,,,,,,,,,,,,,,,-0.000027,499.995148,,99.989029,1.295739,1636.127441,,,,,,,,,,
,3827625473.53,1.899952,0.4439657,9.9e-006,7,1,4,7,643,643,,,,,,,,,,,,,,,,,,,,,,,-0.000007,499.995148,,99.989029,1.295739,1631.082520,,,,,,,,,,
,3827625492.28,1.899924,0.4439657,9.9e-006,7,1,4,7,643,643,,,,,,,,,,,,,,,,,,,,,,,-0.000001,499.995148,,99.989029,1.295739,1627.396606,,,,,,,,,,
,3827625511.22,1.899848,0.3906898,9.9e-006,7,1,4,7,643,643,,,,,,,,,,,,,,,,,,,,,,,-0.000028,499.995148,,99.989029,1.295739,1623.741455,,,,,,,,,,
,3827625530.09,1.899768,0.3729312,9.9e-006,7,1,4,7,643,643,,,,,,,,,,,,,,,,,,,,,,,-0.000017,499.995148,,99.989029,1.295739,1622.140381,,,,,,,,,,
,3827625548.96,1.900201,0.4439657,9.9e-006,7,1,4,7,643,643,,,,,,,,,,,,,,,,,,,,,,,-0.000001,499.995148,,99.989029,1.295739,1618.152832,,,,,,,,,,
,3827625567.68,1.899644,0.3906898,9.9e-006,7,1,4,7,643,643,,,,,,,,,,,,,,,,,,,,,,,0.000052,499.995148,,99.989029,1.295739,1616.702515,,,,,,,,,,
,3827625586.64,1.900129,0.3729312,9.9e-006,7,1,4,7,643,643,,,,,,,,,,,,,,,,,,,,,,,0.000072,499.995148,,99.989029,1.295739,1613.017090,,,,,,,,,,
,3827625605.54,1.900159,0.4439657,9.9e-006,7,1,4,7,643,643,,,,,,,,,,,,,,,,,,,,,,,0.000146,499.995148,,99.989029,1.295739,1609.633667,,,,,,,,,,
,3827625624.58,1.900147,0.3906898,9.9e-006,7,1,4,7,643,643,,,,,,,,,,,,,,,,,,,,,,,0.000106,499.995148,,99.989029,1.295739,1607.337524,,,,,,,,,,
,3827625643.30,1.900049,0.4084484,9.9e-006,7,1,4,7,643,643,,,,,,,,,,,,,,,,,,,,,,,0.000155,499.995148,,99.989029,1.295739,1606.944824,,,,,,,,,,
,3827625662.20,1.90008,0.426207,9.9e-006,7,1,4,7,643,643,,,,,,,,,,,,,,,,,,,,,,,0.000170,499.995148,,99.989029,1.295739,1603.682251,,,,,,,,,,
,3827625680.88,1.89984,0.426207,9.9e-006,7,1,4,7,643,643,,,,,,,,,,,,,,,,,,,,,,,0.000164,499.995148,,99.989029,1.295739,1599.241455,,,,,,,,,,
,3827625699.92,1.900152,0.426207,9.9e-006,7,1,4,7,643,643,,,,,,,,,,,,,,,,,,,,,,,0.000147,499.995148,,99.989029,1.295739,1598.758179,,,,,,,,,,
,3827625718.86,1.899807,0.4617243,9.9e-006,7,1,4,7,643,643,,,,,,,,,,,,,,,,,,,,,,,0.000148,499.995148,,99.989029,1.295739,1595.132935,,,,,,,,,,
,3827625737.61,1.899811,0.4794829,9.9e-006,7,1,4,7,643,643,,,,,,,,,,,,,,,,,,,,,,,0.000194,499.995148,,99.989029,1.295739,1594.377563,,,,,,,,,,
,3827625756.31,1.899914,0.426207,9.9e-006,7,1,4,7,643,643,,,,,,,,,,,,,,,,,,,,,,,0.000157,499.995148,,99.989029,1.295739,1590.208618,,,,,,,,,,
,3827625775.04,1.900066,0.4617243,9.9e-006,7,1,4,7,643,643,,,,,,,,,,,,,,,,,,,,,,,0.000154,499.995148,,99.989029,1.295739,1588.667969,,,,,,,,,,
,3827625793.83,1.900103,0.5150002,9.9e-006,7,1,4,7,643,643,,,,,,,,,,,,,,,,,,,,,,,0.000196,499.995148,,99.989029,1.295739,1587.066772,,,,,,,,,,
,3827625812.58,1.899824,0.426207,9.9e-006,7,1,4,7,643,643,,,,,,,,,,,,,,,,,,,,,,,0.000120,499.995148,,99.989029,1.295739,1584.106201,,,,,,,,,,
,3827625831.44,1.899881,0.426207,9.9e-006,7,1,4,7,643,643,,,,,,,,,,,,,,,,,,,,,,,0.000163,499.995148,,99.989029,1.295739,1586.613770,,,,,,,,,,
,3827625850.25,1.899904,0.3906898,9.9e-006,7,1,4,7,643,643,,,,,,,,,,,,,,,,,,,,,,,0.000197,499.995148,,99.989029,1.295739,1580.239502,,,,,,,,,,
,3827625868.96,1.900084,0.4084484,9.9e-006,7,1,4,7,643,643,,,,,,,,,,,,,,,,,,,,,,,0.000229,499.995148,,99.989029,1.295739,1578.245605,,,,,,,,,,
,3827625887.71,1.899811,0.4617243,9.9e-006,7,1,4,7,643,643,,,,,,,,,,,,,,,,,,,,,,,0.000203,499.995148,,99.989029,1.295739,1580.511230,,,,,,,,,,
,3827625906.65,1.900201,0.4439657,9.9e-006,7,1,4,7,643,643,,,,,,,,,,,,,,,,,,,,,,,0.000183,499.995148,,99.989029,1.295739,1574.831787,,,,,,,,,,
,3827625925.45,1.899801,0.4439657,9.9e-006,7,1,4,7,643,643,,,,,,,,,,,,,,,,,,,,,,,0.000183,499.995148,,99.989029,1.295739,1574.711060,,,,,,,,,,
,3827625944.30,1.899892,0.3551725,9.9e-006,7,1,4,7,643,643,,,,,,,,,,,,,,,,,,,,,,,0.000212,499.995148,,99.989029,1.295739,1570.995239,,,,,,,,,,
,3827625963.04,1.900218,0.426207,9.9e-006,7,1,4,7,643,643,,,,,,,,,,,,,,,,,,,,,,,0.000169,499.995148,,99.989029,1.295739,1570.723389,,,,,,,,,,
,3827625981.78,1.900083,0.3906898,9.9e-006,7,1,4,7,643,643,,,,,,,,,,,,,,,,,,,,,,,0.000207,499.995148,,99.989029,1.295739,1570.995239,,,,,,,,,,
,3827626000.66,1.899986,0.4972415,9.9e-006,7,1,4,7,643,643,,,,,,,,,,,,,,,,,,,,,,,0.000208,499.995148,,99.989029,1.295739,1568.276489,,,,,,,,,,
,3827626019.67,1.900021,0.4084484,9.9e-006,7,1,4,7,643,643,,,,,,,,,,,,,,,,,,,,,,,0.000187,499.995148,,99.989029,1.295739,1566.222046,,,,,,,,,,
,3827626038.48,1.899983,0.426207,9.9e-006,7,1,4,7,643,643,,,,,,,,,,,,,,,,,,,,,,,0.000163,499.995148,,99.989029,1.295739,1565.768921,,,,,,,,,,
,3827626057.59,1.899957,0.4084484,9.9e-006,7,1,4,7,643,643,,,,,,,,,,,,,,,,,,,,,,,0.000210,499.995148,,99.989029,1.295739,1561.116699,,,,,,,,,,
,3827626076.30,1.90027,0.426207,9.9e-006,7,1,4,7,643,643,,,,,,,,,,,,,,,,,,,,,,,0.000206,499.995148,,99.989029,1.295739,1561.418579,,,,,,,,,,
,3827626095.51,1.900067,0.3906898,9.9e-006,7,1,4,7,643,643,,,,,,,,,,,,,,,,,,,,,,,0.000173,499.995148,,99.989029,1.295739,1560.663574,,,,,,,,,,
,3827626114.22,1.899833,0.4439657,9.9e-006,7,1,4,7,643,643,,,,,,,,,,,,,,,,,,,,,,,0.000187,499.995148,,99.989029,1.295739,1560.150024,,,,,,,,,,
,3827626133.01,1.900329,0.4084484,9.9e-006,7,1,4,7,643,643,,,,,,,,,,,,,,,,,,,,,,,0.000171,499.995148,,99.989029,1.295739,1559.545776,,,,,,,,,,
,3827626151.73,1.900194,0.3906898,9.9e-006,7,1,4,7,643,643,,,,,,,,,,,,,,,,,,,,,,,0.000192,499.995148,,99.989029,1.295739,1559.364624,,,,,,,,,,
,3827626170.54,1.899621,0.4084484,9.9e-006,7,1,4,7,643,643,,,,,,,,,,,,,,,,,,,,,,,0.000207,499.995148,,99.989029,1.295739,1555.890381,,,,,,,,,,
,3827626189.53,1.900021,0.3551725,9.9e-006,7,1,4,7,643,643,,,,,,,,,,,,,,,,,,,,,,,0.000191,499.995148,,99.989029,1.295739,1555.044434,,,,,,,,,,
,3827626208.25,1.899711,0.4617243,9.9e-006,7,1,4,7,643,643,,,,,,,,,,,,,,,,,,,,,,,0.000222,499.995148,,99.989029,1.295739,1554.953857,,,,,,,,,,
,3827626227.01,1.900024,0.3729312,9.9e-006,7,1,4,7,643,643,,,,,,,,,,,,,,,,,,,,,,,0.000268,499.995148,,99.989029,1.295739,1553.534180,,,,,,,,,,
,3827626245.93,1.900179,0.3906898,9.9e-006,7,1,4,7,643,643,,,,,,,,,,,,,,,,,,,,,,,0.000241,499.995148,,99.989029,1.295739,1550.543213,,,,,,,,,,
,3827626264.82,1.899803,0.4084484,9.9e-006,7,1,4,7,643,643,,,,,,,,,,,,,,,,,,,,,,,0.000186,499.995148,,99.989029,1.295739,1550.996460,,,,,,,,,,
,3827626283.66,1.899995,0.3729312,9.9e-006,7,1,4,7,643,643,,,,,,,,,,,,,,,,,,,,,,,0.000171,499.995148,,99.989029,1.295739,1550.845215,,,,,,,,,,
,3827626302.69,1.900334,0.3551725,9.9e-006,7,1,4,7,643,643,,,,,,,,,,,,,,,,,,,,,,,0.000191,499.995148,,99.989029,1.295739,1547.884766,,,,,,,,,,
,3827626321.58,1.900045,0.3551725,9.9e-006,7,1,4,7,643,643,,,,,,,,,,,,,,,,,,,,,,,0.000164,499.995148,,99.989029,1.295739,1549.757813,,,,,,,,,,
,3827626340.33,1.899817,0.3729312,9.9e-006,7,1,4,7,643,643,,,,,,,,,,,,,,,,,,,,,,,0.000229,499.995148,,99.989029,1.295739,1546.918091,,,,,,,,,,
,3827626359.04,1.899906,0.426207,9.9e-006,7,1,4,7,643,643,,,,,,,,,,,,,,,,,,,,,,,0.000162,499.995148,,99.989029,1.295739,1547.552612,,,,,,,,,,
,3827626377.81,1.899932,0.426207,9.9e-006,7,1,4,7,643,643,,,,,,,,,,,,,,,,,,,,,,,0.000210,499.995148,,99.989029,1.295739,1545.709717,,,,,,,,,,
,3827626396.79,1.89998,0.426207,9.9e-006,7,1,4,7,643,643,,,,,,,,,,,,,,,,,,,,,,,0.000200,499.995148,,99.989029,1.295739,1547.824463,,,,,,,,,,
,3827626415.52,1.900004,0.3729312,9.9e-006,7,1,4,7,643,643,,,,,,,,,,,,,,,,,,,,,,,0.000203,499.995148,,99.989029,1.295739,1548.972290,,,,,,,,,,
,3827626434.29,1.899903,0.3906898,9.9e-006,7,1,4,7,643,643,,,,,,,,,,,,,,,,,,,,,,,0.000219,499.995148,,99.989029,1.295739,1542.809448,,,,,,,,,,
,3827626452.93,1.899948,0.426207,9.9e-006,7,1,4,7,643,643,,,,,,,,,,,,,,,,,,,,,,,0.000241,499.995148,,99.989029,1.295739,1543.564819,,,,,,,,,,
,3827626471.92,1.899785,0.426207,9.9e-006,7,1,4,7,643,643,,,,,,,,,,,,,,,,,,,,,,,0.000170,499.995148,,99.989029,1.295739,1545.558594,,,,,,,,,,
,3827626490.86,1.900214,0.3906898,9.9e-006,7,1,4,7,643,643,,,,,,,,,,,,,,,,,,,,,,,0.000208,499.995148,,99.989029,1.295739,1540.543945,,,,,,,,,,
,3827626509.81,1.899887,0.4617243,9.9e-006,7,1,4,7,643,643,,,,,,,,,,,,,,,,,,,,,,,0.000170,499.995148,,99.989029,1.295739,1543.625244,,,,,,,,,,
,3827626528.83,1.900081,0.4972415,9.9e-006,7,1,4,7,643,643,,,,,,,,,,,,,,,,,,,,,,,0.000155,499.995148,,99.989029,1.295739,1542.809448,,,,,,,,,,
,3827626547.54,1.899833,0.4084484,9.9e-006,7,1,4,7,643,643,,,,,,,,,,,,,,,,,,,,,,,0.000218,499.995148,,99.989029,1.295739,1544.319946,,,,,,,,,,
,3827626566.31,1.900022,0.3729312,9.9e-006,7,1,4,7,643,643,,,,,,,,,,,,,,,,,,,,,,,0.000214,499.995148,,99.989029,1.295739,1541.359497,,,,,,,,,,
,3827626585.11,1.90008,0.4084484,9.9e-006,7,1,4,7,643,643,,,,,,,,,,,,,,,,,,,,,,,0.000145,499.995148,,99.989029,1.295739,1539.818848,,,,,,,,,,
,3827626603.96,1.900139,0.4084484,9.9e-006,7,1,4,7,643,643,,,,,,,,,,,,,,,,,,,,,,,0.000205,499.995148,,99.989029,1.295739,1541.359497,,,,,,,,,,
,3827626622.74,1.90015,0.3729312,9.9e-006,7,1,4,7,643,643,,,,,,,,,,,,,,,,,,,,,,,0.000218,499.995148,,99.989029,1.295739,1539.728149,,,,,,,,,,
,3827626641.44,1.899897,0.4439657,9.9e-006,7,1,4,7,643,643,,,,,,,,,,,,,,,,,,,,,,,0.000215,499.995148,,99.989029,1.295739,1541.661499,,,,,,,,,,
,3827626660.35,1.900026,0.4439657,9.9e-006,7,1,4,7,643,643,,,,,,,,,,,,,,,,,,,,,,,0.000219,499.995148,,99.989029,1.295739,1540.483398,,,,,,,,,,
,3827626679.21,1.899644,0.4439657,9.9e-006,7,1,4,7,643,643,,,,,,,,,,,,,,,,,,,,,,,0.000200,499.995148,,99.989029,1.295739,1539.305298,,,,,,,,,,
,3827626697.90,1.900158,0.4084484,9.9e-006,7,1,4,7,643,643,,,,,,,,,,,,,,,,,,,,,,,0.000193,499.995148,,99.989029,1.295739,1538.217651,,,,,,,,,,
,3827626717.00,1.899885,0.426207,9.9e-006,7,1,4,7,643,643,,,,,,,,,,,,,,,,,,,,,,,0.000227,499.995148,,99.989029,1.295739,1538.459473,,,,,,,,,,
,3827626735.84,1.90008,0.3374139,9.9e-006,7,1,4,7,643,643,,,,,,,,,,,,,,,,,,,,,,,0.000147,499.995148,,99.989029,1.295739,1538.852051,,,,,,,,,,
,3827626754.47,1.899996,0.3551725,9.9e-006,7,1,4,7,643,643,,,,,,,,,,,,,,,,,,,,,,,0.000142,499.995148,,99.989029,1.295739,1540.604248,,,,,,,,,,
,3827626773.13,1.900024,0.3729312,9.9e-006,7,1,4,7,643,643,,,,,,,,,,,,,,,,,,,,,,,0.000228,499.995148,,99.989029,1.295739,1540.030151,,,,,,,,,,
,3827626792.12,1.900019,0.4084484,9.9e-006,7,1,4,7,643,643,,,,,,,,,,,,,,,,,,,,,,,0.000176,499.995148,,99.989029,1.295739,1538.459351,,,,,,,,,,
,3827626810.90,1.900205,0.426207,9.9e-006,7,1,4,7,643,643,,,,,,,,,,,,,,,,,,,,,,,0.000236,499.995148,,99.989029,1.295739,1538.580200,,,,,,,,,,
,3827626829.64,1.900262,0.426207,9.9e-006,7,1,4,7,643,643,,,,,,,,,,,,,,,,,,,,,,,0.000171,499.995148,,99.989029,1.295739,1538.429077,,,,,,,,,,
,3827626848.65,1.900174,0.3374139,9.9e-006,7,1,4,7,643,643,,,,,,,,,,,,,,,,,,,,,,,0.000213,499.995148,,99.989029,1.295739,1538.731323,,,,,,,,,,
,3827626867.44,1.900485,0.426207,9.9e-006,7,1,4,7,643,643,,,,,,,,,,,,,,,,,,,,,,,0.000201,499.995148,,99.989029,1.295739,1538.700928,,,,,,,,,,
,3827626886.29,1.900196,0.426207,9.9e-006,7,1,4,7,643,643,,,,,,,,,,,,,,,,,,,,,,,0.000229,499.995148,,99.989029,1.295739,1536.858276,,,,,,,,,,
,3827626905.15,1.899839,0.426207,9.9e-006,7,1,4,7,643,643,,,,,,,,,,,,,,,,,,,,,,,0.000211,499.995148,,99.989029,1.295739,1538.550049,,,,,,,,,,
,3827626923.84,1.899995,0.426207,9.9e-006,7,1,4,7,643,643,,,,,,,,,,,,,,,,,,,,,,,0.000217,499.995148,,99.989029,1.295739,1537.522827,,,,,,,,,,
,3827626942.66,1.900046,0.3729312,9.9e-006,7,1,4,7,643,643,,,,,,,,,,,,,,,,,,,,,,,0.000172,499.995148,,99.989029,1.295739,1539.728149,,,,,,,,,,
,3827626961.58,1.899861,0.3551725,9.9e-006,7,1,4,7,643,643,,,,,,,,,,,,,,,,,,,,,,,0.000192,499.995148,,99.989029,1.295739,1539.093628,,,,,,,,,,
,3827626980.44,1.899749,0.4084484,9.9e-006,7,1,4,7,643,643,,,,,,,,,,,,,,,,,,,,,,,0.000233,499.995148,,99.989029,1.295739,1535.408203,,,,,,,,,,
,3827626999.44,1.900264,0.3374139,9.9e-006,7,1,4,7,643,643,,,,,,,,,,,,,,,,,,,,,,,0.000211,499.995148,,99.989029,1.295739,1537.190430,,,,,,,,,,
,3827627018.23,1.900116,0.3729312,9.9e-006,7,1,4,7,643,643,,,,,,,,,,,,,,,,,,,,,,,0.000197,499.995148,,99.989029,1.295739,1537.704224,,,,,,,,,,
,3827627037.01,1.900228,0.3729312,9.9e-006,7,1,4,7,643,643,,,,,,,,,,,,,,,,,,,,,,,0.000213,499.995148,,99.989029,1.295739,1536.223999,,,,,,,,,,
,3827627055.85,1.899531,0.3906898,9.9e-006,7,1,4,7,643,643,,,,,,,,,,,,,,,,,,,,,,,0.000193,499.995148,,99.989029,1.295739,1538.308472,,,,,,,,,,
,3827627074.57,1.899793,0.3374139,9.9e-006,7,1,4,7,643,643,,,,,,,,,,,,,,,,,,,,,,,0.000176,499.995148,,99.989029,1.295739,1535.891602,,,,,,,,,,
,3827627093.37,1.900039,0.3906898,9.9e-006,7,1,4,7,643,643,,,,,,,,,,,,,,,,,,,,,,,0.000203,499.995148,,99.989029,1.295739,1537.794800,,,,,,,,,,
,3827627112.17,1.900085,0.4084484,9.9e-006,7,1,4,7,643,643,,,,,,,,,,,,,,,,,,,,,,,0.000155,499.995148,,99.989029,1.295739,1535.136230,,,,,,,,,,
,3827627131.07,1.899987,0.4617243,9.9e-006,7,1,4,7,643,643,,,,,,,,,,,,,,,,,,,,,,,0.000228,499.995148,,99.989029,1.295739,1538.489624,,,,,,,,,,
,3827627149.91,1.900042,0.4084484,9.9e-006,7,1,4,7,643,643,,,,,,,,,,,,,,,,,,,,,,,0.000220,499.995148,,99.989029,1.295739,1538.187500,,,,,,,,,,
,3827627168.90,1.899948,0.3551725,9.9e-006,7,1,4,7,643,643,,,,,,,,,,,,,,,,,,,,,,,0.000116,499.995148,,99.989029,1.295739,1537.794678,,,,,,,,,,
,3827627187.65,1.899925,0.426207,9.9e-006,7,1,4,7,643,643,,,,,,,,,,,,,,,,,,,,,,,0.000229,499.995148,,99.989029,1.295739,1536.888550,,,,,,,,,,
,3827627206.43,1.900031,0.3374139,9.9e-006,7,1,4,7,643,643,,,,,,,,,,,,,,,,,,,,,,,0.000167,499.995148,,99.989029,1.295739,1539.365601,,,,,,,,,,
,3827627225.31,1.899901,0.3551725,9.9e-006,7,1,4,7,643,643,,,,,,,,,,,,,,,,,,,,,,,0.000157,499.995148,,99.989029,1.295739,1537.643677,,,,,,,,,,
,3827627244.06,1.899879,0.426207,9.9e-006,7,1,4,7,643,643,,,,,,,,,,,,,,,,,,,,,,,0.000190,499.995148,,99.989029,1.295739,1537.281250,,,,,,,,,,
,3827627262.78,1.900208,0.4084484,9.9e-006,7,1,4,7,643,643,,,,,,,,,,,,,,,,,,,,,,,0.000208,499.995148,,99.989029,1.295739,1535.589478,,,,,,,,,,
,3827627281.51,1.899882,0.426207,9.9e-006,7,1,4,7,643,643,,,,,,,,,,,,,,,,,,,,,,,0.000146,499.995148,,99.989029,1.295739,1537.673950,,,,,,,,,,
,3827627300.25,1.900249,0.4084484,9.9e-006,7,1,4,7,643,643,,,,,,,,,,,,,,,,,,,,,,,0.000175,499.995148,,99.989029,1.295739,1538.398926,,,,,,,,,,
,3827627319.06,1.900061,0.3551725,9.9e-006,7,1,4,7,643,643,,,,,,,,,,,,,,,,,,,,,,,0.000194,499.995148,,99.989029,1.295739,1536.918701,,,,,,,,,,
,3827627337.86,1.900016,0.3729312,9.9e-006,7,1,4,7,643,643,,,,,,,,,,,,,,,,,,,,,,,0.000191,499.995148,,99.989029,1.295739,1536.979248,,,,,,,,,,
,3827627356.63,1.900184,0.3906898,9.9e-006,7,1,4,7,643,643,,,,,,,,,,,,,,,,,,,,,,,0.000188,499.995148,,99.989029,1.295739,1535.831055,,,,,,,,,,
,3827627375.50,1.899821,0.3374139,9.9e-006,7,1,4,7,643,643,,,,,,,,,,,,,,,,,,,,,,,0.000180,499.995148,,99.989029,1.295739,1538.066650,,,,,,,,,,
,3827627394.25,1.900015,0.3729312,9.9e-006,7,1,4,7,643,643,,,,,,,,,,,,,,,,,,,,,,,0.000256,499.995148,,99.989029,1.295739,1534.260254,,,,,,,,,,
,3827627413.08,1.89993,0.3906898,9.9e-006,7,1,4,7,643,643,,,,,,,,,,,,,,,,,,,,,,,0.000177,499.995148,,99.989029,1.295739,1536.042480,,,,,,,,,,
,3827627431.95,1.900217,0.426207,9.9e-006,7,1,4,7,643,643,,,,,,,,,,,,,,,,,,,,,,,0.000158,499.995148,,99.989029,1.295739,1538.972900,,,,,,,,,,
,3827627450.88,1.89991,0.4617243,9.9e-006,7,1,4,7,643,643,,,,,,,,,,,,,,,,,,,,,,,0.000209,499.995148,,99.989029,1.295739,1534.562378,,,,,,,,,,
,3827627469.59,1.90016,0.426207,9.9e-006,7,1,4,7,643,643,,,,,,,,,,,,,,,,,,,,,,,0.000198,499.995148,,99.989029,1.295739,1535.619629,,,,,,,,,,
,3827627488.40,1.899849,0.4794829,9.9e-006,7,1,4,7,643,643,,,,,,,,,,,,,,,,,,,,,,,0.000138,499.995148,,99.989029,1.295739,1534.380981,,,,,,,,,,
,3827627507.32,1.899751,0.4084484,9.9e-006,7,1,4,7,643,643,,,,,,,,,,,,,,,,,,,,,,,0.000205,499.995148,,99.989029,1.295739,1534.743530,,,,,,,,,,
,3827627526.39,1.899976,0.4084484,9.9e-006,7,1,4,7,643,643,,,,,,,,,,,,,,,,,,,,,,,0.000202,499.995148,,99.989029,1.295739,1535.468506,,,,,,,,,,
,3827627545.37,1.899898,0.426207,9.9e-006,7,1,4,7,643,643,,,,,,,,,,,,,,,,,,,,,,,0.000164,499.995148,,99.989029,1.295739,1536.193604,,,,,,,,,,
,3827627564.17,1.899915,0.426207,9.9e-006,7,1,4,7,643,643,,,,,,,,,,,,,,,,,,,,,,,0.000231,499.995148,,99.989029,1.295739,1533.867432,,,,,,,,,,
,3827627582.86,1.899606,0.4084484,9.9e-006,7,1,4,7,643,643,,,,,,,,,,,,,,,,,,,,,,,0.000167,499.995148,,99.989029,1.295739,1536.767578,,,,,,,,,,
,3827627601.62,1.900205,0.3196553,9.9e-006,7,1,4,7,643,643,,,,,,,,,,,,,,,,,,,,,,,0.000213,499.995148,,99.989029,1.295739,1534.683105,,,,,,,,,,
,3827627620.46,1.899766,0.4617243,9.9e-006,0,1,4,7,643,643,,,,,,,,,,,,,,,,,,,,,,,0.000171,499.995148,,99.989029,1.295739,1535.438354,,,,,,,,,,
,3827627639.48,1.899996,0.3551725,9.9e-006,3,1,4,7,643,643,,,,,,,,,,,,,,,,,,,,,,,0.000187,499.995148,,99.989029,1.295739,1538.247925,,,,,,,,,,
,3827627658.27,1.900111,0.4439657,9.9e-006,3,1,4,7,643,643,,,,,,,,,,,,,,,,,,,,,,,0.000218,499.995148,,99.989029,1.295739,1536.163452,,,,,,,,,,
,3827627677.05,1.900177,0.3729312,9.9e-006,3,1,4,7,643,643,,,,,,,,,,,,,,,,,,,,,,,0.000188,499.995148,,99.989029,1.295739,1536.284302,,,,,,,,,,
,3827627696.37,1.900093,0.4084484,9.9e-006,3,1,4,7,643,643,,,,,,,,,,,,,,,,,,,,,,,0.000240,499.995148,,99.989029,1.295739,1537.069702,,,,,,,,,,
,3827627715.03,1.899997,0.4084484,9.9e-006,3,1,4,7,643,643,,,,,,,,,,,,,,,,,,,,,,,0.000179,499.995148,,99.989029,1.295739,1536.163452,,,,,,,,,,
,3827627733.79,1.900285,0.426207,9.9e-006,3,1,4,7,643,643,,,,,,,,,,,,,,,,,,,,,,,0.000231,499.995148,,99.989029,1.295739,1536.465576,,,,,,,,,,
,3827627752.95,1.900119,0.3906898,9.9e-006,3,1,4,7,643,643,,,,,,,,,,,,,,,,,,,,,,,0.000182,499.995148,,99.989029,1.295739,1536.374878,,,,,,,,,,
,3827627771.72,1.899843,0.426207,9.9e-006,3,1,4,7,643,643,,,,,,,,,,,,,,,,,,,,,,,0.000226,499.995148,,99.989029,1.295739,1534.894653,,,,,,,,,,
,3827627790.54,1.899941,0.426207,9.9e-006,3,1,4,7,643,643,,,,,,,,,,,,,,,,,,,,,,,0.000198,499.995148,,99.989029,1.295739,1536.979004,,,,,,,,,,
,3827627809.19,1.899939,0.3906898,9.9e-006,3,1,4,7,643,643,,,,,,,,,,,,,,,,,,,,,,,0.000232,499.995148,,99.989029,1.295739,1537.099976,,,,,,,,,,
,3827627827.92,1.900096,0.3729312,9.9e-006,3,1,4,7,643,643,,,,,,,,,,,,,,,,,,,,,,,0.000245,499.995148,,99.989029,1.295739,1533.142334,,,,,,,,,,
,3827627846.83,1.900061,0.426207,9.9e-006,3,1,4,7,643,643,,,,,,,,,,,,,,,,,,,,,,,0.000180,499.995148,,99.989029,1.295739,1534.773682,,,,,,,,,,
,3827627865.67,1.9,0.426207,9.9e-006,3,1,4,7,643,643,,,,,,,,,,,,,,,,,,,,,,,0.000217,499.995148,,99.989029,1.295739,1536.586304,,,,,,,,,,
,3827627884.68,1.899836,0.426207,9.9e-006,3,1,4,7,643,643,,,,,,,,,,,,,,,,,,,,,,,0.000219,499.995148,,99.989029,1.295739,1533.595581,,,,,,,,,,
,3827627903.70,1.899936,0.3374139,9.9e-006,3,1,4,7,643,643,,,,,,,,,,,,,,,,,,,,,,,0.000237,499.995148,,99.989029,1.295739,1534.411377,,,,,,,,,,
,3827627922.56,1.912701,0.3729312,9.9e-006,3,2,4,7,643,643,,,,,,,,,,,,,,,,,,,,,,,0.000192,499.995148,,99.989029,1.295739,1537.855225,,,,,,,,,,
,3827627941.40,1.943793,0.3906898,9.9e-006,3,2,4,7,643,643,,,,,,,,,,,,,,,,,,,,,,,0.000173,499.995148,,99.989029,1.295739,1536.163452,,,,,,,,,,
,3827627960.07,1.974613,0.3906898,9.9e-006,3,2,4,7,643,643,,,,,,,,,,,,,,,,,,,,,,,0.000215,499.995148,,99.989029,1.295739,1536.405151,,,,,,,,,,
,3827627978.91,2.006163,0.4439657,9.9e-006,3,2,4,7,643,643,,,,,,,,,,,,,,,,,,,,,,,0.000200,499.995148,,99.989029,1.295739,1535.770752,,,,,,,,,,
,3827627997.82,2.038249,0.4084484,9.9e-006,3,2,4,7,643,643,,,,,,,,,,,,,,,,,,,,,,,0.000197,499.995148,,99.989029,1.295739,1530.151733,,,,,,,,,,
,3827628016.87,2.069993,0.426207,9.9e-006,3,2,4,7,643,643,,,,,,,,,,,,,,,,,,,,,,,0.000179,499.995148,,99.989029,1.295739,1531.631958,,,,,,,,,,
,3827628035.78,2.100951,0.4084484,9.9e-006,3,2,4,7,643,643,,,,,,,,,,,,,,,,,,,,,,,0.000247,499.995148,,99.989029,1.295739,1524.502441,,,,,,,,,,
,3827628054.41,2.132285,0.4084484,9.9e-006,3,2,4,7,643,643,,,,,,,,,,,,,,,,,,,,,,,0.000241,499.995148,,99.989029,1.295739,1522.569092,,,,,,,,,,
,3827628073.05,2.163586,0.3196553,9.9e-006,3,2,4,7,643,643,,,,,,,,,,,,,,,,,,,,,,,0.000195,499.995148,,99.989029,1.295739,1514.351929,,,,,,,,,,
,3827628091.84,2.194806,0.3374139,9.9e-006,3,2,4,7,643,643,,,,,,,,,,,,,,,,,,,,,,,0.000204,499.995148,,99.989029,1.295739,1508.763062,,,,,,,,,,
,3827628110.68,2.226506,0.3374139,9.9e-006,3,2,4,7,643,643,,,,,,,,,,,,,,,,,,,,,,,0.000161,499.995148,,99.989029,1.295739,1501.361816,,,,,,,,,,
,3827628129.54,2.258121,0.3374139,9.9e-006,3,2,4,7,643,643,,,,,,,,,,,,,,,,,,,,,,,0.000183,499.995148,,99.989029,1.295739,1491.543579,,,,,,,,,,
,3827628148.51,2.289782,0.4084484,9.9e-006,3,2,4,7,643,643,,,,,,,,,,,,,,,,,,,,,,,0.000170,499.995148,,99.989029,1.295739,1486.830933,,,,,,,,,,
,3827628167.39,2.32057,0.4084484,9.9e-006,3,2,4,7,643,643,,,,,,,,,,,,,,,,,,,,,,,0.000183,499.995148,,99.989029,1.295739,1482.510864,,,,,,,,,,
,3827628186.50,2.35305,0.426207,9.9e-006,3,2,4,7,643,643,,,,,,,,,,,,,,,,,,,,,,,0.000167,499.995148,,99.989029,1.295739,1475.774292,,,,,,,,,,
,3827628205.25,2.384682,0.3729312,9.9e-006,3,2,4,7,643,643,,,,,,,,,,,,,,,,,,,,,,,0.000194,499.995148,,99.989029,1.295739,1470.819824,,,,,,,,,,
,3827628223.97,2.415124,0.3729312,9.9e-006,3,2,4,7,643,643,,,,,,,,,,,,,,,,,,,,,,,0.000217,499.995148,,99.989029,1.295739,1465.261230,,,,,,,,,,
,3827628242.89,2.446689,0.3196553,9.9e-006,3,2,4,7,643,643,,,,,,,,,,,,,,,,,,,,,,,0.000255,499.995148,,99.989029,1.295739,1461.757080,,,,,,,,,,
,3827628261.61,2.478064,0.3729312,9.9e-006,3,2,4,7,643,643,,,,,,,,,,,,,,,,,,,,,,,0.000228,499.995148,,99.989029,1.295739,1458.947510,,,,,,,,,,
,3827628280.31,2.509444,0.3729312,9.9e-006,3,2,4,7,643,643,,,,,,,,,,,,,,,,,,,,,,,0.000185,499.995148,,99.989029,1.295739,1453.388916,,,,,,,,,,
,3827628299.14,2.539982,0.3729312,9.9e-006,3,2,4,7,643,643,,,,,,,,,,,,,,,,,,,,,,,0.000191,499.995148,,99.989029,1.295739,1448.887573,,,,,,,,,,
,3827628317.94,2.572557,0.3374139,9.9e-006,3,2,4,7,643,643,,,,,,,,,,,,,,,,,,,,,,,0.000177,499.995148,,99.989029,1.295739,1444.990723,,,,,,,,,,
,3827628336.75,2.60283,0.426207,9.9e-006,3,2,4,7,643,643,,,,,,,,,,,,,,,,,,,,,,,0.000267,499.995148,,99.989029,1.295739,1442.453003,,,,,,,,,,
,3827628355.55,2.635025,0.3906898,9.9e-006,3,2,4,7,643,643,,,,,,,,,,,,,,,,,,,,,,,0.000198,499.995148,,99.989029,1.295739,1437.226563,,,,,,,,,,
,3827628374.40,2.665907,0.3729312,9.9e-006,3,2,4,7,643,643,,,,,,,,,,,,,,,,,,,,,,,0.000202,499.995148,,99.989029,1.295739,1434.235962,,,,,,,,,,
,3827628393.17,2.697187,0.3374139,9.9e-006,3,2,4,7,643,643,,,,,,,,,,,,,,,,,,,,,,,0.000232,499.995148,,99.989029,1.295739,1432.181519,,,,,,,,,,
,3827628411.87,2.728665,0.426207,9.9e-006,3,2,4,7,643,643,,,,,,,,,,,,,,,,,,,,,,,0.000238,499.995148,,99.989029,1.295739,1429.281494,,,,,,,,,,
,3827628430.76,2.75983,0.3906898,0.0001117723,3,2,4,7,643,643,,,,,,,,,,,,,,,,,,,,,,,0.000194,499.995148,,99.989029,1.295739,1425.444824,,,,,,,,,,
,3827628449.73,2.790593,0.4439657,0.0002908685,3,2,4,7,643,643,,,,,,,,,,,,,,,,,,,,,,,0.000212,499.995148,,99.989029,1.295739,1420.671631,,,,,,,,,,
,3827628468.68,2.823719,0.3729312,0.0004520793,3,2,4,7,643,643,,,,,,,,,,,,,,,,,,,,,,,0.000190,499.995148,,99.989029,1.295739,1419.402954,,,,,,,,,,
,3827628487.56,2.855688,0.3906898,0.0006027513,3,2,4,7,643,643,,,,,,,,,,,,,,,,,,,,,,,0.000186,499.995148,,99.989029,1.295739,1414.871582,,,,,,,,,,
,3827628506.27,2.886859,0.4084484,0.0007710175,3,2,4,7,643,643,,,,,,,,,,,,,,,,,,,,,,,0.000201,499.995148,,99.989029,1.295739,1411.608765,,,,,,,,,,
,3827628525.24,2.917709,0.3729312,0.001017176,3,2,4,7,643,643,,,,,,,,,,,,,,,,,,,,,,,0.000200,499.995148,,99.989029,1.295739,1410.158936,,,,,,,,,,
,3827628543.98,2.949137,0.3906898,0.001116436,3,2,4,7,643,643,,,,,,,,,,,,,,,,,,,,,,,0.000228,499.995148,,99.989029,1.295739,1406.352173,,,,,,,,,,
,3827628562.74,2.980554,0.3196553,0.00135486,3,2,4,7,643,643,,,,,,,,,,,,,,,,,,,,,,,0.000189,499.995148,,99.989029,1.295739,1402.092773,,,,,,,,,,
,3827628581.49,2.999883,0.3729312,0.001588406,3,5,4,7,643,643,,,,,,,,,,,,,,,,,,,,,,,0.000203,499.995148,,99.989029,1.295739,1397.772583,,,,,,,,,,
,3827628600.32,2.999125,0.4084484,0.001538456,3,5,4,7,643,643,,,,,,,,,,,,,,,,,,,,,,,0.000188,499.995148,,99.989029,1.295739,1401.911499,,,,,,,,,,
,3827628619.11,2.999905,0.4794829,0.001449964,3,5,4,7,643,643,,,,,,,,,,,,,,,,,,,,,,,0.000256,499.995148,,99.989029,1.295739,1399.283325,,,,,,,,,,
,3827628625.95,2.999806,0.4617243,0.001545344,3,1,4,7,643,643,,,,,,,,,,,,,,,,,,,,,,,0.000178,499.995148,,99.989029,1.295739,1400.944824,,,,,,,,,,