File: Sample_Data/ADR__CaSb2-b3-1_R(0p1-15K)_100uA_0OeParaXtal_20210411.dat
[Header]
; Copyright 1997-99, Quantum Design, Inc. All rights reserved.
FILEOPENTIME,35965019.63,4/11/2021,1:16 AM
BYAPP, LogData, 1.1, 2.0
INFO, APPNAME, PPMS MultiVu Application, 1.5.11
FIELDGROUP, Standard,2,3,4,5,6,7,8,9,10,11,12,13,14,15,16,17,18,19,20,21,22,23,24,25,26,27,28,29,30,31,32
FIELDGROUP, Diagnostic,2,32,33,34,35,36,37,38,39,40,41,42,43,44,45,46,47,48,49,50,51,52,53,54
FIELDGROUP, User,2,64,65,66,67,68,69,70,71,72,73,74,75,76,77,78,79,80,81,82,83,84,85,86,87,88,89,90,91,92,93
FIELDGROUP, MAP User,2,96,97,98,99,100,101,102,103,104,105,106,107,108,109,110,111,112,113,114,115,116,117,118,119,120,121,122,123,124,125
STARTUPGROUP, All
STARTUPAXIS, X, 2, LINEAR, AUTO
STARTUPAXIS, Y1, 4, LINEAR, AUTO
TIMEMODE, MINUTES, RELATIVE
PLOT_APPEARANCE, ALL, HORZ_GRID_ON, VERT_GRID_ON, MARKERS_AND_LINES, ALL_LINES
RECORDS, ALL_RECORDS
DATATYPE, TIME, 2
DATATYPE, COMMENT, 1
[Data]
Comment,Time Stamp (sec),Status (code),Temperature (K),Magnetic Field (Oe),Sample Position (deg),Bridge 1 Resistance (ohms),Bridge 1 Excitation (uA),Bridge 2 Resistance (ohms),Bridge 2 Excitation (uA),Bridge 3 Resistance (ohms),Bridge 3 Excitation (uA),Bridge 4 Resistance (ohms),Bridge 4 Excitation (uA),Signal 1 Vin (V),Signal 2 Vin (V),Digital Inputs (code),Drive 1 Iout (mA),Drive 1 Ipower (watts),Drive 2 Iout (mA),Drive 2 Ipower (watts),Pressure (),Map 20 (),Map 21 (),Map 22 (),Map 23 (),Map 24 (),Map 25 (),Map 26 (),Map 27 (),Map 28 (),Map 29 (),System Status (code),Setpoint (K),Magnet (Oe),Valve Position (deg),CIG/Cernox (K),CIG Excit (uA),Plat Therm (K),Plat Excit (uA),Neck Therm (K),Neck Excit (uA),Spare Therm (K),Spare Excit (uA),Flow Rate (l/min),Annulus Vacuum (V),Impedance (mode),Block Htr Cur (mA),Block Htr Pwr (W),Neck Htr Cur (mA),Neck Htr Pwr (W),Annulus Pres (Torr),System Pres (Torr),Tableless Map53 (),Tableless Map54 (),Redirected 55 (),Redirected 56 (),Redirected 57 (),Redirected 58 (),Redirected 59 (),Redirected 60 (),Redirected 61 (),Seq Stat (),Sys Temp (),He Level (),Map 67 (),Map 68 (),Map 69 (),PSU Field (Oe),Hi res (A) read,Mag (V) read,Mag adj/sc(I)set,Sw heater state,DAC <I> (cnts),Therm V,KRPMs,Pump temp (C),pump power (W),High Vacuum mode,Flapper state,Regen htr flag,iso flag,BlockHeater(Ohm),NeckHeater(Ohm),Map 86 (),Map 87 (),Map 88 (),Map 89 (),Map 90 (),Map 91 (),Map 92 (),Map 93 (),MAP 1,MAP 2,MAP 3,MAP 4,MAP 5,MAP 6,MAP 7,MAP 8,MAP 9,MAP 10,MAP 11,MAP 12,MAP 13,MAP 14,MAP 15,MAP 16,MAP 17,MAP 18,MAP 19,MAP 20,MAP 21,MAP 22,MAP 23,MAP 24,MAP 25,MAP 26,MAP 27,MAP 28,MAP 29,MAP 30
,35965019.84,5905,1.9000,0.801041,364.80991,-1.9092176e-5,99.902,,,2.1409409e3,9.990,,,0.0049,0.0000,48,0.00,0.00,0.00,0.00,0.0001179,,400.0017395,,,,,1.706546e-3,1.0314655,,
,35965067.88,5905,1.8985,0.801041,364.80991,-1.7182960e-4,99.902,,,2.1409143e3,9.990,,,0.0049,0.0000,48,0.00,0.00,0.00,0.00,0.0001179,,400.0017395,,,,,-7.712511e-2,1.0314741,,
,35965115.72,5905,1.9004,0.801041,364.80991,1.9092177e-4,99.902,,,2.1408838e3,9.990,,,0.0049,0.0000,48,0.00,0.00,0.00,0.00,0.0001165,,400.0017395,,,,,1.929563e-2,1.0314840,,
,35965163.75,5905,1.9002,0.801041,364.80991,-9.5460884e-5,99.902,,,2.1409124e3,9.990,,,0.0049,0.0000,48,0.00,0.00,0.00,0.00,0.0001208,,400.0017395,,,,,1.051441e-2,1.0314747,,
,35965211.89,5905,1.8978,0.801041,364.80991,2.6729048e-4,99.902,,,2.1408760e3,9.990,,,0.0000,0.0000,48,0.00,0.00,0.00,0.00,0.0001165,,400.0017395,,,,,-0.115207,1.0314865,,
,35965259.75,5905,1.9010,0.801041,364.80991,-3.8184354e-4,99.902,,,2.1408352e3,9.990,,,0.0049,-0.0049,48,0.00,0.00,0.00,0.00,0.0001208,,400.0017395,,,,,5.449912e-2,1.0314996,,
,35965307.98,5905,1.9006,0.801041,364.80991,5.7276531e-5,99.902,,,2.1407703e3,9.990,,,0.0049,0.0000,48,0.00,0.00,0.00,0.00,0.0001208,,400.0017395,,,,,3.042675e-2,1.0315206,,
,35965355.72,5905,1.9009,0.801041,364.80991,2.1001394e-4,99.902,,,2.1406423e3,9.990,,,0.0049,0.0000,48,0.00,0.00,0.00,0.00,0.0001194,,400.0017395,,,,,4.564259e-2,1.0315619,,
,35965403.91,5905,1.8980,0.801041,364.80991,-1.5273741e-4,99.902,,,2.1406423e3,9.990,,,0.0049,-0.0049,48,0.00,0.00,0.00,0.00,0.0001179,,400.0017395,,,,,-0.103952,1.0315619,,
,35965451.91,5905,1.8980,0.801041,364.80991,-1.9092177e-4,99.902,,,2.1405728e3,9.990,,,0.0049,-0.0049,48,0.00,0.00,0.00,0.00,0.0001194,,400.0017395,,,,,-0.105876,1.0315843,,
,35965499.92,5905,1.9009,0.801041,364.80991,-1.9092176e-5,99.902,,,2.1405588e3,9.990,,,0.0049,0.0000,48,0.00,0.00,0.00,0.00,0.0001194,,400.0017395,,,,,4.523514e-2,1.0315888,,
,35965547.67,5905,1.9019,0.801041,364.80991,1.1455306e-4,99.902,,,2.1403757e3,9.990,,,0.0000,0.0049,48,0.00,0.00,0.00,0.00,0.0001194,,400.0017395,,,,,9.964741e-2,1.0316479,,
,35965596.23,5905,1.8986,0.801041,364.80991,-2.1001394e-4,99.902,,,2.1403545e3,9.990,,,0.0000,0.0049,48,0.00,0.00,0.00,0.00,0.0001165,,400.0017395,,,,,-7.397071e-2,1.0316547,,
,35965643.78,5905,1.9021,0.801041,364.80991,3.8184353e-5,99.902,,,2.1402876e3,9.990,,,0.0000,-0.0049,48,0.00,0.00,0.00,0.00,0.0001194,,400.0017395,,,,,0.110786,1.0316763,,
,35965691.72,5905,1.8975,0.801041,364.80991,-1.1455306e-4,99.902,,,2.1400879e3,9.990,,,0.0049,-0.0049,48,0.00,0.00,0.00,0.00,0.0001179,,400.0017395,,,,,-0.133649,1.0317408,,
,35965739.84,5905,1.8975,0.801041,364.80991,-7.6368706e-5,99.902,,,2.1400476e3,9.990,,,0.0049,0.0049,48,0.00,0.00,0.00,0.00,0.0001179,,400.0017395,,,,,-0.133636,1.0317538,,
,35965787.84,5905,1.9008,0.801041,364.80991,-1.9092176e-5,99.902,,,2.1397009e3,9.990,,,0.0000,-0.0049,48,0.00,0.00,0.00,0.00,0.0001194,,400.0017395,,,,,4.420710e-2,1.0318657,,
,35965835.84,5905,1.9009,0.801041,364.80991,-1.1455306e-4,99.902,,,2.1395232e3,9.990,,,0.0049,0.0000,48,0.00,0.00,0.00,0.00,0.0001194,,400.0017395,,,,,4.782396e-2,1.0319232,,
,35965883.72,5905,1.8978,0.801041,364.80991,1.1455306e-4,99.902,,,2.1393323e3,9.990,,,0.0049,0.0000,48,0.00,0.00,0.00,0.00,0.0001208,,400.0017395,,,,,-0.114912,1.0319848,,
,35965931.81,5905,1.8996,0.801041,364.80991,2.1001394e-4,99.902,,,2.1390864e3,9.990,,,0.0049,0.0049,48,0.00,0.00,0.00,0.00,0.0001179,,400.0017395,,,,,-1.854362e-2,1.0320643,,
,35965979.89,5905,1.8982,0.801041,364.80991,1.5273741e-4,99.902,,,2.1388989e3,9.990,,,0.0000,0.0049,48,0.00,0.00,0.00,0.00,0.0001179,,400.0017395,,,,,-9.331494e-2,1.0321249,,
,35966027.80,5905,1.8994,0.801041,364.80991,-2.8638265e-4,99.902,,,2.1386057e3,9.990,,,0.0049,0.0000,48,0.00,0.00,0.00,0.00,0.0001179,,400.0017395,,,,,-3.373506e-2,1.0322196,,
,35966075.77,5905,1.9017,0.801041,364.80991,2.8638265e-4,99.902,,,2.1382537e3,9.990,,,0.0049,0.0000,48,0.00,0.00,0.00,0.00,0.0001165,,400.0017395,,,,,8.720391e-2,1.0323336,,
,35966123.94,5905,1.8998,0.801041,364.80991,1.5273741e-4,99.902,,,2.1377856e3,9.990,,,0.0049,-0.0049,48,0.00,0.00,0.00,0.00,0.0001208,,400.0017395,,,,,-1.202276e-2,1.0324850,,
,35966171.66,5905,1.8998,0.801041,364.80991,-2.1001394e-4,99.902,,,2.1372341e3,9.990,,,0.0049,0.0000,48,0.00,0.00,0.00,0.00,0.0001223,,400.0017395,,,,,-8.094339e-3,1.0326636,,
,35966219.83,5905,1.8982,0.801041,364.80991,-4.7730442e-4,99.902,,,2.1366318e3,9.990,,,0.0000,0.0049,48,0.00,0.00,0.00,0.00,0.0001179,,400.0017395,,,,,-9.708661e-2,1.0328586,,
,35966268.09,5905,1.9018,0.801041,364.80991,1.1455306e-4,99.902,,,2.1360112e3,9.990,,,0.0049,0.0000,48,0.00,0.00,0.00,0.00,0.0001165,,400.0017395,,,,,9.388007e-2,1.0330595,,
,35966315.94,5905,1.8990,0.801041,364.80991,,99.902,,,2.1353621e3,9.990,,,0.0000,0.0049,48,0.00,0.00,0.00,0.00,0.0001179,,,,,,,-5.035048e-2,1.0332692,,
,35966363.67,5905,1.8987,0.801041,364.80991,2.1001394e-4,99.902,,,2.1344646e3,9.990,,,0.0000,-0.0049,48,0.00,0.00,0.00,0.00,0.0001194,,400.0017395,,,,,-6.937143e-2,1.0335592,,
,35966411.67,5905,1.9013,0.801041,364.80991,1.9092176e-5,99.902,,,2.1335769e3,9.990,,,0.0000,0.0000,48,0.00,0.00,0.00,0.00,0.0001165,,400.0017395,,,,,6.703849e-2,1.0338463,,
,35966459.86,5905,1.8984,0.801041,364.80991,7.6368706e-5,99.902,,,2.1325679e3,9.990,,,0.0000,0.0000,48,0.00,0.00,0.00,0.00,0.0001208,,400.0017395,,,,,-8.239754e-2,1.0341729,,
,35966507.88,5905,1.8994,0.801041,364.80991,-3.2456699e-4,99.902,,,2.1313240e3,9.990,,,0.0049,0.0000,48,0.00,0.00,0.00,0.00,0.0001179,,400.0017395,,,,,-3.001838e-2,1.0345761,,
,35966555.84,5905,1.9017,0.801041,364.80991,,99.902,,,2.1299778e3,9.990,,,0.0049,0.0000,48,0.00,0.00,0.00,0.00,0.0001194,,,,,,,8.856302e-2,1.0350130,,
,35966603.86,5905,1.8982,0.801041,364.80991,,99.902,,,2.1283723e3,9.990,,,0.0000,0.0049,48,0.00,0.00,0.00,0.00,0.0001165,,,,,,,-9.599280e-2,1.0355347,,
,35966651.75,5905,1.8982,0.801041,364.80991,-1.9092176e-5,99.902,,,2.1267043e3,9.990,,,0.0049,0.0000,48,0.00,0.00,0.00,0.00,0.0001194,,400.0017395,,,,,-9.381781e-2,1.0360777,,
,35966699.83,5905,1.9011,0.801041,364.80991,3.8184353e-5,99.902,,,2.1246433e3,9.990,,,0.0000,-0.0049,48,0.00,0.00,0.00,0.00,0.0001194,,400.0017395,,,,,5.622261e-2,1.0367501,,
,35966747.64,5905,1.8991,0.801041,364.80991,-3.6275137e-4,99.902,,,2.1221689e3,9.990,,,0.0049,0.0049,48,0.00,0.00,0.00,0.00,0.0001179,,400.0017395,,,,,-4.706589e-2,1.0375592,,
,35966795.75,5905,1.8996,0.801041,364.80991,-3.0547482e-4,99.902,,,2.1195049e3,9.990,,,0.0098,0.0049,48,0.00,0.00,0.00,0.00,0.0001208,,400.0017395,,,,,-2.247286e-2,1.0384324,,
,35966843.78,5905,1.9013,0.801041,364.80991,-1.3364524e-4,99.902,,,2.1163804e3,9.990,,,0.0049,-0.0049,48,0.00,0.00,0.00,0.00,0.0001194,,400.0017395,,,,,7.079781e-2,1.0394596,,
,35966891.78,5905,1.8996,0.801041,364.80991,2.8638265e-4,99.902,,,2.1127634e3,9.990,,,0.0049,0.0049,48,0.00,0.00,0.00,0.00,0.0001194,,400.0017395,,,,,-2.343953e-2,1.0406530,,
,35966939.66,5905,1.8981,0.801041,364.80991,9.5460884e-5,99.902,,,2.1086843e3,9.990,,,0.0049,0.0000,48,0.00,0.00,0.00,0.00,0.0001179,,400.0017395,,,,,-9.840047e-2,1.0420040,,
,35966988.03,5905,1.8980,0.801041,364.80991,-2.1001394e-4,99.902,,,2.1039302e3,9.990,,,0.0049,-0.0049,48,0.00,0.00,0.00,0.00,0.0001179,,400.0017395,,,,,-0.105046,1.0435857,,
,35967035.69,5905,1.8974,0.801041,364.80991,3.0547482e-4,99.902,,,2.0985444e3,9.990,,,-0.0049,0.0000,48,0.00,0.00,0.00,0.00,0.0001194,,400.0017395,,,,,-0.137839,1.0453870,,
,35967083.86,5905,1.9018,0.801041,364.80991,-3.8184353e-5,99.902,,,2.0923174e3,9.990,,,0.0049,0.0000,48,0.00,0.00,0.00,0.00,0.0001165,,400.0017395,,,,,9.248354e-2,1.0474823,,
,35967131.91,5905,1.9001,0.801041,364.80991,5.3458096e-4,99.902,,,2.0851975e3,9.990,,,0.0049,0.0049,48,0.00,0.00,0.00,0.00,0.0001165,,400.0017395,,,,,3.017786e-3,1.0498945,,
,35967179.61,5905,1.8974,0.801041,364.80991,2.8638265e-4,99.902,,,2.0769722e3,9.990,,,0.0000,0.0049,48,0.00,0.00,0.00,0.00,0.0001179,,400.0017395,,,,,-0.138248,1.0527036,,
,35967227.78,5905,1.8987,0.801041,364.80991,7.6368706e-5,99.902,,,2.0677886e3,9.990,,,0.0000,-0.0049,48,0.00,0.00,0.00,0.00,0.0001194,,400.0017395,,,,,-6.744891e-2,1.0558685,,
,35967275.73,5905,1.8989,0.801041,364.80991,-3.8184353e-5,99.902,,,2.0573228e3,9.990,,,0.0049,0.0049,48,0.00,0.00,0.00,0.00,0.0001208,,400.0017395,,,,,-5.768663e-2,1.0595127,,
,35967323.64,5905,1.8988,0.801041,364.80991,4.2002788e-4,99.902,,,2.0454618e3,9.990,,,0.0000,-0.0049,48,0.00,0.00,0.00,0.00,0.0001223,,400.0017395,,,,,-6.271830e-2,1.0636917,,
,35967371.91,5905,1.9033,0.801041,364.80991,-1.5273741e-4,99.902,,,2.0323424e3,9.990,,,0.0049,-0.0049,48,0.00,0.00,0.00,0.00,0.0001194,,400.0017395,,,,,0.171536,1.0683757,,
,35967419.88,5905,1.8997,0.801041,364.80991,-1.9092176e-5,99.902,,,2.0176654e3,9.990,,,0.0049,0.0000,48,0.00,0.00,0.00,0.00,0.0001179,,400.0017395,,,,,-1.629668e-2,1.0736945,,
,35967467.69,5905,1.9024,0.801041,364.80991,-1.7182960e-4,99.902,,,2.0018429e3,9.990,,,0.0098,0.0000,48,0.00,0.00,0.00,0.00,0.0001179,,400.0017395,,,,,0.128418,1.0795232,,
,35967515.81,5905,1.8990,0.801041,364.80991,3.4365919e-4,99.902,,,1.9844828e3,9.990,,,0.0049,-0.0049,48,0.00,0.00,0.00,0.00,0.0001165,,400.0017395,,,,,-5.083408e-2,1.0860347,,
,35967563.69,5905,1.8991,0.801041,364.80991,-2.6729048e-4,99.902,,,1.9659670e3,9.990,,,0.0000,0.0000,48,0.00,0.00,0.00,0.00,0.0001194,,400.0017395,,,,,-4.656349e-2,1.0931177,,
,35967611.83,5905,1.9015,0.801041,364.80991,3.2456699e-4,99.902,,,1.9463534e3,9.990,,,0.0049,-0.0049,48,0.00,0.00,0.00,0.00,0.0001194,,400.0017395,,,,,8.038905e-2,1.1007810,,
,35967659.77,5905,1.9022,0.801041,364.80991,2.1001394e-4,99.902,,,1.9259689e3,9.990,,,0.0049,0.0000,48,0.00,0.00,0.00,0.00,0.0001194,,400.0017395,,,,,0.115086,1.1089259,,
,35967707.69,5905,1.8977,0.801041,364.80991,-1.5273741e-4,99.902,,,1.9052288e3,9.990,,,0.0000,0.0000,48,0.00,0.00,0.00,0.00,0.0001179,,400.0017395,,,,,-0.119175,1.1174084,,
,35967755.81,5905,1.8984,0.801041,364.80991,-7.6368706e-5,99.902,,,1.8839829e3,9.990,,,0.0049,0.0000,48,0.00,0.00,0.00,0.00,0.0001194,,400.0017395,,,,,-8.172510e-2,1.1263094,,
,35967803.69,5905,1.8987,0.801041,364.80991,9.5460884e-5,99.902,,,1.8630023e3,9.990,,,0.0049,0.0000,48,0.00,0.00,0.00,0.00,0.0001208,,400.0017395,,,,,-6.676410e-2,1.1353173,,
,35967851.72,5905,1.8998,0.801041,364.80991,-1.7182960e-4,99.902,,,1.8423312e3,9.990,,,0.0049,0.0049,48,0.00,0.00,0.00,0.00,0.0001194,,400.0017395,,,,,-9.901626e-3,1.1444123,,
,35967899.73,5905,1.9016,0.801041,364.80991,-3.2456699e-4,99.902,,,1.8220316e3,9.990,,,0.0049,0.0000,48,0.00,0.00,0.00,0.00,0.0001179,,400.0017395,,,,,8.396571e-2,1.1535678,,
,35967947.97,5905,1.9033,0.801041,364.80991,1.9092177e-4,99.902,,,1.8027319e3,9.990,,,0.0049,0.0049,48,0.00,0.00,0.00,0.00,0.0001194,,400.0017395,,,,,0.171267,1.1624882,,
,35967995.59,5905,1.9000,0.801041,364.80991,,99.902,,,1.7842544e3,9.990,,,0.0049,0.0049,48,0.00,0.00,0.00,0.00,0.0001194,,,,,,,-2.139539e-3,1.1712321,,
,35968044.02,5905,1.9024,0.801041,364.80991,7.6368706e-5,99.902,,,1.7664465e3,9.990,,,0.0049,0.0049,48,0.00,0.00,0.00,0.00,0.0001179,,400.0017395,,,,,0.127535,1.1798549,,
,35968091.63,5905,1.8990,0.801041,364.80991,-5.7276531e-5,99.902,,,1.7500510e3,9.990,,,0.0049,0.0000,48,0.00,0.00,0.00,0.00,0.0001179,,400.0017395,,,,,-5.165056e-2,1.1879698,,
,35968139.69,5905,1.9013,0.801041,364.80991,4.0093571e-4,99.902,,,1.7347216e3,9.990,,,0.0000,0.0000,48,0.00,0.00,0.00,0.00,0.0001194,,400.0017395,,,,,6.814752e-2,1.1957154,,
,35968187.75,5905,1.8981,0.801041,364.80991,2.2910612e-4,99.902,,,1.7202740e3,9.990,,,0.0000,-0.0049,48,0.00,0.00,0.00,0.00,0.0001208,,400.0017395,,,,,-9.860794e-2,1.2031599,,
,35968235.59,5905,1.8997,0.801041,364.80991,-2.1001394e-4,99.902,,,1.7069438e3,9.990,,,0.0049,0.0049,48,0.00,0.00,0.00,0.00,0.0001179,,400.0017395,,,,,-1.571927e-2,1.2101572,,
,35968283.66,5905,1.8986,0.801041,364.80991,-2.8638265e-4,99.902,,,1.6944105e3,9.990,,,0.0098,-0.0049,48,0.00,0.00,0.00,0.00,0.0001194,,400.0017395,,,,,-7.334865e-2,1.2168519,,
,35968331.59,5905,1.8972,0.801041,364.80991,3.4365919e-4,99.902,,,1.6830114e3,9.990,,,0.0098,0.0000,48,0.00,0.00,0.00,0.00,0.0001208,,400.0017395,,,,,-0.149555,1.2230411,,
,35968379.58,5905,1.8984,0.801041,364.80991,-3.0547482e-4,99.902,,,1.6724452e3,9.990,,,0.0049,0.0000,48,0.00,0.00,0.00,0.00,0.0001179,,400.0017395,,,,,-8.667120e-2,1.2288653,,
,35968427.69,5905,1.8969,0.801041,364.80991,1.1455306e-4,99.902,,,1.6625145e3,9.990,,,0.0049,-0.0049,48,0.00,0.00,0.00,0.00,0.0001208,,400.0017395,,,,,-0.162791,1.2344178,,
,35968475.77,5905,1.8993,0.801041,364.80991,1.7182960e-4,99.902,,,1.6535619e3,9.990,,,0.0000,0.0049,48,0.00,0.00,0.00,0.00,0.0001194,,400.0017395,,,,,-3.661065e-2,1.2394902,,
,35968523.91,5905,1.9016,0.801041,364.80991,3.4365919e-4,99.902,,,1.6450573e3,9.990,,,0.0049,-0.0049,48,0.00,0.00,0.00,0.00,0.0001208,,400.0017395,,,,,8.594499e-2,1.2443684,,
,35968571.78,5905,1.9014,0.801041,364.80991,-1.7182960e-4,99.902,,,1.6376932e3,9.990,,,0.0049,0.0049,48,0.00,0.00,0.00,0.00,0.0001179,,400.0017395,,,,,7.294049e-2,1.2486405,,
,35968619.73,5905,1.8982,0.801041,364.80991,2.8638265e-4,99.902,,,1.6306816e3,9.990,,,0.0049,0.0000,48,0.00,0.00,0.00,0.00,0.0001194,,400.0017395,,,,,-9.249777e-2,1.2527504,,
,35968667.78,5905,1.8984,0.801041,364.80991,3.6275137e-4,99.902,,,1.6241597e3,9.990,,,0.0049,0.0000,48,0.00,0.00,0.00,0.00,0.0001194,,400.0017395,,,,,-8.220272e-2,1.2566106,,
,35968715.66,5905,1.9016,0.801041,364.80991,2.4819831e-4,99.902,,,1.6181140e3,9.990,,,0.0049,0.0049,48,0.00,0.00,0.00,0.00,0.0001194,,400.0017395,,,,,8.278814e-2,1.2602218,,
,35968763.72,5905,1.9020,0.801041,364.80991,7.6368706e-5,99.902,,,1.6123086e3,9.990,,,0.0000,-0.0049,48,0.00,0.00,0.00,0.00,0.0001208,,400.0017395,,,,,0.103473,1.2637197,,
,35968811.80,5905,1.9000,0.801041,364.80991,1.3364524e-4,99.902,,,1.6069286e3,9.990,,,0.0049,0.0000,48,0.00,0.00,0.00,0.00,0.0001151,,400.0017395,,,,,9.348431e-4,1.2669879,,
,35968859.89,5905,1.8983,0.801041,364.80991,5.1548879e-4,99.902,,,1.6018962e3,9.990,,,0.0049,0.0000,48,0.00,0.00,0.00,0.00,0.0001179,,400.0017395,,,,,-8.796593e-2,1.2700685,,
,35968907.58,5905,1.8986,0.801041,364.80991,4.0093571e-4,99.902,,,1.5973702e3,9.990,,,0.0049,-0.0049,48,0.00,0.00,0.00,0.00,0.0001194,,400.0017395,,,,,-7.205429e-2,1.2728589,,
,35968955.78,5905,1.9001,0.801041,364.80991,-1.3364524e-4,99.902,,,1.5931647e3,9.990,,,0.0000,-0.0049,48,0.00,0.00,0.00,0.00,0.0001208,,400.0017395,,,,,5.495874e-3,1.2754685,,
,35969003.78,5905,1.8999,0.801041,364.80991,2.1001394e-4,99.902,,,1.5890455e3,9.990,,,0.0049,0.0000,48,0.00,0.00,0.00,0.00,0.0001179,,400.0017395,,,,,-7.203270e-3,1.2780260,,
,35969051.78,5905,1.9024,0.801041,364.80991,1.1455306e-4,99.902,,,1.5853922e3,9.990,,,0.0049,0.0049,48,0.00,0.00,0.00,0.00,0.0001165,,400.0017395,,,,,0.126653,1.2803069,,
,35969099.75,5905,1.8978,0.801041,364.80991,-2.4819831e-4,99.902,,,1.5819813e3,9.990,,,0.0049,-0.0049,48,0.00,0.00,0.00,0.00,0.0001194,,400.0017395,,,,,-0.116698,1.2824473,,
,35969147.69,5905,1.8974,0.801041,364.80991,1.5273741e-4,99.902,,,1.5787443e3,9.990,,,0.0049,0.0049,48,0.00,0.00,0.00,0.00,0.0001194,,400.0017395,,,,,-0.139141,1.2844884,,
,35969195.91,5905,1.8966,0.801041,364.80991,9.5460884e-5,99.902,,,1.5758311e3,9.990,,,0.0000,0.0049,48,0.00,0.00,0.00,0.00,0.0001179,,400.0017395,,,,,-0.179229,1.2863336,,
,35969243.80,5905,1.8987,0.801041,364.80991,,99.902,,,1.5729796e3,9.990,,,0.0049,0.0000,48,0.00,0.00,0.00,0.00,0.0001208,,,,,,,-6.627407e-2,1.2881472,,
,35969291.75,5905,1.9000,0.801041,364.80991,2.2910612e-4,99.902,,,1.5703009e3,9.990,,,0.0049,-0.0049,48,0.00,0.00,0.00,0.00,0.0001165,,400.0017395,,,,,1.041502e-3,1.2898579,,
,35969339.66,5905,1.9003,0.801041,364.80991,1.9092176e-5,99.902,,,1.5678300e3,9.990,,,0.0000,0.0049,48,0.00,0.00,0.00,0.00,0.0001194,,400.0017395,,,,,1.519374e-2,1.2914416,,
,35969387.63,5905,1.9021,0.801041,364.80991,-1.9092176e-5,99.902,,,1.5655764e3,9.990,,,0.0049,-0.0049,48,0.00,0.00,0.00,0.00,0.0001194,,400.0017395,,,,,0.111224,1.2928911,,
,35969435.86,5905,1.9001,0.801041,364.80991,7.6368706e-5,99.902,,,1.5634059e3,9.990,,,0.0049,-0.0049,48,0.00,0.00,0.00,0.00,0.0001208,,400.0017395,,,,,5.063002e-3,1.2942919,,
,35969483.73,5905,1.8992,0.801041,364.80991,1.7182960e-4,99.902,,,1.5613898e3,9.990,,,0.0049,0.0049,48,0.00,0.00,0.00,0.00,0.0001179,,400.0017395,,,,,-4.142670e-2,1.2955968,,
,35969531.56,5905,1.9026,0.801041,364.80991,-1.9092177e-4,99.902,,,1.5594906e3,9.990,,,0.0049,0.0049,48,0.00,0.00,0.00,0.00,0.0001194,,400.0017395,,,,,0.135251,1.2968297,,
,35969579.64,5905,1.9023,0.801041,364.80991,3.4365919e-4,99.902,,,1.5577708e3,9.990,,,0.0049,0.0049,48,0.00,0.00,0.00,0.00,0.0001179,,400.0017395,,,,,0.121252,1.2979492,,
,35969627.55,5905,1.8978,0.801041,364.80991,3.8184353e-5,99.902,,,1.5561283e3,9.990,,,0.0049,-0.0049,48,0.00,0.00,0.00,0.00,0.0001194,,400.0017395,,,,,-0.116924,1.2990210,,
,35969675.83,5905,1.8993,0.801041,364.80991,3.0547482e-4,99.902,,,1.5544839e3,9.990,,,0.0098,0.0000,48,0.00,0.00,0.00,0.00,0.0001194,,400.0017395,,,,,-3.572535e-2,1.3000966,,
,35969723.66,5905,1.8982,0.801041,364.80991,3.4365919e-4,99.902,,,1.5530696e3,9.990,,,0.0049,0.0049,48,0.00,0.00,0.00,0.00,0.0001179,,400.0017395,,,,,-9.640140e-2,1.3010238,,
,35969771.59,5905,1.9022,0.801041,364.80991,3.0547482e-4,99.902,,,1.5517284e3,9.990,,,0.0000,-0.0049,48,0.00,0.00,0.00,0.00,0.0001179,,400.0017395,,,,,0.115274,1.3019049,,
,35969819.75,5905,1.9010,0.801041,364.80991,1.1455306e-4,99.902,,,1.5504965e3,9.990,,,0.0049,0.0000,48,0.00,0.00,0.00,0.00,0.0001194,,400.0017395,,,,,5.315163e-2,1.3027157,,
,35969867.70,5905,1.9000,0.801041,364.80991,2.8638265e-4,99.902,,,1.5491831e3,9.990,,,0.0049,0.0000,48,0.00,0.00,0.00,0.00,0.0001165,,400.0017395,,,,,2.126900e-3,1.3035817,,
,35969915.78,5905,1.9005,0.801041,364.80991,,99.902,,,1.5480321e3,9.990,,,0.0049,-0.0049,48,0.00,0.00,0.00,0.00,0.0001208,,,,,,,2.605612e-2,1.3043422,,
,35969963.67,5905,1.8990,0.801041,364.80991,3.2456699e-4,99.902,,,1.5469636e3,9.990,,,0.0049,0.0000,48,0.00,0.00,0.00,0.00,0.0001179,,400.0017395,,,,,-5.303232e-2,1.3050493,,
,35970011.75,5905,1.8994,0.801041,364.80991,2.2910612e-4,99.902,,,1.5459220e3,9.990,,,0.0049,0.0000,48,0.00,0.00,0.00,0.00,0.0001208,,400.0017395,,,,,-3.284353e-2,1.3057396,,
,35970059.78,5905,1.9011,0.801041,364.80991,5.1548879e-4,99.902,,,1.5448906e3,9.990,,,0.0049,0.0000,48,0.00,0.00,0.00,0.00,0.0001194,,400.0017395,,,,,5.608473e-2,1.3064243,,
,35970107.89,5905,1.9013,0.801041,364.80991,5.9185748e-4,99.902,,,1.5441085e3,9.990,,,0.0049,0.0000,48,0.00,0.00,0.00,0.00,0.0001179,,400.0017395,,,,,6.902470e-2,1.3069441,,
,35970155.59,5905,1.8975,0.801041,364.80991,2.1001394e-4,99.902,,,1.5432266e3,9.990,,,0.0049,-0.0049,48,0.00,0.00,0.00,0.00,0.0001179,,400.0017395,,,,,-0.131799,1.3075311,,
,35970203.59,5905,1.8983,0.801041,364.80991,-2.8638265e-4,99.902,,,1.5424913e3,9.990,,,0.0049,0.0000,48,0.00,0.00,0.00,0.00,0.0001194,,400.0017395,,,,,-8.726828e-2,1.3080211,,
,35970251.53,5905,1.8983,0.801041,364.80991,3.6275137e-4,99.902,,,1.5415531e3,9.990,,,0.0000,0.0000,48,0.00,0.00,0.00,0.00,0.0001165,,400.0017395,,,,,-8.726828e-2,1.3086470,,
,35970299.81,5905,1.8994,0.801041,364.80991,2.6729048e-4,99.902,,,1.5409801e3,9.990,,,0.0000,0.0000,48,0.00,0.00,0.00,0.00,0.0001165,,400.0017395,,,,,-2.995560e-2,1.3090298,,
,35970347.63,5905,1.8967,0.801041,364.80991,,99.902,,,1.5402604e3,9.990,,,0.0049,0.0000,48,0.00,0.00,0.00,0.00,0.0001194,,,,,,,-0.175463,1.3095109,,
,35970395.52,5905,1.9000,0.801041,364.80991,9.5460884e-5,99.902,,,1.5395919e3,9.990,,,0.0000,0.0000,48,0.00,0.00,0.00,0.00,0.0001208,,400.0017395,,,,,-1.311319e-3,1.3099583,,
,35970443.63,4881,1.9023,0.801041,364.80991,1.1455306e-4,99.902,,,1.5391005e3,9.990,,,0.0049,0.0049,48,0.00,0.00,0.00,0.00,0.0001208,,400.0017395,,,,,0.121928,1.3102876,,
,35970491.56,4881,1.8995,0.801041,364.80991,-1.3364524e-4,99.902,,,1.5384526e3,9.990,,,0.0000,0.0000,48,0.00,0.00,0.00,0.00,0.0001179,,400.0017395,,,,,-2.441877e-2,1.3107219,,
,35970539.69,4881,1.9013,0.801041,364.80991,2.1001394e-4,99.902,,,1.5378416e3,9.990,,,0.0049,-0.0049,48,0.00,0.00,0.00,0.00,0.0001179,,400.0017395,,,,,6.675027e-2,1.3111320,,
,35970587.69,4881,1.9003,0.801041,364.80991,-1.1455306e-4,99.902,,,1.5373488e3,9.990,,,0.0000,0.0000,48,0.00,0.00,0.00,0.00,0.0001208,,400.0017395,,,,,1.807890e-2,1.3114630,,
,35970635.92,4881,1.8993,0.801041,364.80991,3.2456699e-4,99.902,,,1.5368418e3,9.990,,,0.0049,0.0000,48,0.00,0.00,0.00,0.00,0.0001165,,400.0017395,,,,,-3.538631e-2,1.3118036,,
,35970683.53,4881,1.9003,0.801041,364.80991,2.4819831e-4,99.902,,,1.5363937e3,9.990,,,0.0049,0.0000,48,0.00,0.00,0.00,0.00,0.0001194,,400.0017395,,,,,1.366955e-2,1.3121051,,
,35970731.59,4882,1.9233,0.801041,364.80991,2.6729048e-4,99.902,,,1.5359238e3,9.990,,,0.0000,0.0049,304,0.00,0.00,0.00,0.00,0.0001194,,400.0017395,,,,,7.936881e-2,1.3124213,,
,35970779.67,4882,2.0050,0.801041,364.80991,-3.8184353e-5,99.902,,,1.5348065e3,9.990,,,0.0049,0.0000,304,0.00,0.00,0.00,0.00,0.0001194,,400.0017395,,,,,0.138569,1.3131742,,
,35970827.73,4882,2.0833,0.801041,364.80991,5.9185748e-4,99.902,,,1.5323348e3,9.990,,,0.0000,0.0000,304,0.00,0.00,0.00,0.00,0.0001179,,400.0017395,,,,,8.568124e-2,1.3148444,,
,35970875.92,4882,2.1643,0.801041,364.80991,2.6729048e-4,99.902,,,1.5274800e3,9.990,,,0.0049,0.0049,304,0.00,0.00,0.00,0.00,0.0001179,,400.0017395,,,,,8.233472e-2,1.3181431,,
,35970923.63,4882,2.2435,0.801041,364.80991,4.2002788e-4,99.902,,,1.5180527e3,9.990,,,0.0049,0.0000,304,0.00,0.00,0.00,0.00,0.0001208,,400.0017395,,,,,6.385805e-2,1.3246186,,
,35970971.83,4882,2.3218,0.801041,364.80991,4.5821225e-4,99.902,,,1.5059513e3,9.990,,,0.0049,0.0049,304,0.00,0.00,0.00,0.00,0.0001194,,400.0017395,,,,,5.750488e-3,1.3330692,,
,35971019.50,4882,2.4009,0.801041,364.80991,5.7276531e-5,99.902,,,1.4916755e3,9.990,,,0.0049,0.0049,304,0.00,0.00,0.00,0.00,0.0001179,,400.0017395,,,,,-2.192601e-2,1.3432438,,
,35971067.66,4882,2.4828,0.801041,364.80991,2.8638265e-4,99.902,,,1.4700812e3,9.990,,,0.0000,0.0000,304,0.00,0.00,0.00,0.00,0.0001194,,400.0017395,,,,,4.461412e-2,1.3590751,,
,35971115.72,4882,2.5629,0.801041,364.80991,2.6729048e-4,99.902,,,1.4485315e3,9.990,,,0.0049,0.0049,304,0.00,0.00,0.00,0.00,0.0001194,,400.0017395,,,,,3.567613e-2,1.3754283,,
,35971163.55,4882,2.6402,0.801041,364.80991,2.2910612e-4,99.902,,,1.4368187e3,9.990,,,0.0049,0.0000,304,0.00,0.00,0.00,0.00,0.0001194,,400.0017395,,,,,-6.826042e-2,1.3845603,,
,35971211.69,4882,2.7243,0.801041,364.80991,-1.1455306e-4,99.902,,,1.4270463e3,9.990,,,0.0049,0.0049,304,0.00,0.00,0.00,0.00,0.0001179,,400.0017395,,,,,9.883220e-2,1.3923159,,
,35971259.70,4882,2.8029,0.801041,364.80991,-2.4819831e-4,99.902,,,1.4194928e3,9.990,,,0.0049,0.0000,304,0.00,0.00,0.00,0.00,0.0001165,,400.0017395,,,,,4.560962e-2,1.3983976,,
,35971307.75,4882,2.8836,0.801041,364.80991,2.6729048e-4,99.902,,,1.4113507e3,9.990,,,0.0049,0.0000,304,0.00,0.00,0.00,0.00,0.0001179,,400.0017395,,,,,5.914966e-2,1.4050403,,
,35971355.64,4882,2.9631,0.801041,364.80991,6.1094965e-4,99.902,,,1.4036323e3,9.990,,,0.0049,0.0000,304,0.00,0.00,0.00,0.00,0.0001194,,400.0017395,,,,,6.467526e-2,1.4114223,,
,35971403.78,4882,3.0430,0.801041,364.80991,3.0547482e-4,99.902,,,1.3962349e3,9.990,,,0.0000,0.0000,304,0.00,0.00,0.00,0.00,0.0001208,,400.0017395,,,,,3.641671e-2,1.4176185,,
,35971451.58,4882,3.1223,0.801041,364.80991,-3.0547482e-4,99.902,,,1.3892201e3,9.990,,,0.0049,0.0000,304,0.00,0.00,0.00,0.00,0.0001194,,400.0017395,,,,,3.821072e-2,1.4235494,,
,35971499.48,4882,3.2033,0.801041,364.80991,1.5273741e-4,99.902,,,1.3823640e3,9.990,,,0.0049,0.0049,304,0.00,0.00,0.00,0.00,0.0001194,,400.0017395,,,,,4.051135e-2,1.4294112,,
,35971547.64,4882,3.2812,0.801041,364.80991,5.7276531e-5,99.902,,,1.3756886e3,9.990,,,0.0049,0.0000,304,0.00,0.00,0.00,0.00,0.0001179,,400.0017395,,,,,-5.449716e-4,1.4351847,,
,35971595.78,4882,3.3638,0.801041,364.80991,4.9639662e-4,99.902,,,1.3692874e3,9.990,,,0.0049,-0.0049,304,0.00,0.00,0.00,0.00,0.0001429,,400.0017395,,,,,5.674480e-2,1.4407836,,
,35971643.58,4882,3.4420,0.801041,364.80991,1.1455306e-4,99.902,,,1.3632269e3,9.990,,,0.0098,0.0000,304,0.00,0.00,0.00,0.00,0.0001795,,400.0017395,,,,,7.418618e-3,1.4461421,,
,35971691.48,4882,3.5217,0.801041,364.80991,7.6368706e-5,99.902,,,1.3575837e3,9.990,,,0.0000,0.0049,304,0.00,0.00,0.00,0.00,0.0002099,,400.0017395,,,,,1.831262e-2,1.4511825,,
,35971739.66,4882,3.6032,0.801041,364.80991,5.5367313e-4,99.902,,,1.3520242e3,9.990,,,0.0049,0.0049,304,0.00,0.00,0.00,0.00,0.0002283,,400.0017395,,,,,2.724803e-2,1.4561971,,
,35971788.05,4882,3.6830,0.801041,364.80991,2.2910612e-4,99.902,,,1.3465936e3,9.990,,,0.0049,0.0000,304,0.00,0.00,0.00,0.00,0.0002800,,400.0017395,,,,,2.570613e-2,1.4611431,,
,35971835.88,4882,3.7645,0.801041,364.80991,,99.902,,,1.3413386e3,9.990,,,0.0000,0.0000,304,0.00,0.00,0.00,0.00,0.0003691,,,,,,,5.165457e-2,1.4659748,,
,35971883.72,4882,3.8361,0.801041,364.80991,2.8638265e-4,99.902,,,1.3358892e3,9.990,,,0.0049,0.0000,304,0.00,0.00,0.00,0.00,0.0004750,,400.0017395,,,,,-0.149772,1.4710331,,
,35971931.56,4882,3.9220,0.801041,364.80991,1.1455306e-4,99.902,,,1.3307615e3,9.990,,,0.0049,-0.0049,304,0.00,0.00,0.00,0.00,0.0005896,,400.0017395,,,,,3.276582e-3,1.4758384,,
,35971979.63,4882,4.0063,0.801041,364.80991,4.2002788e-4,99.902,,,1.3259678e3,9.990,,,0.0049,-0.0049,304,0.00,0.00,0.00,0.00,0.0007254,,400.0017395,,,,,0.126389,1.4803709,,
,35972027.86,4882,4.0767,0.801041,364.80991,8.4005576e-4,99.902,,,1.3213590e3,9.990,,,0.0098,-0.0049,304,0.00,0.00,0.00,0.00,0.0009234,,400.0017395,,,,,-0.123165,1.4847656,,
,35972075.83,4882,4.1608,0.801041,364.80991,5.7276531e-5,99.902,,,1.3165785e3,9.990,,,0.0049,-0.0049,48,0.00,0.00,0.00,0.00,0.0009945,,400.0017395,,,,,-3.435773e-2,1.4893636,,
,35972123.84,4882,4.2511,0.801041,364.80991,,99.902,,,1.3119180e3,9.990,,,0.0000,-0.0049,48,0.00,0.00,0.00,0.00,0.0011194,,,,,,,0.208687,1.4938850,,
,35972171.92,4882,4.3137,0.801041,364.80991,-1.3364524e-4,99.902,,,1.3080220e3,9.990,,,0.0000,0.0000,48,0.00,0.00,0.00,0.00,0.0013071,,400.0017395,,,,,-0.200146,1.4976946,,
,35972219.47,4886,4.3793,0.801041,364.80991,8.5914799e-4,99.902,,,1.3142670e3,9.990,,,0.0049,-0.0049,48,0.00,0.00,0.00,0.00,0.0012482,,400.0017395,,,,,-0.247583,1.4916013,,
,35972267.89,4886,4.5149,0.801041,364.80991,4.7730442e-4,99.902,,,1.2963688e3,9.990,,,0.0049,0.0049,48,0.00,0.00,0.00,0.00,0.0018437,,400.0017395,,,,,0.972479,1.5092551,,
,35972315.81,4882,4.5584,0.801041,364.80991,3.0547482e-4,99.902,,,1.2966362e3,9.990,,,0.0049,-0.0049,48,0.00,0.00,0.00,0.00,0.0018982,,400.0017395,,,,,0.152369,1.5089871,,
,35972363.64,4882,4.6327,0.801041,364.80991,7.0641056e-4,99.902,,,1.2932688e3,9.990,,,0.0049,0.0000,48,0.00,0.00,0.00,0.00,0.0020699,,400.0017395,,,,,4.158270e-2,1.5123731,,
,35972411.64,4882,4.7106,0.801041,364.80991,2.4819831e-4,99.902,,,1.2896975e3,9.990,,,0.0000,-0.0049,48,0.00,0.00,0.00,0.00,0.0023191,,400.0017395,,,,,-1.527517e-2,1.5159878,,
,35972459.73,4882,4.7917,0.801041,364.80991,3.6275137e-4,99.902,,,1.2861979e3,9.990,,,0.0049,0.0000,48,0.00,0.00,0.00,0.00,0.0026294,,400.0017395,,,,,2.239057e-2,1.5195535,,
,35972507.69,4882,4.8720,0.801041,364.80991,5.5367313e-4,99.902,,,1.2828066e3,9.990,,,0.0049,0.0049,48,0.00,0.00,0.00,0.00,0.0028946,,400.0017395,,,,,2.368533e-2,1.5230316,,
,35972555.55,4882,4.9515,0.801041,364.80991,-3.8184353e-5,99.902,,,1.2794030e3,9.990,,,0.0049,0.0000,48,0.00,0.00,0.00,0.00,0.0032200,,400.0017395,,,,,1.689145e-2,1.5265450,,
,35972603.50,4882,5.0323,0.801041,364.80991,5.7276531e-5,99.902,,,1.2762489e3,9.990,,,0.0000,0.0000,48,0.00,0.00,0.00,0.00,0.0035769,,400.0017395,,,,,4.604179e-2,1.5298214,,
,35972651.58,4882,5.1129,0.801041,364.80991,1.3364524e-4,99.902,,,1.2732028e3,9.990,,,0.0098,0.0000,48,0.00,0.00,0.00,0.00,0.0038692,,400.0017395,,,,,4.872901e-2,1.5330045,,
,35972699.67,4882,5.1918,0.801041,364.80991,2.2910612e-4,99.902,,,1.2700978e3,9.990,,,0.0049,0.0000,48,0.00,0.00,0.00,0.00,0.0043504,,400.0017395,,,,,1.314297e-2,1.5362684,,
,35972747.77,4882,5.2731,0.801041,364.80991,4.3912008e-4,99.902,,,1.2670116e3,9.990,,,0.0049,0.0000,48,0.00,0.00,0.00,0.00,0.0049502,,400.0017395,,,,,4.239260e-2,1.5395318,,
,35972795.59,4882,5.3524,0.801041,364.80991,2.1001394e-4,99.902,,,1.2640403e3,9.990,,,0.0049,-0.0049,48,0.00,0.00,0.00,0.00,0.0054765,,400.0017395,,,,,3.217880e-2,1.5426924,,
,35972843.70,4882,5.4321,0.801041,364.80991,1.9092176e-5,99.902,,,1.2612283e3,9.990,,,0.0000,0.0000,48,0.00,0.00,0.00,0.00,0.0059708,,400.0017395,,,,,2.634333e-2,1.5457006,,
,35972891.56,4882,5.5117,0.801041,364.80991,6.6822622e-4,99.902,,,1.2583541e3,9.990,,,0.0049,0.0049,48,0.00,0.00,0.00,0.00,0.0068240,,400.0017395,,,,,2.325484e-2,1.5487922,,
,35972939.45,4882,5.5924,0.801041,364.80991,-1.9092177e-4,99.902,,,1.2555026e3,9.990,,,0.0000,0.0049,48,0.00,0.00,0.00,0.00,0.0072629,,400.0017395,,,,,3.896627e-2,1.5518768,,
,35972987.86,4882,5.6709,0.801041,364.80991,3.4365919e-4,99.902,,,1.2528013e3,9.990,,,0.0049,-0.0049,48,0.00,0.00,0.00,0.00,0.0076342,,400.0017395,,,,,-1.145240e-2,1.5548149,,
,35973035.59,4882,5.7528,0.801041,364.80991,1.3364524e-4,99.902,,,1.2501705e3,9.990,,,0.0049,0.0049,304,0.00,0.00,0.00,0.00,0.0078495,,400.0017395,,,,,3.291493e-2,1.5576913,,
,35973083.61,4882,5.8320,0.801041,364.80991,1.7182960e-4,99.902,,,1.2475626e3,9.990,,,0.0000,0.0049,304,0.00,0.00,0.00,0.00,0.0083054,,400.0017395,,,,,2.750465e-2,1.5605577,,
,35973131.75,4882,5.9119,0.801041,364.80991,1.9092176e-5,99.902,,,1.2449271e3,9.990,,,0.0049,0.0000,304,0.00,0.00,0.00,0.00,0.0085348,,400.0017395,,,,,1.259866e-2,1.5634694,,
,35973179.73,4882,5.9911,0.801041,364.80991,5.7276531e-5,99.902,,,1.2425172e3,9.990,,,0.0000,0.0049,48,0.00,0.00,0.00,0.00,0.0087378,,400.0017395,,,,,-9.948842e-4,1.5661454,,
,35973227.69,4882,6.0736,0.801041,364.80991,9.5460884e-5,99.902,,,1.2400573e3,9.990,,,0.0049,-0.0049,48,0.00,0.00,0.00,0.00,0.0089181,,400.0017395,,,,,4.688606e-2,1.5688903,,
,35973275.64,4882,6.1521,0.801041,364.80991,1.1455306e-4,99.902,,,1.2376700e3,9.990,,,0.0049,0.0000,48,0.00,0.00,0.00,0.00,0.0090110,,400.0017395,,,,,2.205093e-2,1.5715669,,
,35973323.55,4882,6.2318,0.801041,364.80991,1.9092177e-4,99.902,,,1.2354452e3,9.990,,,0.0000,0.0049,48,0.00,0.00,0.00,0.00,0.0090294,,400.0017395,,,,,1.920584e-2,1.5740733,,
,35973371.53,4882,6.3106,0.801041,364.80991,3.4365919e-4,99.902,,,1.2330543e3,9.990,,,0.0000,0.0049,48,0.00,0.00,0.00,0.00,0.0090744,,400.0017395,,,,,4.866128e-3,1.5767790,,
,35973419.58,4882,6.3920,0.801041,364.80991,2.4819831e-4,99.902,,,1.2308861e3,9.990,,,0.0000,0.0000,48,0.00,0.00,0.00,0.00,0.0090979,,400.0017395,,,,,1.656086e-2,1.5792520,,
,35973467.95,4882,6.4728,0.801041,364.80991,2.1001394e-4,99.902,,,1.2287140e3,9.990,,,0.0049,0.0000,48,0.00,0.00,0.00,0.00,0.0091250,,400.0017395,,,,,3.032921e-2,1.5817410,,
,35973515.52,4882,6.5518,0.801041,364.80991,9.5460884e-5,99.902,,,1.2265000e3,9.990,,,0.0049,0.0000,48,0.00,0.00,0.00,0.00,0.0091906,,400.0017395,,,,,1.564749e-2,1.5842897,,
,35973563.67,4882,6.6319,0.801041,364.80991,5.7276531e-5,99.902,,,1.2243514e3,9.990,,,0.0049,0.0000,48,0.00,0.00,0.00,0.00,0.0092299,,400.0017395,,,,,1.873741e-2,1.5867742,,
,35973611.69,4882,6.7120,0.801041,364.80991,2.1001394e-4,99.902,,,1.2222698e3,9.990,,,0.0000,0.0049,48,0.00,0.00,0.00,0.00,0.0092979,,400.0017395,,,,,2.392701e-2,1.5891923,,
,35973659.50,4882,6.7905,0.801041,364.80991,1.3364524e-4,99.902,,,1.2201978e3,9.990,,,0.0000,0.0000,48,0.00,0.00,0.00,0.00,0.0094079,,400.0017395,,,,,-5.666874e-3,1.5916095,,
,35973707.67,4882,6.8727,0.801041,364.80991,1.9092177e-4,99.902,,,1.2182572e3,9.990,,,0.0049,0.0049,48,0.00,0.00,0.00,0.00,0.0094394,,400.0017395,,,,,3.095081e-2,1.5938830,,
,35973755.72,4882,6.9518,0.801041,364.80991,,99.902,,,1.2162789e3,9.990,,,0.0000,-0.0049,48,0.00,0.00,0.00,0.00,0.0096252,,,,,,,1.916468e-2,1.5962104,,
,35973803.55,4882,7.0311,0.801041,364.80991,3.8184353e-5,99.902,,,1.2143977e3,9.990,,,0.0000,0.0000,48,0.00,0.00,0.00,0.00,0.0097151,,400.0017395,,,,,1.274299e-2,1.5984325,,
,35973851.64,4882,7.1120,0.801041,364.80991,-3.8184353e-5,99.902,,,1.2124764e3,9.990,,,0.0049,0.0000,48,0.00,0.00,0.00,0.00,0.0098707,,400.0017395,,,,,1.845118e-2,1.6007112,,
,35973899.52,4882,7.1919,0.801041,364.80991,3.8184354e-4,99.902,,,1.2106431e3,9.990,,,0.0049,-0.0049,48,0.00,0.00,0.00,0.00,0.0101312,,400.0017395,,,,,1.869062e-2,1.6028943,,
,35973947.55,4882,7.2715,0.801041,364.80991,2.6729048e-4,99.902,,,1.2088956e3,9.990,,,0.0049,0.0000,48,0.00,0.00,0.00,0.00,0.0101312,,400.0017395,,,,,7.292059e-3,1.6049830,,
,35973995.53,4882,7.3511,0.801041,364.80991,4.2002788e-4,99.902,,,1.2070565e3,9.990,,,0.0049,0.0000,48,0.00,0.00,0.00,0.00,0.0106018,,400.0017395,,,,,4.294130e-3,1.6071898,,
,35974043.47,4882,7.4307,0.801041,364.80991,1.5273741e-4,99.902,,,1.2052709e3,9.990,,,0.0049,-0.0049,48,0.00,0.00,0.00,0.00,0.0107630,,400.0017395,,,,,1.049840e-2,1.6093408,,
,35974091.52,4882,7.5123,0.801041,364.80991,2.8638265e-4,99.902,,,1.2035732e3,9.990,,,0.0049,0.0000,48,0.00,0.00,0.00,0.00,0.0109263,,400.0017395,,,,,2.545948e-2,1.6113933,,
,35974139.56,4882,7.5911,0.801041,364.80991,1.1455306e-4,99.902,,,1.2018677e3,9.990,,,0.0049,0.0049,48,0.00,0.00,0.00,0.00,0.0114297,,400.0017395,,,,,2.581716e-3,1.6134630,,
,35974187.48,4882,7.6713,0.801041,364.80991,4.2002788e-4,99.902,,,1.2002635e3,9.990,,,0.0049,0.0000,48,0.00,0.00,0.00,0.00,0.0112596,,400.0017395,,,,,4.966481e-3,1.6154166,,
,35974235.55,4882,7.7511,0.801041,364.80991,2.2910612e-4,99.902,,,1.1985695e3,9.990,,,0.0049,0.0000,48,0.00,0.00,0.00,0.00,0.0117767,,400.0017395,,,,,1.356488e-2,1.6174872,,
,35974283.53,4882,7.8316,0.801041,364.80991,3.0547482e-4,99.902,,,1.1969844e3,9.990,,,0.0049,0.0000,48,0.00,0.00,0.00,0.00,0.0119537,,400.0017395,,,,,1.710295e-2,1.6194315,,
,35974331.58,4882,7.9107,0.801041,364.80991,3.6275137e-4,99.902,,,1.1953231e3,9.990,,,0.0000,0.0000,48,0.00,0.00,0.00,0.00,0.0124990,,400.0017395,,,,,-4.942760e-4,1.6214763,,
,35974379.56,4882,7.9914,0.801041,364.80991,4.7730442e-4,99.902,,,1.1939135e3,9.990,,,0.0000,-0.0049,48,0.00,0.00,0.00,0.00,0.0124990,,400.0017395,,,,,1.198743e-2,1.6232173,,
,35974427.64,4882,8.0718,0.801041,364.80991,1.5273741e-4,99.902,,,1.1923093e3,9.990,,,0.0000,0.0049,48,0.00,0.00,0.00,0.00,0.0130666,,400.0017395,,,,,1.876208e-2,1.6252049,,
,35974475.86,4882,8.1524,0.801041,364.80991,3.6275137e-4,99.902,,,1.1907336e3,9.990,,,0.0098,0.0049,48,0.00,0.00,0.00,0.00,0.0132679,,400.0017395,,,,,1.790966e-2,1.6271641,,
,35974523.56,4882,8.2315,0.801041,364.80991,-3.8184354e-4,99.902,,,1.1893014e3,9.990,,,0.0049,-0.0049,48,0.00,0.00,0.00,0.00,0.0140935,,400.0017395,,,,,1.668338e-2,1.6289508,,
,35974571.58,4882,8.3113,0.801041,364.80991,4.3912008e-4,99.902,,,1.1878595e3,9.990,,,0.0049,0.0000,48,0.00,0.00,0.00,0.00,0.0143022,,400.0017395,,,,,1.166944e-2,1.6307553,,
,35974619.52,4882,8.3919,0.801041,364.80991,4.7730442e-4,99.902,,,1.1864686e3,9.990,,,0.0049,0.0049,48,0.00,0.00,0.00,0.00,0.0145127,,400.0017395,,,,,1.766002e-2,1.6325014,,
,35974667.44,4882,8.4705,0.801041,364.80991,7.8277930e-4,99.902,,,1.1850178e3,9.990,,,0.0098,-0.0049,48,0.00,0.00,0.00,0.00,0.0151570,,400.0017395,,,,,-1.283496e-3,1.6343282,,
,35974715.48,4882,8.5515,0.801041,364.80991,3.8184354e-4,99.902,,,1.1835946e3,9.990,,,0.0000,0.0000,48,0.00,0.00,0.00,0.00,0.0153765,,400.0017395,,,,,9.089034e-3,1.6361262,,
,35974763.45,4882,8.6312,0.801041,364.80991,9.5460884e-5,99.902,,,1.1822388e3,9.990,,,0.0000,0.0049,48,0.00,0.00,0.00,0.00,0.0158233,,400.0017395,,,,,1.038624e-2,1.6378443,,
,35974811.50,4882,8.7116,0.801041,364.80991,1.1455306e-4,99.902,,,1.1809093e3,9.990,,,0.0000,0.0000,48,0.00,0.00,0.00,0.00,0.0162810,,400.0017395,,,,,1.461450e-2,1.6395339,,
,35974859.53,4882,8.7918,0.801041,364.80991,3.2456699e-4,99.902,,,1.1794734e3,9.990,,,0.0049,0.0049,48,0.00,0.00,0.00,0.00,0.0169892,,400.0017395,,,,,1.175848e-2,1.6413645,,
,35974907.52,4882,8.8717,0.801041,364.80991,3.8184353e-5,99.902,,,1.1782000e3,9.990,,,0.0049,0.0000,48,0.00,0.00,0.00,0.00,0.0169892,,400.0017395,,,,,1.511394e-2,1.6429930,,
,35974955.45,4882,8.9519,0.801041,364.80991,1.9092177e-4,99.902,,,1.1768822e3,9.990,,,0.0000,-0.0049,48,0.00,0.00,0.00,0.00,0.0177313,,400.0017395,,,,,1.884578e-2,1.6446828,,
,35975003.55,4882,9.0321,0.801041,364.80991,2.8638265e-4,99.902,,,1.1756302e3,9.990,,,0.0049,-0.0049,48,0.00,0.00,0.00,0.00,0.0179868,,400.0017395,,,,,2.352473e-2,1.6462928,,
,35975051.55,4882,9.1117,0.801041,364.80991,3.8184353e-5,99.902,,,1.1743400e3,9.990,,,0.0000,0.0000,48,0.00,0.00,0.00,0.00,0.0185078,,400.0017395,,,,,6.091487e-3,1.6479570,,
,35975099.42,4882,9.1907,0.801041,364.80991,1.3364524e-4,99.902,,,1.1732131e3,9.990,,,0.0049,-0.0049,48,0.00,0.00,0.00,0.00,0.0190421,,400.0017395,,,,,7.398431e-3,1.6494142,,
,35975147.48,4882,9.2712,0.801041,364.80991,2.2910612e-4,99.902,,,1.1719543e3,9.990,,,0.0049,-0.0049,48,0.00,0.00,0.00,0.00,0.0193144,,400.0017395,,,,,4.927194e-3,1.6510465,,
,35975195.58,4882,9.3518,0.801041,364.80991,5.1548879e-4,99.902,,,1.1707893e3,9.990,,,0.0049,0.0049,48,0.00,0.00,0.00,0.00,0.0198693,,400.0017395,,,,,1.298176e-2,1.6525613,,
,35975243.44,4882,9.4315,0.801041,364.80991,1.3364524e-4,99.902,,,1.1695455e3,9.990,,,0.0049,0.0049,48,0.00,0.00,0.00,0.00,0.0198693,,400.0017395,,,,,6.956765e-3,1.6541829,,
,35975291.59,4882,9.5120,0.801041,364.80991,2.4819831e-4,99.902,,,1.1683352e3,9.990,,,0.0000,-0.0049,48,0.00,0.00,0.00,0.00,0.0210221,,400.0017395,,,,,1.334469e-2,1.6557653,,
,35975339.67,4882,9.5916,0.801041,364.80991,1.7182960e-4,99.902,,,1.1672284e3,9.990,,,0.0049,-0.0049,48,0.00,0.00,0.00,0.00,0.0207285,,400.0017395,,,,,4.384771e-3,1.6572161,,
,35975387.72,4882,9.6720,0.801041,364.80991,3.2456699e-4,99.902,,,1.1660332e3,9.990,,,0.0049,-0.0049,48,0.00,0.00,0.00,0.00,0.0219254,,400.0017395,,,,,7.404993e-3,1.6587868,,
,35975435.61,4882,9.7520,0.801041,364.80991,,99.902,,,1.1649351e3,9.990,,,0.0049,0.0000,48,0.00,0.00,0.00,0.00,0.0225467,,,,,,,1.153955e-2,1.6602336,,
,35975483.45,4882,9.8320,0.801041,364.80991,-9.5460884e-5,99.902,,,1.1638250e3,9.990,,,0.0049,0.0049,48,0.00,0.00,0.00,0.00,0.0231837,,400.0017395,,,,,1.997177e-2,1.6617001,,
,35975531.63,4882,9.9120,0.801041,364.80991,1.9092177e-4,99.902,,,1.1627444e3,9.990,,,0.0049,0.0049,48,0.00,0.00,0.00,0.00,0.0235081,,400.0017395,,,,,8.033919e-3,1.6631310,,
,35975579.48,4882,9.9910,0.801041,364.80991,1.5273741e-4,99.902,,,1.1617368e3,9.990,,,0.0000,0.0049,48,0.00,0.00,0.00,0.00,0.0238366,,400.0017395,,,,,2.739510e-3,1.6644685,,
,35975627.52,4882,10.0718,0.801041,364.80991,4.5821225e-4,99.902,,,1.1606619e3,9.990,,,0.0049,0.0049,48,0.00,0.00,0.00,0.00,0.0235081,,400.0017395,,,,,1.272599e-2,1.6658987,,
,35975675.52,4882,10.1514,0.801041,364.80991,-2.2910612e-4,99.902,,,1.1595923e3,9.990,,,0.0098,-0.0049,48,0.00,0.00,0.00,0.00,0.0238366,,400.0017395,,,,,3.964485e-3,1.6673253,,
,35975723.75,4882,10.2322,0.801041,364.80991,-7.6368706e-5,99.902,,,1.1584886e3,9.990,,,0.0049,0.0049,48,0.00,0.00,0.00,0.00,0.0241692,,400.0017395,,,,,7.428290e-3,1.6688011,,
,35975771.64,4882,10.3130,0.801041,364.80991,9.5460884e-5,99.902,,,1.1574382e3,9.990,,,0.0049,-0.0049,48,0.00,0.00,0.00,0.00,0.0248469,,400.0017395,,,,,1.901243e-2,1.6702089,,
,35975819.52,4882,10.3920,0.801041,364.80991,3.6275137e-4,99.902,,,1.1565216e3,9.990,,,0.0049,0.0000,48,0.00,0.00,0.00,0.00,0.0251920,,400.0017395,,,,,7.332400e-3,1.6714405,,
,35975867.52,4882,10.4723,0.801041,364.80991,2.6729048e-4,99.902,,,1.1553783e3,9.990,,,0.0049,0.0000,48,0.00,0.00,0.00,0.00,0.0255414,,400.0017395,,,,,9.334330e-3,1.6729801,,
,35975915.45,4882,10.5517,0.801041,364.80991,7.4459496e-4,99.902,,,1.1544998e3,9.990,,,0.0000,0.0049,48,0.00,0.00,0.00,0.00,0.0255414,,400.0017395,,,,,1.150556e-2,1.6741658,,
,35975963.59,4882,10.6320,0.801041,364.80991,2.2910612e-4,99.902,,,1.1534674e3,9.990,,,0.0000,0.0049,48,0.00,0.00,0.00,0.00,0.0251920,,400.0017395,,,,,9.839944e-3,1.6755624,,
,35976011.47,4882,10.7123,0.801041,364.80991,6.8731839e-4,99.902,,,1.1525371e3,9.990,,,0.0049,0.0000,48,0.00,0.00,0.00,0.00,0.0262533,,400.0017395,,,,,8.929277e-3,1.6768237,,
,35976059.48,4882,10.7921,0.801041,364.80991,3.4365919e-4,99.902,,,1.1515927e3,9.990,,,0.0049,0.0000,48,0.00,0.00,0.00,0.00,0.0266159,,400.0017395,,,,,8.801394e-3,1.6781069,,
,35976107.44,4882,10.8721,0.801041,364.80991,1.9092177e-4,99.902,,,1.1506438e3,9.990,,,0.0049,0.0000,48,0.00,0.00,0.00,0.00,0.0269829,,400.0017395,,,,,1.157877e-2,1.6793990,,
,35976155.59,4882,10.9527,0.801041,364.80991,2.2910612e-4,99.902,,,1.1497844e3,9.990,,,0.0049,0.0049,48,0.00,0.00,0.00,0.00,0.0273544,,400.0017395,,,,,1.658729e-2,1.6805718,,
,35976203.44,4882,11.0310,0.801041,364.80991,2.6729048e-4,99.902,,,1.1487528e3,9.990,,,0.0000,0.0000,48,0.00,0.00,0.00,0.00,0.0273544,,400.0017395,,,,,-3.077760e-3,1.6819825,,
,35976251.58,4882,11.1118,0.801041,364.80991,5.7276531e-5,99.902,,,1.1479139e3,9.990,,,0.0000,-0.0049,48,0.00,0.00,0.00,0.00,0.0273544,,400.0017395,,,,,5.853285e-3,1.6831323,,
,35976299.59,4882,11.1927,0.801041,364.80991,5.5367313e-4,99.902,,,1.1469509e3,9.990,,,0.0049,0.0000,48,0.00,0.00,0.00,0.00,0.0273544,,400.0017395,,,,,1.933308e-2,1.6844548,,
,35976347.44,4882,11.2712,0.801041,364.80991,-5.7276531e-5,99.902,,,1.1462128e3,9.990,,,0.0098,-0.0049,48,0.00,0.00,0.00,0.00,0.0284967,,400.0017395,,,,,5.838214e-3,1.6854706,,
,35976395.55,4882,11.3521,0.801041,364.80991,4.3912008e-4,99.902,,,1.1453248e3,9.990,,,0.0049,0.0000,48,0.00,0.00,0.00,0.00,0.0284967,,400.0017395,,,,,1.027422e-2,1.6866949,,
,35976443.59,4882,11.4321,0.801041,364.80991,5.7276530e-4,99.902,,,1.1443632e3,9.990,,,0.0000,0.0000,48,0.00,0.00,0.00,0.00,0.0288868,,400.0017395,,,,,5.939537e-3,1.6880236,,
,35976491.70,4882,11.5126,0.801041,364.80991,3.6275137e-4,99.902,,,1.1435787e3,9.990,,,0.0049,-0.0049,48,0.00,0.00,0.00,0.00,0.0288868,,400.0017395,,,,,1.141502e-2,1.6891097,,
,35976539.44,4882,11.5917,0.801041,364.80991,3.8184353e-5,99.902,,,1.1426675e3,9.990,,,0.0049,0.0000,48,0.00,0.00,0.00,0.00,0.0296814,,400.0017395,,,,,5.429962e-3,1.6903739,,
,35976587.55,4882,11.6717,0.801041,364.80991,1.5273741e-4,99.902,,,1.1418423e3,9.990,,,0.0049,0.0049,48,0.00,0.00,0.00,0.00,0.0300844,,400.0017395,,,,,3.055887e-3,1.6915210,,
,35976635.64,4882,11.7524,0.801041,364.80991,-5.7276531e-5,99.902,,,1.1410020e3,9.990,,,0.0049,0.0000,48,0.00,0.00,0.00,0.00,0.0292817,,400.0017395,,,,,6.743336e-3,1.6926914,,
,35976683.63,4882,11.8319,0.801041,364.80991,4.0093571e-4,99.902,,,1.1403130e3,9.990,,,0.0049,-0.0049,48,0.00,0.00,0.00,0.00,0.0300844,,400.0017395,,,,,2.393883e-3,1.6936529,,
,35976731.84,4882,11.9126,0.801041,364.80991,3.4365919e-4,99.902,,,1.1395027e3,9.990,,,0.0098,0.0000,48,0.00,0.00,0.00,0.00,0.0296814,,400.0017395,,,,,1.003904e-2,1.6947854,,
,35976779.45,4882,11.9922,0.801041,364.80991,5.7276531e-5,99.902,,,1.1385942e3,9.990,,,0.0049,0.0000,48,0.00,0.00,0.00,0.00,0.0304863,,400.0017395,,,,,1.008375e-2,1.6960579,,
,35976827.39,4882,12.0700,0.801041,364.80991,2.1001394e-4,99.902,,,1.1378114e3,9.990,,,0.0049,0.0049,48,0.00,0.00,0.00,0.00,0.0308934,,400.0017395,,,,,-1.198613e-2,1.6971565,,
,35976875.72,4882,12.1540,0.801041,364.80991,5.7276530e-4,99.902,,,1.1370649e3,9.990,,,0.0049,0.0049,48,0.00,0.00,0.00,0.00,0.0313059,,400.0017395,,,,,2.477949e-2,1.6982061,,
,35976923.45,4882,12.2315,0.801041,364.80991,2.2910612e-4,99.902,,,1.1362577e3,9.990,,,0.0000,0.0000,48,0.00,0.00,0.00,0.00,0.0313059,,400.0017395,,,,,2.728906e-4,1.6993431,,
,35976971.42,4882,12.3125,0.801041,364.80991,3.0547482e-4,99.902,,,1.1355848e3,9.990,,,0.0049,-0.0049,48,0.00,0.00,0.00,0.00,0.0313059,,400.0017395,,,,,1.013122e-2,1.7002925,,
,35977019.38,4882,12.3917,0.801041,364.80991,4.7730442e-4,99.902,,,1.1348086e3,9.990,,,0.0049,0.0000,48,0.00,0.00,0.00,0.00,0.0313059,,400.0017395,,,,,5.294906e-3,1.7013897,,
,35977067.45,4882,12.4724,0.801041,364.80991,3.6275137e-4,99.902,,,1.1341116e3,9.990,,,0.0049,0.0000,48,0.00,0.00,0.00,0.00,0.0308934,,400.0017395,,,,,7.065179e-3,1.7023766,,
,35977115.73,4882,12.5522,0.801041,364.80991,5.7276531e-5,99.902,,,1.1333356e3,9.990,,,0.0000,0.0049,48,0.00,0.00,0.00,0.00,0.0321470,,400.0017395,,,,,1.853838e-3,1.7034771,,
,35977163.56,4882,12.6325,0.801041,364.80991,2.6729048e-4,99.902,,,1.1326041e3,9.990,,,0.0049,0.0000,48,0.00,0.00,0.00,0.00,0.0321470,,400.0017395,,,,,8.523211e-3,1.7045165,,
,35977211.70,4882,12.7120,0.801041,364.80991,2.6729048e-4,99.902,,,1.1318497e3,9.990,,,0.0000,-0.0049,48,0.00,0.00,0.00,0.00,0.0325758,,400.0017395,,,,,1.177834e-3,1.7055904,,
,35977259.45,4882,12.7918,0.801041,364.80991,-3.8184353e-5,99.902,,,1.1311609e3,9.990,,,0.0049,-0.0049,48,0.00,0.00,0.00,0.00,0.0325758,,400.0017395,,,,,2.706301e-3,1.7065727,,
,35977307.36,4882,12.8728,0.801041,364.80991,3.4365919e-4,99.902,,,1.1304255e3,9.990,,,0.0049,0.0000,48,0.00,0.00,0.00,0.00,0.0325758,,400.0017395,,,,,1.020147e-2,1.7076230,,
,35977355.44,4882,12.9530,0.801041,364.80991,1.1455306e-4,99.902,,,1.1297135e3,9.990,,,0.0049,0.0049,48,0.00,0.00,0.00,0.00,0.0334502,,400.0017395,,,,,1.553504e-2,1.7086418,,
,35977403.50,4882,13.0322,0.801041,364.80991,2.4819831e-4,99.902,,,1.1290942e3,9.990,,,0.0049,0.0000,48,0.00,0.00,0.00,0.00,0.0321470,,400.0017395,,,,,5.715242e-3,1.7095292,,
,35977451.67,4882,13.1121,0.801041,364.80991,7.4459496e-4,99.902,,,1.1283308e3,9.990,,,0.0049,0.0049,48,0.00,0.00,0.00,0.00,0.0334502,,400.0017395,,,,,1.803758e-3,1.7106249,,
,35977499.70,4882,13.1930,0.801041,364.80991,4.5821225e-4,99.902,,,1.1276062e3,9.990,,,0.0049,0.0000,48,0.00,0.00,0.00,0.00,0.0334502,,400.0017395,,,,,6.086534e-3,1.7116669,,
,35977547.55,4882,13.2724,0.801041,364.80991,2.1001394e-4,99.902,,,1.1269951e3,9.990,,,0.0049,0.0000,48,0.00,0.00,0.00,0.00,0.0343476,,400.0017395,,,,,8.392526e-3,1.7125471,,
,35977595.44,4882,13.3522,0.801041,364.80991,4.0093571e-4,99.902,,,1.1262162e3,9.990,,,0.0000,0.0049,48,0.00,0.00,0.00,0.00,0.0338960,,400.0017395,,,,,7.985254e-3,1.7136708,,
,35977643.45,4882,13.4337,0.801041,364.80991,3.0547482e-4,99.902,,,1.1256676e3,9.990,,,0.0049,0.0000,48,0.00,0.00,0.00,0.00,0.0343476,,400.0017395,,,,,1.566065e-2,1.7144635,,
,35977691.36,4882,13.5131,0.801041,364.80991,2.6729048e-4,99.902,,,1.1250208e3,9.990,,,0.0000,0.0000,48,0.00,0.00,0.00,0.00,0.0343476,,400.0017395,,,,,9.033497e-3,1.7153996,,
,35977739.52,4882,13.5926,0.801041,364.80991,2.6729048e-4,99.902,,,1.1242880e3,9.990,,,0.0049,0.0000,48,0.00,0.00,0.00,0.00,0.0348049,,400.0017395,,,,,8.321139e-3,1.7164618,,
,35977787.52,4882,13.6734,0.801041,364.80991,-1.5273741e-4,99.902,,,1.1236674e3,9.990,,,0.0049,0.0000,48,0.00,0.00,0.00,0.00,0.0348049,,400.0017395,,,,,1.610447e-2,1.7173628,,
,35977835.73,4882,13.7525,0.801041,364.80991,5.7276530e-4,99.902,,,1.1230674e3,9.990,,,0.0000,-0.0049,48,0.00,0.00,0.00,0.00,0.0352683,,400.0017395,,,,,1.227412e-3,1.7182351,,
,35977883.36,4882,13.8324,0.801041,364.80991,5.5367313e-4,99.902,,,1.1224391e3,9.990,,,0.0000,0.0049,48,0.00,0.00,0.00,0.00,0.0357376,,400.0017395,,,,,9.886689e-3,1.7191499,,
,35977931.56,4882,13.9128,0.801041,364.80991,1.7182960e-4,99.902,,,1.1218481e3,9.990,,,0.0049,0.0000,48,0.00,0.00,0.00,0.00,0.0348049,,400.0017395,,,,,6.148606e-3,1.7200117,,
,35977979.50,4882,13.9919,0.801041,364.80991,3.8184354e-4,99.902,,,1.1212329e3,9.990,,,0.0098,0.0000,48,0.00,0.00,0.00,0.00,0.0362129,,400.0017395,,,,,8.451712e-4,1.7209102,,
,35978027.52,4882,14.0730,0.801041,364.80991,2.4819831e-4,99.902,,,1.1205548e3,9.990,,,0.0049,0.0000,48,0.00,0.00,0.00,0.00,0.0348049,,400.0017395,,,,,9.954842e-3,1.7219021,,
,35978075.53,4882,14.1531,0.801041,364.80991,4.0093571e-4,99.902,,,1.1200328e3,9.990,,,0.0000,-0.0049,48,0.00,0.00,0.00,0.00,0.0362129,,400.0017395,,,,,1.188628e-2,1.7226666,,
,35978123.44,4882,14.2323,0.801041,364.80991,4.7730442e-4,99.902,,,1.1193452e3,9.990,,,0.0000,0.0049,48,0.00,0.00,0.00,0.00,0.0366944,,400.0017395,,,,,4.415798e-3,1.7236754,,
,35978171.34,4882,14.3119,0.801041,364.80991,4.9639662e-4,99.902,,,1.1187948e3,9.990,,,0.0049,-0.0049,48,0.00,0.00,0.00,0.00,0.0366944,,400.0017395,,,,,2.405528e-3,1.7244840,,
,35978219.39,4882,14.3912,0.801041,364.80991,9.5460884e-5,99.902,,,1.1182886e3,9.990,,,0.0049,0.0049,48,0.00,0.00,0.00,0.00,0.0366944,,400.0017395,,,,,-7.421992e-4,1.7252287,,
,35978267.61,4882,14.4731,0.801041,364.80991,2.2910612e-4,99.902,,,1.1176394e3,9.990,,,0.0049,0.0000,48,0.00,0.00,0.00,0.00,0.0357376,,400.0017395,,,,,5.693154e-3,1.7261850,,
,35978315.58,4882,14.5524,0.801041,364.80991,-3.8184353e-5,99.902,,,1.1170121e3,9.990,,,0.0049,0.0049,48,0.00,0.00,0.00,0.00,0.0371821,,400.0017395,,,,,2.346114e-3,1.7271105,,
,35978363.39,4882,14.6326,0.801041,364.80991,7.6368706e-5,99.902,,,1.1165210e3,9.990,,,0.0000,0.0049,48,0.00,0.00,0.00,0.00,0.0371821,,400.0017395,,,,,8.094712e-3,1.7278360,,
,35978411.64,4882,14.7131,0.801041,364.80991,3.6275137e-4,99.902,,,1.1158832e3,9.990,,,0.0098,-0.0049,48,0.00,0.00,0.00,0.00,0.0371821,,400.0017395,,,,,8.834680e-3,1.7287797,,
,35978459.47,4882,14.7926,0.801041,364.80991,4.2002788e-4,99.902,,,1.1154038e3,9.990,,,0.0049,0.0000,48,0.00,0.00,0.00,0.00,0.0376761,,400.0017395,,,,,6.924026e-3,1.7294898,,
,35978507.38,4882,14.8732,0.801041,364.80991,3.8184354e-4,99.902,,,1.1148118e3,9.990,,,0.0049,-0.0049,48,0.00,0.00,0.00,0.00,0.0376761,,400.0017395,,,,,1.079144e-2,1.7303680,,
,35978555.52,4882,14.9532,0.801041,364.80991,7.6368706e-5,99.902,,,1.1142908e3,9.990,,,0.0000,0.0000,48,0.00,0.00,0.00,0.00,0.0376761,,400.0017395,,,,,1.104619e-2,1.7311419,,
,35978603.53,4885,14.9984,0.801041,364.80991,4.5821225e-4,99.902,,,1.1138380e3,9.990,,,0.0000,0.0000,48,0.00,0.00,0.00,0.00,0.0376761,,400.0017395,,,,,-1.082220e-2,1.7318152,,
,35978647.67,4881,15.0014,0.801041,364.80991,3.6275137e-4,99.902,,,1.1137518e3,9.990,,,0.0000,0.0000,48,0.00,0.00,0.00,0.00,0.0381764,,400.0017395,,,,,9.300638e-3,1.7319435,,